Workbook

Sheet 00_はじめに
B1: 暗黙タスク棚卸し台帳 v3.4（Researcher 1回版）
B2: 対象：管理職（不特定多数への配布を想定） ／ 人の操作：Researcher への依頼1回・貼り付け1回・本人確認 ／ 待ち時間：5〜45分
B4: 1. この台帳でやること
B5: ・Microsoft 365 Copilot の Researcher に1回だけ依頼し、保存期間（既定14か月）分のメール・Teams チャット・会議から、調整・連絡・確認などで時間が過ぎていく「暗黙のタスク」を洗い出す。
B6: ・Researcher は6つの観点を順番に調べ、業務区分（顧客案件・社内・庶務など）、案件・対象名、タスク名、他の人が読んでもわかる詳細、代表的なやり取り、頻度と時間の目安、任せやすさの採点（A1〜A7）までを1つの表で返す。
B7: ・台帳は貼り付けた表を自動でチェックし、月あたりの時間と「自動化／オフショア／ニアショア／社内」の区分を計算する。提出するのは 05_タスク一覧（提出用）。
B8: ・06_顧客別集計で、顧客ごとのタスク数・時間・任せられる候補の時間が見られる。会社名の表記ゆれは自動でそろえ、そろわないものだけ本人が統一後の名前を入れる。
B9: ・この台帳と提出物は社内でのみ利用する前提のため、顧客名・案件名はそのまま記載する（人名・メールアドレス・金額は書かない）。
B10: ・分類は3つある。業務区分＝どの仕事のためか（顧客案件・社内・庶務など）／類型＝どんな種類の手間か（日程調整・催促・取りまとめなど）／観点＝Researcher がどの切り口で探したか（漏れの確認用）。
B12: 2. 手順（02_ダッシュボードの「次にやること」が自動で切り替わる）
B13: ① 02_ダッシュボードの「このセルをコピー」を選んでコピーする（Ctrl+C）
B14: ② Microsoft 365 Copilot で Researcher を開き、新しいチャットに貼り付けて送る。調べる範囲を選べる場合は「メール」「会議」「チャット」を選び、Web は外す
... B46: ・類型コード・採点基準・移管区分は全員共通なので、部署・役職をまたいで集計できる。調査の文面は 03_プロンプトの原本（黄色）で一括して直せる。

Sheet 01_設定
A1: 01_設定
A2: 黄色のセルだけを入力・選択する。灰色は自動計算。
B3: 項目 | C3: 値 | D3: 説明
B4: 実行者ID（匿名） | D4: 空欄なら、ファイル名の先頭（最初の「_」の前）を実行者IDとして使う。ファイル名と違うIDにしたいときだけ入力する。氏名は使わない。
B5: 部署区分 | C5: 企画・管理 | D5: プルダウンから選ぶ。
B6: 役職区分 | C6: 課長級 | D6: プルダウンから選ぶ。
B7: 実行日 | D7: Researcher を実行する（した）日。空欄の間は今日の日付が使われる。本人確認のときに日付を入れて固定する。
B8: 保存期間（月） | C8: 14 | D8: 会社のメール・チャットの保存期間。対象期間の長さになる。
B9: 最大行数 | C9: 50 | D9: Researcher に挙げてもらうタスクの上限。
B10: 直近とみなす月数 | C10: 3 | D10: 偏りチェック用。根拠の最初がこの月数以内のタスクを「直近」とみなす。
B11: 偏りの判定基準 | C11: 0.7 | D11: 直近のタスクがこの割合以上なら、ダッシュボードに注意を出す。
B12: 調査の完了 | C12: 自動 | D12: 通常は「自動」。終わりの印（##END##）がないが表は全部出ていると判断した場合だけ「完了」にする。
B13: 本人確認 | C13: 未完了 | D13: 本人確認が終わったら「完了」にする。
B14: 提出状況 | C14: 未提出 | D14: 提出したら「提出済み」にする。
B16: ■ 実行の記録（任意）
B17: Researcher を実行した日時
B18: かかった時間（分）
B19: メモ
B21: ■ 自動計算（触らない）
B22: 実行日（使用する値） | C22: =IF(C7="",TODAY(),C7)
B23: 対象開始日 | C23: =EDATE(C22,-C8)
B24: 対象月数 | C24: =ROUND((C22-C23)/30.44,0)
B25: 前半の終了日 | C25: =C23+INT((C22-C23)/2)
B26: 直近の境界日 | C26: =EDATE(C22,-C10)
B27: 直近に偏っている割合（観点6を除く） | C27: =IFERROR(COUNTIFS('04_調査結果'!$AY$5:$AY$404,1,'04_調査結果'!$AO$5:$AO$404,"<>6")/(COUNTIFS('04_調査結果'!$AY$5:$AY$404,1,'04_調査結果'!$AO$5:$AO$404,"<>6")+COUNTIFS('04_調査結果'!$AY$5:$AY$404,0,'04_調査結果'!$AO$5:$AO$404,"<>6")),"")
B28: OKの件数 | C28: =COUNTIF('04_調査結果'!$AB$5:$AB$404,"OK")
B29: 終わりの印の数 | C29: =COUNTIF('04_調査結果'!$AB$5:$AB$404,"（終わりの印）")
B30: 状態コード | C30: =IF(C28=0,IF(C31="列がずれている可能性",6,1),IF(AND(C29=0,C12<>"完了"),2,IF(C13<>"完了",3,IF(C14<>"提出済み",4,5))))
B31: 列の並びチェック | C31: =IF(ISNA(MATCH("調査ID",'04_調査結果'!$AM$5:$AM$404,0)),"見出し行なし（確認できない）",IF(AND(INDEX('04_調査結果'!$H$5:$H$404,MATCH("調査ID",'04_調査結果'!$AM$5:$AM$404,0))="類型",INDEX('04_調査結果'!$P$5:$P$404,MATCH("調査ID",'04_調査結果'!$AM$5:$AM$404,0))="根拠の件数",INDEX('04_調査結果'!$AA$5:$AA$404,MATCH("調査ID",'04_調査結果'!$AM$5:$AM$404,0))="任せるための前提条件"),"OK","列がずれている可能性"))
B32: 台帳の版 | C32: v3.4
B33: ファイルの場所 | C33: =CELL("filename",$A$1)
B34: ファイル名 | C34: =IFERROR(MID(C33,FIND("[",C33)+1,FIND("]",C33)-FIND("[",C33)-1),"")
B35: ファイル名の先頭のID | C35: =IF(C34="","",LEFT(C34,FIND("_",C34&"_")-1))
B36: 実行者ID（使用する値） | C36: =IF(C4<>"",C4,IF(OR(C35="",C35="実行者ID"),"（未設定）",C35))
B37: ファイル名チェック | C37: =IF(C34="","未保存（保存すると確認できる）",IF(C36="（未設定）","実行者IDが未設定",IF(LEFT(C34,LEN(C36)+1)=C36&"_","OK","ファイル名の先頭が実行者IDになっていない")))
B38: 推奨ファイル名 | C38: =IF(C36="（未設定）","（先に実行者IDを入力するか、ファイル名の先頭にIDを付ける）",C36&"_暗黙タスク棚卸し台帳_"&TEXT(C22,"yyyymmdd")&".xlsx")

Sheet 02_ダッシュボード
A1: 02_ダッシュボード
A2: 「次にやること」を上から順に行う。Researcher に送るのは基本的に1回だけ。
B4: 実行者ID | C4: ='01_設定'!C36
B5: 対象期間 | C5: =TEXT('01_設定'!C23,"yyyy/mm/dd")&"〜"&TEXT('01_設定'!C22,"yyyy/mm/dd")&"（約"&'01_設定'!C24&"か月）"&IF('01_設定'!C7=""," ※実行日が未入力のため今日の日付で計算中","")
B6: ファイル名 | C6: ='01_設定'!C37&IF('01_設定'!C37="OK",""," → 推奨：" & '01_設定'!C38)
B7: ■ 次にやること
B8: 状態 | C8: =CHOOSE('01_設定'!$C$30,"① 調査プロンプトを Researcher の新しいチャットに送り、表を 04_調査結果に貼る","② 終わりの印がまだない。表が途中なら続きプロンプトを同じチャットに送り、続きを貼る（全部出ていれば 01_設定の「調査の完了」を「完了」に）","③ 本人確認（手順は下のセル）","④ 提出（手順は下のセル）"&IF('01_設定'!C7=""," ※先に 01_設定の実行日を入力",""),"すべて完了","⑥ 列の並びが指定と違う。出し直しプロンプトを同じチャットに送り、ずれた行を消してから貼り直す")
B9: このセルをコピー | C9: =CHOOSE('01_設定'!$C$30,'03_プロンプト'!$E$13,'03_プロンプト'!$E$14,'03_プロンプト'!$E$8,'03_プロンプト'!$E$9,"",'03_プロンプト'!$E$15)
B10: 文字数 | C10: =IF(C9="","",LEN(C9))
B11: ※ セルを選んで Ctrl+C → Researcher の入力欄に Ctrl+V。先頭と末尾に " が付いてもそのまま送ってよい。
B12: ※ Researcher で調べる範囲を選べる場合は、メール・会議・チャットを選び、Web は外す。
B13: ※ Researcher から確認の質問が来たら「指示どおりに進めてください」と返す。
B14: ※ 表にならなかった・表が分かれた・列がずれた場合は、03_プロンプトの「出し直し」を同じチャットに送る。
B16: ■ 品質チェック
B17: 項目 | C17: 値 | D17: 見方・対処
B18: OK のタスク数 | C18: ='01_設定'!C28 | D18: 少なすぎる（10件未満など）場合は、貼り付け漏れや途中終了がないか確認する
B19: 列の並び | C19: ='01_設定'!C31 | D19: 「列がずれている可能性」なら、03_プロンプトの「出し直し」を同じチャットに送り、貼り直す
B20: 直さないと集計されない行（△） | C20: =COUNTIF('04_調査結果'!$AB$5:$AB$404,"△*") | D20: 値を直すと集計の対象になる（直さなくても他の行には影響しない）
B21: 要確認のタスク | C21: =COUNTIF('04_調査結果'!$AC$5:$AC$404,"?*") | D21: 根拠1件・同名あり・回数を換算したもの。本人確認で優先して見る
B22: 直近に偏っている割合 | C22: ='01_設定'!C27 | D22: 基準以上なら注意。気になる場合だけ、03_プロンプトの R2（前半の追加調査・任意）を使う
B24: ■ 観点別のタスク数（0件の観点は漏れの可能性がある）
B25: 観点 | C25: タスク数 | D25: 内容
B26: 1 | C26: =COUNTIFS('04_調査結果'!$AO$5:$AO$404,B26,'04_調査結果'!$AB$5:$AB$404,"OK") | D26: 中継・調整・催促・取りまとめ
B27: 2 | C27: =COUNTIFS('04_調査結果'!$AO$5:$AO$404,B27,'04_調査結果'!$AB$5:$AB$404,"OK") | D27: 確認・承認・問い合わせ対応
B28: 3 | C28: =COUNTIFS('04_調査結果'!$AO$5:$AO$404,B28,'04_調査結果'!$AB$5:$AB$404,"OK") | D28: 利害調整・トラブル・相談対応
B29: 4 | C29: =COUNTIFS('04_調査結果'!$AO$5:$AO$404,B29,'04_調査結果'!$AB$5:$AB$404,"OK") | D29: 定例報告・会議運営
B30: 5 | C30: =COUNTIFS('04_調査結果'!$AO$5:$AO$404,B30,'04_調査結果'!$AB$5:$AB$404,"OK") | D30: 申請・手配・調べもの・資料作成
B31: 6 | C31: =COUNTIFS('04_調査結果'!$AO$5:$AO$404,B31,'04_調査結果'!$AB$5:$AB$404,"OK") | D31: 年に数回の業務
B33: ■ 業務区分別の集計（除外したタスクを除く）
B34: 業務区分 | C34: タスク数 | D34: 区分名 | E34: 暗黙の数 | F34: 月あたり時間h
B35: 1 | C35: =COUNTIFS('04_調査結果'!$AP$5:$AP$404,B35,'04_調査結果'!$AZ$5:$AZ$404,">0") | D35: 顧客案件 | E35: =COUNTIFS('04_調査結果'!$AP$5:$AP$404,B35,'04_調査結果'!$AZ$5:$AZ$404,">0",'04_調査結果'!$M$5:$M$404,"暗黙") | F35: =SUMIFS('04_調査結果'!$AI$5:$AI$404,'04_調査結果'!$AP$5:$AP$404,B35,'04_調査結果'!$AZ$5:$AZ$404,">0")
B36: 2 | C36: =COUNTIFS('04_調査結果'!$AP$5:$AP$404,B36,'04_調査結果'!$AZ$5:$AZ$404,">0") | D36: 提案・営業 | E36: =COUNTIFS('04_調査結果'!$AP$5:$AP$404,B36,'04_調査結果'!$AZ$5:$AZ$404,">0",'04_調査結果'!$M$5:$M$404,"暗黙") | F36: =SUMIFS('04_調査結果'!$AI$5:$AI$404,'04_調査結果'!$AP$5:$AP$404,B36,'04_調査結果'!$AZ$5:$AZ$404,">0")
B37: 3 | C37: =COUNTIFS('04_調査結果'!$AP$5:$AP$404,B37,'04_調査結果'!$AZ$5:$AZ$404,">0") | D37: 社内プロジェクト・改善 | E37: =COUNTIFS('04_調査結果'!$AP$5:$AP$404,B37,'04_調査結果'!$AZ$5:$AZ$404,">0",'04_調査結果'!$M$5:$M$404,"暗黙") | F37: =SUMIFS('04_調査結果'!$AI$5:$AI$404,'04_調査結果'!$AP$5:$AP$404,B37,'04_調査結果'!$AZ$5:$AZ$404,">0")
B38: 4 | C38: =COUNTIFS('04_調査結果'!$AP$5:$AP$404,B38,'04_調査結果'!$AZ$5:$AZ$404,">0") | D38: 部門運営・人材マネジメント | E38: =COUNTIFS('04_調査結果'!$AP$5:$AP$404,B38,'04_調査結果'!$AZ$5:$AZ$404,">0",'04_調査結果'!$M$5:$M$404,"暗黙") | F38: =SUMIFS('04_調査結果'!$AI$5:$AI$404,'04_調査結果'!$AP$5:$AP$404,B38,'04_調査結果'!$AZ$5:$AZ$404,">0")
B39: 5 | C39: =COUNTIFS('04_調査結果'!$AP$5:$AP$404,B39,'04_調査結果'!$AZ$5:$AZ$404,">0") | D39: 庶務・事務手続き | E39: =COUNTIFS('04_調査結果'!$AP$5:$AP$404,B39,'04_調査結果'!$AZ$5:$AZ$404,">0",'04_調査結果'!$M$5:$M$404,"暗黙") | F39: =SUMIFS('04_調査結果'!$AI$5:$AI$404,'04_調査結果'!$AP$5:$AP$404,B39,'04_調査結果'!$AZ$5:$AZ$404,">0")
B40: 6 | C40: =COUNTIFS('04_調査結果'!$AP$5:$AP$404,B40,'04_調査結果'!$AZ$5:$AZ$404,">0") | D40: 全社行事・その他 | E40: =COUNTIFS('04_調査結果'!$AP$5:$AP$404,B40,'04_調査結果'!$AZ$5:$AZ$404,">0",'04_調査結果'!$M$5:$M$404,"暗黙") | F40: =SUMIFS('04_調査結果'!$AI$5:$AI$404,'04_調査結果'!$AP$5:$AP$404,B40,'04_調査結果'!$AZ$5:$AZ$404,">0")
B42: ■ 類型別の集計（除外したタスクを除く）
B43: 類型 | C43: タスク数 | D43: 類型名 | E43: 暗黙の数 | F43: 月あたり時間h
B44: T01 | C44: =COUNTIFS('04_調査結果'!$AQ$5:$AQ$404,B44,'04_調査結果'!$AZ$5:$AZ$404,">0") | D44: 中継・転送 | E44: =COUNTIFS('04_調査結果'!$AQ$5:$AQ$404,B44,'04_調査結果'!$AZ$5:$AZ$404,">0",'04_調査結果'!$M$5:$M$404,"暗黙") | F44: =SUMIFS('04_調査結果'!$AI$5:$AI$404,'04_調査結果'!$AQ$5:$AQ$404,B44,'04_調査結果'!$AZ$5:$AZ$404,">0")
B45: T02 | C45: =COUNTIFS('04_調査結果'!$AQ$5:$AQ$404,B45,'04_調査結果'!$AZ$5:$AZ$404,">0") | D45: 日程・会議調整 | E45: =COUNTIFS('04_調査結果'!$AQ$5:$AQ$404,B45,'04_調査結果'!$AZ$5:$AZ$404,">0",'04_調査結果'!$M$5:$M$404,"暗黙") | F45: =SUMIFS('04_調査結果'!$AI$5:$AI$404,'04_調査結果'!$AQ$5:$AQ$404,B45,'04_調査結果'!$AZ$5:$AZ$404,">0")
...

Sheet 03_プロンプト
A1: 03_プロンプト
A2: Researcher に送る文面。上（黄色）が原本で、下が日付などを差し込んだ完成版。普段は 02_ダッシュボードのセルをコピーすればよい。
B4: ID | C4: 名称 | D4: 使う場面 | E4: 本文 | F4: 文字数
B5: RT | C5: 調査（原本） | D5: Researcher の新しいチャットで1回だけ。 | E5: 【業務の棚卸し {調査ID}】暗黙のタスクの洗い出し ■対象期間：{期間開始}〜{期間終了}（約{月数}か月） ■調べる範囲：私のメール（特に私が送信したもの）、Teamsのチャット、会議。Webは使わない。 ■目的：依頼された仕事だけでなく、誰にも頼まれていないのに私の時間を使っている「暗黙のタスク」を洗い出し、自動化や、他の拠点・委託先に任せられるかを判断したい。{追加の指示} ■調べ方（確認の質問はせず、このまま進めてください） 次の6つの観点を、1つずつ順番に検索してください。 観点1：転送・共有による中継、日程・会議の調整、返事の催促・再確認、複数人からの回収・取りまとめ 観点2：他人の作成物や申請の確認・承認・差し戻し、問い合わせへの一次対応と担当の振り分け 観点3：関係者間の意見調整・根回し、トラブルや例外への一次対応、部下・同僚からの相談対応・指導 観点4：定例の報告・数値の更新、会議の準備・進行・議事録・宿題の管理 観点5：申請・手配・事務手続き、回答や判断のための調べもの、資料・文書の作成 観点6：年に数回だけ発生する業務（予算策定・人事評価・目標設定・年度計画・決算・監査対応・棚卸・人事異動・年次イベントなど） ・どの観点も、対象期間の前半と後半の両方から根拠となるやり取りを確認してください（直近に偏らないこと）。 ・繰り返し発生している作業を優先し、個々のメールではなく、同じ種類の作業を1つのタスクにまとめてください。 ・同じ種類の作業でも、対象の顧客・案件が違えば別のタスクにしてください。多くの顧客で同じ作業をしている場合だけ1つにまとめ、顧客名を「複数」にして、詳細に主な顧客の例を書いてください。 ・実際のやり取りで確認できたものだけを挙げてください。推測で作らないでください。該当がない観点は0件でかまいません。 ■出力のルール ・前置き・まとめは書かず、1つの表だけを出す（観点ごとに表を分けない）。最大{最大行数}行。 ・人名・メールアドレス・電話番号・金額は、表のどの列にも書かない（人は「顧客の経理担当」「部下」のように役割で書く）。会社名・案件名・プロジェクト名は書いてよい。表の中に出典番号やリンクを入れない。 ・全部出し終えたら、表の最後の行として、調査IDの列に「##END##」とだけ書いた行を加える。途中で止める場合は、同じように「##続きあり##」の行を加える。 ・表の列（この順番、この見出しのまま）： | 調査ID | No | 観点 | 業務区分 | 顧客名 | 案件・対象名 | タスク名 | 類型 | 説明 | 詳細 | 代表的なやり取り | 主な相手 | 明示暗黙 | 月あたり回数 | 1回あたり分 | 根拠の件数 | 根拠の最初 | 根拠の最後 | 暗黙の理由 | A1 | A2 | A3 | A4 | A5 | A6 | A7 | 任せるための前提条件 | ・調査ID：すべての行に {調査ID} と書く ・No：1からの連番 ・観点：1〜6の数字だけ ・業務区分：次の番号だけ {業務区分一覧} ・顧客名：顧客・取引先の会社名だけを書く（例：A社）。同じ会社は表全体で同じ表記にそろえ、「株式会社」などは付けない。多くの顧客で同じ作業なら「複数」。社内の仕事なら - ・案件・対象名：案件名・社内プロジェクト名・会議体・手続きの名前（例：決算監査、システム導入支援、部門定例会議、経費精算）。顧客名はここには書かない ・タスク名：「業務対象＋動作」で20字以内（例：監査調書のレビュー依頼の取りまとめ） ・類型：次のコードだけを書く（例：T02） T01 中継・転送／T02 日程・会議調整／T03 催促・フォローアップ／T04 取りまとめ・集約／T05 確認・承認・レビュー／T06 問い合わせ対応・振り分け／T07 利害調整・合意形成／T08 定例報告・数値更新／T09 申請・手配・事務手続き／T10 調査・情報探し／T11 トラブル・例外対応／T12 相談対応・指導／T13 会議運営／T14 資料・文書作成／T99 その他 ・説明：40字以内の要約 ・詳細：100〜200字。本人や他の人が読んで、どの作業か特定できるように書く。何のための作業か、誰（役割）とどんなやり取りをするか、どんな手順で何を作る・送るか、手間がかかる理由を含める ・代表的なやり取り：根拠にしたやり取りの代表例を1〜2件、「yyyy/mm 件名や話題の要約」の形で書く（人名は書かない） ・主な相手：上司／部下／自部署／他部署／経営層／顧客／取引先／社外その他／複数 のどれか ・明示暗黙：私宛てに具体的な依頼があり、成果物か期限がはっきりしているものは「明示」、それ以外は「暗黙」 ・月あたり回数：数字だけ（週1回なら4、月2回なら2、年1回なら0.1、四半期ごとなら0.3） ・1回あたり分：数字だけ（1回分のやり取り全体にかかる時間の目安） ・根拠の件数：このタスクの根拠として確認したやり取りの件数（数字だけ） ・根拠の最初、根拠の最後：根拠にしたやり取りの最初と最後の年月（yyyy/mm） ・暗黙の理由：30字以内（例：依頼がないのに自分から催促している）。明示なら - ・A1〜A7：下の基準で 0・1・2 の数字だけ（大きいほど任せにくい。迷ったら大きい方） A1 判断・裁量：0=手順どおりで判断不要／1=軽い判断がある／2=管理職の判断・決裁が必要 A2 機密性：0=社内の一般的な情報／1=社外秘／2=人事・評価・個人情報・未公表の経営情報 A3 関係性：0=誰が対応しても同じ／1=相手との一定の関係が必要／2=私本人との信頼関係が前提 A4 言語・文脈：0=定型文で足りる／1=日本語の言い回し・社内用語が必要／2=経緯や空気を読む高度な日本語が必要 A5 即時性：0=翌営業日でよい／1=当日中に必要／2=即時、または日本の勤務時間内の対応が必須 A6 非定型度：0=毎回同じ手順／1=いくつかのパターンがある／2=毎回内容が違う A7 システム権限：0=メール・Teamsだけで完結／1=社内システムの閲覧が必要／2=承認権限・特別なIDが必要 ・任せるための前提条件：40字以内（例：手順書と定型文の整備、閲覧権限の付与） | F5: =LEN(E5)
B6: RC | C6: 続き（原本） | D6: 表が途中で終わったとき、同じチャットで。 | E6: 【続き {調査ID}】表が途中で終わっています。続きを No.{次No} から、同じ列・同じルールの1つの表で出してください。すでに出した行は繰り返さないでください。前置きは不要です。全部出し終えたら、表の最後の行として、調査IDの列に「##END##」とだけ書いた行を加えてください。 | F6: =LEN(E6)
B7: RF | C7: 出し直し（原本） | D7: 表にならなかった・表が分かれた・列がずれたとき、同じチャットで。 | E7: 【出し直し {調査ID}】上の調査結果を、最初に指定した27列の表1つだけで出し直してください。列の順番と見出しは指定どおりにし、数字の列には数字だけを書いてください。前置き・まとめは不要です。表の最後の行として、調査IDの列に「##END##」とだけ書いた行を加えてください。 | F7: =LEN(E7)
B8: MR | C8: 手作業：本人確認 | D8: 調査のあと。 | E8: 【手作業】本人確認（目安20分） 1. 01_設定の「実行日」が空欄なら、Researcher を実行した日を入れる（空欄のままだと毎日変わる）。 2. 04_調査結果の判定列（AB列）に「△」が出ている行は、値を直すと集計の対象になる（直さなければ集計されないだけ）。「×」や見出し行・終わりの印はそのままでよい。 3. 05_タスク一覧を上から見て、明らかな誤り・業務ではないもの・重複があれば、04_調査結果のAD列（本人確認）で「除外」を選ぶ。AC列（要確認）に「根拠1件」「同名あり」と出ているものを優先して見る。何もしなければ提出の対象になる。 4. 回数や時間が実感と大きく違うものだけ、AE列・AF列に自分の見積もりを入れる。移管区分に異論があるものだけ、AG列で選び直す。 5. 詳細を読んで、自分でも何の作業かわからないものは、詳細を書き足すか「除外」にする。業務区分・案件・対象名が違っていれば直す。 6. 06_顧客別集計の「会社名の名寄せ」で、同じ会社が別の表記になっていないか確認する。自動でそろわなかったものだけ「統一後の名前」に正しい名前を入れる。人名が残っていれば書き換える。 7. 終わったら、01_設定の「本人確認」を「完了」にする。 | F8: =LEN(E8)
B9: MS | C9: 手作業：提出 | D9: 本人確認のあと。 | E9: 【手作業】提出 1. 05_タスク一覧（提出用）に、除外していないタスクだけが並んでいることを確認する（氏名・メール本文は含まれない）。 2. 02_ダッシュボードの「ファイル名」が OK か確認する。OK でなければ、表示されている推奨ファイル名（実行者IDで始まる名前）で保存し直す。 3. 配布元の指示に従い、このファイルを提出先に保存する。 4. 01_設定の「提出状況」を「提出済み」にする。 | F9: =LEN(E9)
B11: ■ 完成版（自動で差し込み済み）
B12: ID | C12: 名称 | D12: 使う場面 | E12: 本文（このセルをコピー） | F12: 文字数
B13: R1 | C13: 調査（送るもの） | D13: Researcher の新しいチャットで1回だけ。 | E13: =SUBSTITUTE(SUBSTITUTE(SUBSTITUTE(SUBSTITUTE(SUBSTITUTE(SUBSTITUTE(SUBSTITUTE($E$5,"{調査ID}","R1"),"{期間開始}",TEXT('01_設定'!$C$23,"yyyy年m月d日")),"{期間終了}",TEXT('01_設定'!$C$22,"yyyy年m月d日")),"{月数}",ROUND(('01_設定'!$C$22-'01_設定'!$C$23)/30.44,0)),"{最大行数}",'01_設定'!$C$9),"{業務区分一覧}",'M2_区分マスタ'!$I$12),"{追加の指示}","") | F13: =LEN(E13)
B14: R1続き | C14: 続き（送るもの） | D14: 表が途中で終わったとき、同じチャットで。 | E14: =SUBSTITUTE(SUBSTITUTE($E$6,"{調査ID}","R1"),"{次No}",IFERROR(_xlfn.MAXIFS('04_調査結果'!$B$5:$B$404,'04_調査結果'!$AM$5:$AM$404,"R1"),0)+1) | F14: =LEN(E14)
B15: R1出し直し | C15: 出し直し（送るもの） | D15: 表にならなかった・表が分かれた・列がずれたとき、同じチャットで。 | E15: =SUBSTITUTE($E$7,"{調査ID}","R1") | F15: =LEN(E15)
B16: R2 | C16: 前半の追加調査（任意） | D16: 結果が直近に偏っていた場合だけ。Researcher の新しいチャットで。 | E16: =SUBSTITUTE(SUBSTITUTE(SUBSTITUTE(SUBSTITUTE(SUBSTITUTE(SUBSTITUTE(SUBSTITUTE($E$5,"{調査ID}","R2"),"{期間開始}",TEXT('01_設定'!$C$23,"yyyy年m月d日")),"{期間終了}",TEXT('01_設定'!$C$25,"yyyy年m月d日")),"{月数}",ROUND(('01_設定'!$C$25-'01_設定'!$C$23)/30.44,0)),"{最大行数}",'01_設定'!$C$9),"{業務区分一覧}",'M2_区分マスタ'!$I$12),"{追加の指示}"," ※ 直近の業務は別の調査で確認済みです。この期間に繰り返し発生していた業務を中心に挙げてください。") | F16: =LEN(E16)

Sheet 04_調査結果
A1: 04_調査結果（Researcher の表の貼り付け先・本人確認もここで行う）
A2: Researcher の表を見出し行ごとコピーし、A5 から下の最初の空き行に貼る（緑の見出しの列 A〜AA）。判定が OK の行だけが集計される。黄色の見出しの列（AD〜AG）は本人確認のときだけ入力する。
A3: 調査ID | B3: No | C3: 観点 | D3: 業務区分 | E3: 顧客名 | F3: 案件・対象名 | G3: タスク名 | H3: 類型 | I3: 説明 | J3: 詳細 | K3: 代表的なやり取り | L3: 主な相手 | M3: 明示暗黙 | N3: 月あたり回数 | O3: 1回あたり分 | P3: 根拠の件数 | Q3: 根拠の最初 | R3: 根拠の最後 | S3: 暗黙の理由 | T3: A1 | U3: A2 | V3: A3 | W3: A4 | X3: A5 | Y3: A6 | Z3: A7 | AA3: 任せるための前提条件 | AB3: 判定 | AC3: 要確認 | AD3: 本人確認 | AE3: 補正：月あたり回数 | AF3: 補正：1回あたり分 | AG3: 本人判断（上書き） | AH3: 採用区分 | AI3: 採用：月あたり時間h | AJ3: 自動判定 | AK3: 任せやすさ（14点満点） | AL3: 月あたり時間h（推定） | AM3: 調査ID（整形） | AN3: キー | AO3: 観点（数値） | AP3: 業務区分（数値） | AQ3: 類型コード | AR3: 回数の数字部分 | AS3: 回数（数値） | AT3: 分（数値） | AU3: 根拠の件数（数値） | AV3: 同名チェック | AW3: 根拠の最初（日付） | AX3: 根拠の最後（日付） | AY3: 直近フラグ | AZ3: 一覧番号 | BA3: 順位用 | BB3: 顧客名（整形） | BC3: 顧客名初出 | BD3: 顧客名初出番号 | BE3: 顧客名（統一後） | BF3: 統一後初出 | BG3: 統一後初出番号
A4: ↓ A5 のセルを選んで貼り付ける（見出し行ごと貼ってよい）。×の行や見出し行は消さなくてよい（集計されない）。
AB5: =IF(AND(A5="",G5=""),"",IF(ISNUMBER(SEARCH("##END",AM5)),"（終わりの印）",IF(ISNUMBER(SEARCH("##続き",AM5)),"（続きありの印）",IF(AM5="調査ID","（見出し行）",IF(AND(AM5<>"R1",AM5<>"R2"),"×表以外の行（集計されない）",IF(COUNTIF($AN$5:AN5,AN5)>1,"△重複（集計されない）",IF(G5="","△タスク名なし",IF(ISNA(MATCH(AQ5,'M1_類型マスタ'!$A$5:$A$19,0)),"△類型が不正",IF(OR(AP5="",N(AP5)<1,N(AP5)>6),"△業務区分が不正",IF(OR(AS5="",AT5=""),"△回数・分が読めない",IF(SUMPRODUCT(--ISNUMBER(--T5:Z5))<7,"△採点が足りない",IF(SUMPRODUCT((--T5:Z5>2)+(--T5:Z5<0))>0,"△採点が範囲外","OK")))))))))))) | AC5: =IF(AB5<>"OK","",TRIM(IF(AND(AU5<>"",N(AU5)<=1),"根拠1件 ","")&IF(AV5<>"","同名あり ","")&IF(AND(NOT(ISNUMBER(N5)),N5<>""),"回数を換算 ","")&IF(J5="","詳細なし ","")&IF(AND(N(AP5)=1,BB5=""),"顧客名なし ",""))) | AH5: =IF(AB5<>"OK","",IF(AG5<>"",AG5,AJ5)) | AI5: =IF(AB5<>"OK","",IFERROR(IF(AE5<>"",AE5,AS5)*IF(AF5<>"",AF5,AT5)/60,"")) | AJ5: =IF(AB5<>"OK","",IF(OR(VALUE(T5)=2,VALUE(U5)=2,VALUE(V5)=2),"社内残置",IF(AND(VALUE(T5)=0,VALUE(W5)=0,VALUE(Y5)=0),"自動化候補",IF(AND(VALUE(U5)=0,VALUE(W5)<=1,VALUE(X5)<=1,VALUE(Y5)<=1,VALUE(Z5)<=1),"オフショア候補",IF(AND(VALUE(Y5)<=1,VALUE(Z5)<=1),"ニアショア候補","社内で手順化→再評価"))))) | AK5: =IF(AB5<>"OK","",14-SUMPRODUCT(--T5:Z5)) | AL5: =IF(AB5<>"OK","",AS5*AT5/60) | AM5: =IF(A5="","",UPPER(TRIM(ASC(A5&"")))) | AN5: =IF(AM5="","",AM5&"-"&B5) | AO5: =IF(C5="","",IFERROR(VALUE(ASC(SUBSTITUTE(C5&"","観点",""))),"")) | AP5: =IF(D5="","",IFERROR(VALUE(LEFT(TRIM(ASC(D5&"")),1)),IFERROR(MATCH(TRIM(D5&""),'M2_区分マスタ'!$I$5:$I$10,0),""))) | AQ5: =IF(H5="","",UPPER(LEFT(TRIM(ASC(H5&"")),3))) | AR5: =IF(N5="","",IFERROR(VALUE(SUBSTITUTE(SUBSTITUTE(SUBSTITUTE(SUBSTITUTE(SUBSTITUTE(SUBSTITUTE(SUBSTITUTE(SUBSTITUTE(SUBSTITUTE(SUBSTITUTE(SUBSTITUTE(SUBSTITUTE(ASC(N5&""),"約",""),"程度",""),"ほど",""),"回",""),"毎",""),"週",""),"月",""),"年",""),"日",""),"に",""),"/","")," ","")),"")) | AS5: =IF(N5="","",IF(ISNUMBER(N5),N5,IFERROR(VALUE(ASC(N5&"")),IF(AR5<>"",AR5*IF(ISNUMBER(SEARCH("週",N5)),4.3,IF(ISNUMBER(SEARCH("年",N5)),1/12,IF(ISNUMBER(SEARCH("日",N5)),20,1))),IF(ISNUMBER(SEARCH("日",N5)),20,IF(ISNUMBER(SEARCH("週",N5)),4.3,IF(ISNUMBER(SEARCH("月",N5)),1,""))))))) | AT5: =IF(O5="","",IF(ISNUMBER(O5),O5,IFERROR(VALUE(ASC(O5&"")),IF(ISNUMBER(SEARCH("時間",O5)),IFERROR(VALUE(SUBSTITUTE(SUBSTITUTE(SUBSTITUTE(SUBSTITUTE(SUBSTITUTE(ASC(O5&""),"約",""),"程度",""),"ほど",""),"時間","")," ",""))*60,""),IFERROR(VALUE(SUBSTITUTE(SUBSTITUTE(SUBSTITUTE(SUBSTITUTE(SUBSTITUTE(ASC(O5&""),"約",""),"程度",""),"ほど",""),"分","")," ","")),""))))) | AU5: =IF(P5="","",IF(ISNUMBER(P5),P5,IFERROR(VALUE(SUBSTITUTE(SUBSTITUTE(SUBSTITUTE(ASC(P5&""),"約",""),"件","")," ","")),""))) | AV5: =IF(AB5<>"OK","",IF(COUNTIFS($G$5:$G$404,G5&"",$F$5:$F$404,F5&"",$BE$5:$BE$404,BE5&"",$AB$5:$AB$404,"OK")>1,"同名あり","")) | AW5: =IF(Q5="","",IF(ISNUMBER(Q5),Q5,IFERROR(DATEVALUE(SUBSTITUTE(SUBSTITUTE(ASC(Q5&""),"-","/"),".","/")&"/01"),""))) | AX5: =IF(R5="","",IF(ISNUMBER(R5),R5,IFERROR(DATEVALUE(SUBSTITUTE(SUBSTITUTE(ASC(R5&""),"-","/"),".","/")&"/01"),""))) | AY5: =IF(OR(AB5<>"OK",AW5=""),"",IF(AW5>='01_設定'!$C$26,1,0)) | AZ5: =IF(AND(AB5="OK",AD5<>"除外"),COUNTIFS($AB$5:AB5,"OK",$AD$5:AD5,"<>除外"),"") | BA5: =IF(OR(AZ5="",AI5=""),"",AI5+ROW()/1000000000) | BB5: =IF(E5="","",IF(OR(TRIM(E5&"")="-",TRIM(E5&"")="－",TRIM(E5&"")="ー"),"",TRIM(E5&""))) | BC5: =IF(AND(AB5="OK",BB5<>""),IF(COUNTIFS($BB$5:BB5,BB5,$AB$5:AB5,"OK")=1,1,""),"") | BD5: =IF(BC5=1,COUNTIF($BC$5:BC5,1),"") | BE5: =IF(BB5="","",IFERROR(INDEX('06_顧客別集計'!$G$5:$G$104,MATCH(BB5,'06_顧客別集計'!$C$5:$C$104,0)),BB5)) | BF5: =IF(AND(AZ5<>"",BE5<>""),IF(COUNTIFS($BE$5:BE5,BE5,$AZ$5:AZ5,">0")=1,1,""),"") | BG5: =IF(BF5=1,COUNTIF($BF$5:BF5,1),"")
AB6: =IF(AND(A6="",G6=""),"",IF(ISNUMBER(SEARCH("##END",AM6)),"（終わりの印）",IF(ISNUMBER(SEARCH("##続き",AM6)),"（続きありの印）",IF(AM6="調査ID","（見出し行）",IF(AND(AM6<>"R1",AM6<>"R2"),"×表以外の行（集計されない）",IF(COUNTIF($AN$5:AN6,AN6)>1,"△重複（集計されない）",IF(G6="","△タスク名なし",IF(ISNA(MATCH(AQ6,'M1_類型マスタ'!$A$5:$A$19,0)),"△類型が不正",IF(OR(AP6="",N(AP6)<1,N(AP6)>6),"△業務区分が不正",IF(OR(AS6="",AT6=""),"△回数・分が読めない",IF(SUMPRODUCT(--ISNUMBER(--T6:Z6))<7,"△採点が足りない",IF(SUMPRODUCT((--T6:Z6>2)+(--T6:Z6<0))>0,"△採点が範囲外","OK")))))))))))) | AC6: =IF(AB6<>"OK","",TRIM(IF(AND(AU6<>"",N(AU6)<=1),"根拠1件 ","")&IF(AV6<>"","同名あり ","")&IF(AND(NOT(ISNUMBER(N6)),N6<>""),"回数を換算 ","")&IF(J6="","詳細なし ","")&IF(AND(N(AP6)=1,BB6=""),"顧客名なし ",""))) | AH6: =IF(AB6<>"OK","",IF(AG6<>"",AG6,AJ6)) | AI6: =IF(AB6<>"OK","",IFERROR(IF(AE6<>"",AE6,AS6)*IF(AF6<>"",AF6,AT6)/60,"")) | AJ6: =IF(AB6<>"OK","",IF(OR(VALUE(T6)=2,VALUE(U6)=2,VALUE(V6)=2),"社内残置",IF(AND(VALUE(T6)=0,VALUE(W6)=0,VALUE(Y6)=0),"自動化候補",IF(AND(VALUE(U6)=0,VALUE(W6)<=1,VALUE(X6)<=1,VALUE(Y6)<=1,VALUE(Z6)<=1),"オフショア候補",IF(AND(VALUE(Y6)<=1,VALUE(Z6)<=1),"ニアショア候補","社内で手順化→再評価"))))) | AK6: =IF(AB6<>"OK","",14-SUMPRODUCT(--T6:Z6)) | AL6: =IF(AB6<>"OK","",AS6*AT6/60) | AM6: =IF(A6="","",UPPER(TRIM(ASC(A6&"")))) | AN6: =IF(AM6="","",AM6&"-"&B6) | AO6: =IF(C6="","",IFERROR(VALUE(ASC(SUBSTITUTE(C6&"","観点",""))),"")) | AP6: =IF(D6="","",IFERROR(VALUE(LEFT(TRIM(ASC(D6&"")),1)),IFERROR(MATCH(TRIM(D6&""),'M2_区分マスタ'!$I$5:$I$10,0),""))) | AQ6: =IF(H6="","",UPPER(LEFT(TRIM(ASC(H6&"")),3))) | AR6: =IF(N6="","",IFERROR(VALUE(SUBSTITUTE(SUBSTITUTE(SUBSTITUTE(SUBSTITUTE(SUBSTITUTE(SUBSTITUTE(SUBSTITUTE(SUBSTITUTE(SUBSTITUTE(SUBSTITUTE(SUBSTITUTE(SUBSTITUTE(ASC(N6&""),"約",""),"程度",""),"ほど",""),"回",""),"毎",""),"週",""),"月",""),"年",""),"日",""),"に",""),"/","")," ","")),"")) | AS6: =IF(N6="","",IF(ISNUMBER(N6),N6,IFERROR(VALUE(ASC(N6&"")),IF(AR6<>"",AR6*IF(ISNUMBER(SEARCH("週",N6)),4.3,IF(ISNUMBER(SEARCH("年",N6)),1/12,IF(ISNUMBER(SEARCH("日",N6)),20,1))),IF(ISNUMBER(SEARCH("日",N6)),20,IF(ISNUMBER(SEARCH("週",N6)),4.3,IF(ISNUMBER(SEARCH("月",N6)),1,""))))))) | AT6: =IF(O6="","",IF(ISNUMBER(O6),O6,IFERROR(VALUE(ASC(O6&"")),IF(ISNUMBER(SEARCH("時間",O6)),IFERROR(VALUE(SUBSTITUTE(SUBSTITUTE(SUBSTITUTE(SUBSTITUTE(SUBSTITUTE(ASC(O6&""),"約",""),"程度",""),"ほど",""),"時間","")," ",""))*60,""),IFERROR(VALUE(SUBSTITUTE(SUBSTITUTE(SUBSTITUTE(SUBSTITUTE(SUBSTITUTE(ASC(O6&""),"約",""),"程度",""),"ほど",""),"分","")," ","")),""))))) | AU6: =IF(P6="","",IF(ISNUMBER(P6),P6,IFERROR(VALUE(SUBSTITUTE(SUBSTITUTE(SUBSTITUTE(ASC(P6&""),"約",""),"件","")," ","")),""))) | AV6: =IF(AB6<>"OK","",IF(COUNTIFS($G$5:$G$404,G6&"",$F$5:$F$404,F6&"",$BE$5:$BE$404,BE6&"",$AB$5:$AB$404,"OK")>1,"同名あり","")) | AW6: =IF(Q6="","",IF(ISNUMBER(Q6),Q6,IFERROR(DATEVALUE(SUBSTITUTE(SUBSTITUTE(ASC(Q6&""),"-","/"),".","/")&"/01"),""))) | AX6: =IF(R6="","",IF(ISNUMBER(R6),R6,IFERROR(DATEVALUE(SUBSTITUTE(SUBSTITUTE(ASC(R6&""),"-","/"),".","/")&"/01"),""))) | AY6: =IF(OR(AB6<>"OK",AW6=""),"",IF(AW6>='01_設定'!$C$26,1,0)) | AZ6: =IF(AND(AB6="OK",AD6<>"除外"),COUNTIFS($AB$5:AB6,"OK",$AD$5:AD6,"<>除外"),"") | BA6: =IF(OR(AZ6="",AI6=""),"",AI6+ROW()/1000000000) | BB6: =IF(E6="","",IF(OR(TRIM(E6&"")="-",TRIM(E6&"")="－",TRIM(E6&"")="ー"),"",TRIM(E6&""))) | BC6: =IF(AND(AB6="OK",BB6<>""),IF(COUNTIFS($BB$5:BB6,BB6,$AB$5:AB6,"OK")=1,1,""),"") | BD6: =IF(BC6=1,COUNTIF($BC$5:BC6,1),"") | BE6: =IF(BB6="","",IFERROR(INDEX('06_顧客別集計'!$G$5:$G$104,MATCH(BB6,'06_顧客別集計'!$C$5:$C$104,0)),BB6)) | BF6: =IF(AND(AZ6<>"",BE6<>""),IF(COUNTIFS($BE$5:BE6,BE6,$AZ$5:AZ6,">0")=1,1,""),"") | BG6: =IF(BF6=1,COUNTIF($BF$5:BF6,1),"")
AB7: =IF(AND(A7="",G7=""),"",IF(ISNUMBER(SEARCH("##END",AM7)),"（終わりの印）",IF(ISNUMBER(SEARCH("##続き",AM7)),"（続きありの印）",IF(AM7="調査ID","（見出し行）",IF(AND(AM7<>"R1",AM7<>"R2"),"×表以外の行（集計されない）",IF(COUNTIF($AN$5:AN7,AN7)>1,"△重複（集計されない）",IF(G7="","△タスク名なし",IF(ISNA(MATCH(AQ7,'M1_類型マスタ'!$A$5:$A$19,0)),"△類型が不正",IF(OR(AP7="",N(AP7)<1,N(AP7)>6),"△業務区分が不正",IF(OR(AS7="",AT7=""),"△回数・分が読めない",IF(SUMPRODUCT(--ISNUMBER(--T7:Z7))<7,"△採点が足りない",IF(SUMPRODUCT((--T7:Z7>2)+(--T7:Z7<0))>0,"△採点が範囲外","OK")))))))))))) | AC7: =IF(AB7<>"OK","",TRIM(IF(AND(AU7<>"",N(AU7)<=1),"根拠1件 ","")&IF(AV7<>"","同名あり ","")&IF(AND(NOT(ISNUMBER(N7)),N7<>""),"回数を換算 ","")&IF(J7="","詳細なし ","")&IF(AND(N(AP7)=1,BB7=""),"顧客名なし ",""))) | AH7: =IF(AB7<>"OK","",IF(AG7<>"",AG7,AJ7)) | AI7: =IF(AB7<>"OK","",IFERROR(IF(AE7<>"",AE7,AS7)*IF(AF7<>"",AF7,AT7)/60,"")) | AJ7: =IF(AB7<>"OK","",IF(OR(VALUE(T7)=2,VALUE(U7)=2,VALUE(V7)=2),"社内残置",IF(AND(VALUE(T7)=0,VALUE(W7)=0,VALUE(Y7)=0),"自動化候補",IF(AND(VALUE(U7)=0,VALUE(W7)<=1,VALUE(X7)<=1,VALUE(Y7)<=1,VALUE(Z7)<=1),"オフショア候補",IF(AND(VALUE(Y7)<=1,VALUE(Z7)<=1),"ニアショア候補","社内で手順化→再評価"))))) | AK7: =IF(AB7<>"OK","",14-SUMPRODUCT(--T7:Z7)) | AL7: =IF(AB7<>"OK","",AS7*AT7/60) | AM7: =IF(A7="","",UPPER(TRIM(ASC(A7&"")))) | AN7: =IF(AM7="","",AM7&"-"&B7) | AO7: =IF(C7="","",IFERROR(VALUE(ASC(SUBSTITUTE(C7&"","観点",""))),"")) | AP7: =IF(D7="","",IFERROR(VALUE(LEFT(TRIM(ASC(D7&"")),1)),IFERROR(MATCH(TRIM(D7&""),'M2_区分マスタ'!$I$5:$I$10,0),""))) | AQ7: =IF(H7="","",UPPER(LEFT(TRIM(ASC(H7&"")),3))) | AR7: =IF(N7="","",IFERROR(VALUE(SUBSTITUTE(SUBSTITUTE(SUBSTITUTE(SUBSTITUTE(SUBSTITUTE(SUBSTITUTE(SUBSTITUTE(SUBSTITUTE(SUBSTITUTE(SUBSTITUTE(SUBSTITUTE(SUBSTITUTE(ASC(N7&""),"約",""),"程度",""),"ほど",""),"回",""),"毎",""),"週",""),"月",""),"年",""),"日",""),"に",""),"/","")," ","")),"")) | AS7: =IF(N7="","",IF(ISNUMBER(N7),N7,IFERROR(VALUE(ASC(N7&"")),IF(AR7<>"",AR7*IF(ISNUMBER(SEARCH("週",N7)),4.3,IF(ISNUMBER(SEARCH("年",N7)),1/12,IF(ISNUMBER(SEARCH("日",N7)),20,1))),IF(ISNUMBER(SEARCH("日",N7)),20,IF(ISNUMBER(SEARCH("週",N7)),4.3,IF(ISNUMBER(SEARCH("月",N7)),1,""))))))) | AT7: =IF(O7="","",IF(ISNUMBER(O7),O7,IFERROR(VALUE(ASC(O7&"")),IF(ISNUMBER(SEARCH("時間",O7)),IFERROR(VALUE(SUBSTITUTE(SUBSTITUTE(SUBSTITUTE(SUBSTITUTE(SUBSTITUTE(ASC(O7&""),"約",""),"程度",""),"ほど",""),"時間","")," ",""))*60,""),IFERROR(VALUE(SUBSTITUTE(SUBSTITUTE(SUBSTITUTE(SUBSTITUTE(SUBSTITUTE(ASC(O7&""),"約",""),"程度",""),"ほど",""),"分","")," ","")),""))))) | AU7: =IF(P7="","",IF(ISNUMBER(P7),P7,IFERROR(VALUE(SUBSTITUTE(SUBSTITUTE(SUBSTITUTE(ASC(P7&""),"約",""),"件","")," ","")),""))) | AV7: =IF(AB7<>"OK","",IF(COUNTIFS($G$5:$G$404,G7&"",$F$5:$F$404,F7&"",$BE$5:$BE$404,BE7&"",$AB$5:$AB$404,"OK")>1,"同名あり","")) | AW7: =IF(Q7="","",IF(ISNUMBER(Q7),Q7,IFERROR(DATEVALUE(SUBSTITUTE(SUBSTITUTE(ASC(Q7&""),"-","/"),".","/")&"/01"),""))) | AX7: =IF(R7="","",IF(ISNUMBER(R7),R7,IFERROR(DATEVALUE(SUBSTITUTE(SUBSTITUTE(ASC(R7&""),"-","/"),".","/")&"/01"),""))) | AY7: =IF(OR(AB7<>"OK",AW7=""),"",IF(AW7>='01_設定'!$C$26,1,0)) | AZ7: =IF(AND(AB7="OK",AD7<>"除外"),COUNTIFS($AB$5:AB7,"OK",$AD$5:AD7,"<>除外"),"") | BA7: =IF(OR(AZ7="",AI7=""),"",AI7+ROW()/1000000000) | BB7: =IF(E7="","",IF(OR(TRIM(E7&"")="-",TRIM(E7&"")="－",TRIM(E7&"")="ー"),"",TRIM(E7&""))) | BC7: =IF(AND(AB7="OK",BB7<>""),IF(COUNTIFS($BB$5:BB7,BB7,$AB$5:AB7,"OK")=1,1,""),"") | BD7: =IF(BC7=1,COUNTIF($BC$5:BC7,1),"") | BE7: =IF(BB7="","",IFERROR(INDEX('06_顧客別集計'!$G$5:$G$104,MATCH(BB7,'06_顧客別集計'!$C$5:$C$104,0)),BB7)) | BF7: =IF(AND(AZ7<>"",BE7<>""),IF(COUNTIFS($BE$5:BE7,BE7,$AZ$5:AZ7,">0")=1,1,""),"") | BG7: =IF(BF7=1,COUNTIF($BF$5:BF7,1),"")
AB8: =IF(AND(A8="",G8=""),"",IF(ISNUMBER(SEARCH("##END",AM8)),"（終わりの印）",IF(ISNUMBER(SEARCH("##続き",AM8)),"（続きありの印）",IF(AM8="調査ID","（見出し行）",IF(AND(AM8<>"R1",AM8<>"R2"),"×表以外の行（集計されない）",IF(COUNTIF($AN$5:AN8,AN8)>1,"△重複（集計されない）",IF(G8="","△タスク名なし",IF(ISNA(MATCH(AQ8,'M1_類型マスタ'!$A$5:$A$19,0)),"△類型が不正",IF(OR(AP8="",N(AP8)<1,N(AP8)>6),"△業務区分が不正",IF(OR(AS8="",AT8=""),"△回数・分が読めない",IF(SUMPRODUCT(--ISNUMBER(--T8:Z8))<7,"△採点が足りない",IF(SUMPRODUCT((--T8:Z8>2)+(--T8:Z8<0))>0,"△採点が範囲外","OK")))))))))))) | AC8: =IF(AB8<>"OK","",TRIM(IF(AND(AU8<>"",N(AU8)<=1),"根拠1件 ","")&IF(AV8<>"","同名あり ","")&IF(AND(NOT(ISNUMBER(N8)),N8<>""),"回数を換算 ","")&IF(J8="","詳細なし ","")&IF(AND(N(AP8)=1,BB8=""),"顧客名なし ",""))) | AH8: =IF(AB8<>"OK","",IF(AG8<>"",AG8,AJ8)) | AI8: =IF(AB8<>"OK","",IFERROR(IF(AE8<>"",AE8,AS8)*IF(AF8<>"",AF8,AT8)/60,"")) | AJ8: =IF(AB8<>"OK","",IF(OR(VALUE(T8)=2,VALUE(U8)=2,VALUE(V8)=2),"社内残置",IF(AND(VALUE(T8)=0,VALUE(W8)=0,VALUE(Y8)=0),"自動化候補",IF(AND(VALUE(U8)=0,VALUE(W8)<=1,VALUE(X8)<=1,VALUE(Y8)<=1,VALUE(Z8)<=1),"オフショア候補",IF(AND(VALUE(Y8)<=1,VALUE(Z8)<=1),"ニアショア候補","社内で手順化→再評価"))))) | AK8: =IF(AB8<>"OK","",14-SUMPRODUCT(--T8:Z8)) | AL8: =IF(AB8<>"OK","",AS8*AT8/60) | AM8: =IF(A8="","",UPPER(TRIM(ASC(A8&"")))) | AN8: =IF(AM8="","",AM8&"-"&B8) | AO8: =IF(C8="","",IFERROR(VALUE(ASC(SUBSTITUTE(C8&"","観点",""))),"")) | AP8: =IF(D8="","",IFERROR(VALUE(LEFT(TRIM(ASC(D8&"")),1)),IFERROR(MATCH(TRIM(D8&""),'M2_区分マスタ'!$I$5:$I$10,0),""))) | AQ8: =IF(H8="","",UPPER(LEFT(TRIM(ASC(H8&"")),3))) | AR8: =IF(N8="","",IFERROR(VALUE(SUBSTITUTE(SUBSTITUTE(SUBSTITUTE(SUBSTITUTE(SUBSTITUTE(SUBSTITUTE(SUBSTITUTE(SUBSTITUTE(SUBSTITUTE(SUBSTITUTE(SUBSTITUTE(SUBSTITUTE(ASC(N8&""),"約",""),"程度",""),"ほど",""),"回",""),"毎",""),"週",""),"月",""),"年",""),"日",""),"に",""),"/","")," ","")),"")) | AS8: =IF(N8="","",IF(ISNUMBER(N8),N8,IFERROR(VALUE(ASC(N8&"")),IF(AR8<>"",AR8*IF(ISNUMBER(SEARCH("週",N8)),4.3,IF(ISNUMBER(SEARCH("年",N8)),1/12,IF(ISNUMBER(SEARCH("日",N8)),20,1))),IF(ISNUMBER(SEARCH("日",N8)),20,IF(ISNUMBER(SEARCH("週",N8)),4.3,IF(ISNUMBER(SEARCH("月",N8)),1,""))))))) | AT8: =IF(O8="","",IF(ISNUMBER(O8),O8,IFERROR(VALUE(ASC(O8&"")),IF(ISNUMBER(SEARCH("時間",O8)),IFERROR(VALUE(SUBSTITUTE(SUBSTITUTE(SUBSTITUTE(SUBSTITUTE(SUBSTITUTE(ASC(O8&""),"約",""),"程度",""),"ほど",""),"時間","")," ",""))*60,""),IFERROR(VALUE(SUBSTITUTE(SUBSTITUTE(SUBSTITUTE(SUBSTITUTE(SUBSTITUTE(ASC(O8&""),"約",""),"程度",""),"ほど",""),"分","")," ","")),""))))) | AU8: =IF(P8="","",IF(ISNUMBER(P8),P8,IFERROR(VALUE(SUBSTITUTE(SUBSTITUTE(SUBSTITUTE(ASC(P8&""),"約",""),"件","")," ","")),""))) | AV8: =IF(AB8<>"OK","",IF(COUNTIFS($G$5:$G$404,G8&"",$F$5:$F$404,F8&"",$BE$5:$BE$404,BE8&"",$AB$5:$AB$404,"OK")>1,"同名あり","")) | AW8: =IF(Q8="","",IF(ISNUMBER(Q8),Q8,IFERROR(DATEVALUE(SUBSTITUTE(SUBSTITUTE(ASC(Q8&""),"-","/"),".","/")&"/01"),""))) | AX8: =IF(R8="","",IF(ISNUMBER(R8),R8,IFERROR(DATEVALUE(SUBSTITUTE(SUBSTITUTE(ASC(R8&""),"-","/"),".","/")&"/01"),""))) | AY8: =IF(OR(AB8<>"OK",AW8=""),"",IF(AW8>='01_設定'!$C$26,1,0)) | AZ8: =IF(AND(AB8="OK",AD8<>"除外"),COUNTIFS($AB$5:AB8,"OK",$AD$5:AD8,"<>除外"),"") | BA8: =IF(OR(AZ8="",AI8=""),"",AI8+ROW()/1000000000) | BB8: =IF(E8="","",IF(OR(TRIM(E8&"")="-",TRIM(E8&"")="－",TRIM(E8&"")="ー"),"",TRIM(E8&""))) | BC8: =IF(AND(AB8="OK",BB8<>""),IF(COUNTIFS($BB$5:BB8,BB8,$AB$5:AB8,"OK")=1,1,""),"") | BD8: =IF(BC8=1,COUNTIF($BC$5:BC8,1),"") | BE8: =IF(BB8="","",IFERROR(INDEX('06_顧客別集計'!$G$5:$G$104,MATCH(BB8,'06_顧客別集計'!$C$5:$C$104,0)),BB8)) | BF8: =IF(AND(AZ8<>"",BE8<>""),IF(COUNTIFS($BE$5:BE8,BE8,$AZ$5:AZ8,">0")=1,1,""),"") | BG8: =IF(BF8=1,COUNTIF($BF$5:BF8,1),"")
AB9: =IF(AND(A9="",G9=""),"",IF(ISNUMBER(SEARCH("##END",AM9)),"（終わりの印）",IF(ISNUMBER(SEARCH("##続き",AM9)),"（続きありの印）",IF(AM9="調査ID","（見出し行）",IF(AND(AM9<>"R1",AM9<>"R2"),"×表以外の行（集計されない）",IF(COUNTIF($AN$5:AN9,AN9)>1,"△重複（集計されない）",IF(G9="","△タスク名なし",IF(ISNA(MATCH(AQ9,'M1_類型マスタ'!$A$5:$A$19,0)),"△類型が不正",IF(OR(AP9="",N(AP9)<1,N(AP9)>6),"△業務区分が不正",IF(OR(AS9="",AT9=""),"△回数・分が読めない",IF(SUMPRODUCT(--ISNUMBER(--T9:Z9))<7,"△採点が足りない",IF(SUMPRODUCT((--T9:Z9>2)+(--T9:Z9<0))>0,"△採点が範囲外","OK")))))))))))) | AC9: =IF(AB9<>"OK","",TRIM(IF(AND(AU9<>"",N(AU9)<=1),"根拠1件 ","")&IF(AV9<>"","同名あり ","")&IF(AND(NOT(ISNUMBER(N9)),N9<>""),"回数を換算 ","")&IF(J9="","詳細なし ","")&IF(AND(N(AP9)=1,BB9=""),"顧客名なし ",""))) | AH9: =IF(AB9<>"OK","",IF(AG9<>"",AG9,AJ9)) | AI9: =IF(AB9<>"OK","",IFERROR(IF(AE9<>"",AE9,AS9)*IF(AF9<>"",AF9,AT9)/60,"")) | AJ9: =IF(AB9<>"OK","",IF(OR(VALUE(T9)=2,VALUE(U9)=2,VALUE(V9)=2),"社内残置",IF(AND(VALUE(T9)=0,VALUE(W9)=0,VALUE(Y9)=0),"自動化候補",IF(AND(VALUE(U9)=0,VALUE(W9)<=1,VALUE(X9)<=1,VALUE(Y9)<=1,VALUE(Z9)<=1),"オフショア候補",IF(AND(VALUE(Y9)<=1,VALUE(Z9)<=1),"ニアショア候補","社内で手順化→再評価"))))) | AK9: =IF(AB9<>"OK","",14-SUMPRODUCT(--T9:Z9)) | AL9: =IF(AB9<>"OK","",AS9*AT9/60) | AM9: =IF(A9="","",UPPER(TRIM(ASC(A9&"")))) | AN9: =IF(AM9="","",AM9&"-"&B9) | AO9: =IF(C9="","",IFERROR(VALUE(ASC(SUBSTITUTE(C9&"","観点",""))),"")) | AP9: =IF(D9="","",IFERROR(VALUE(LEFT(TRIM(ASC(D9&"")),1)),IFERROR(MATCH(TRIM(D9&""),'M2_区分マスタ'!$I$5:$I$10,0),""))) | AQ9: =IF(H9="","",UPPER(LEFT(TRIM(ASC(H9&"")),3))) | AR9: =IF(N9="","",IFERROR(VALUE(SUBSTITUTE(SUBSTITUTE(SUBSTITUTE(SUBSTITUTE(SUBSTITUTE(SUBSTITUTE(SUBSTITUTE(SUBSTITUTE(SUBSTITUTE(SUBSTITUTE(SUBSTITUTE(SUBSTITUTE(ASC(N9&""),"約",""),"程度",""),"ほど",""),"回",""),"毎",""),"週",""),"月",""),"年",""),"日",""),"に",""),"/","")," ","")),"")) | AS9: =IF(N9="","",IF(ISNUMBER(N9),N9,IFERROR(VALUE(ASC(N9&"")),IF(AR9<>"",AR9*IF(ISNUMBER(SEARCH("週",N9)),4.3,IF(ISNUMBER(SEARCH("年",N9)),1/12,IF(ISNUMBER(SEARCH("日",N9)),20,1))),IF(ISNUMBER(SEARCH("日",N9)),20,IF(ISNUMBER(SEARCH("週",N9)),4.3,IF(ISNUMBER(SEARCH("月",N9)),1,""))))))) | AT9: =IF(O9="","",IF(ISNUMBER(O9),O9,IFERROR(VALUE(ASC(O9&"")),IF(ISNUMBER(SEARCH("時間",O9)),IFERROR(VALUE(SUBSTITUTE(SUBSTITUTE(SUBSTITUTE(SUBSTITUTE(SUBSTITUTE(ASC(O9&""),"約",""),"程度",""),"ほど",""),"時間","")," ",""))*60,""),IFERROR(VALUE(SUBSTITUTE(SUBSTITUTE(SUBSTITUTE(SUBSTITUTE(SUBSTITUTE(ASC(O9&""),"約",""),"程度",""),"ほど",""),"分","")," ","")),""))))) | AU9: =IF(P9="","",IF(ISNUMBER(P9),P9,IFERROR(VALUE(SUBSTITUTE(SUBSTITUTE(SUBSTITUTE(ASC(P9&""),"約",""),"件","")," ","")),""))) | AV9: =IF(AB9<>"OK","",IF(COUNTIFS($G$5:$G$404,G9&"",$F$5:$F$404,F9&"",$BE$5:$BE$404,BE9&"",$AB$5:$AB$404,"OK")>1,"同名あり","")) | AW9: =IF(Q9="","",IF(ISNUMBER(Q9),Q9,IFERROR(DATEVALUE(SUBSTITUTE(SUBSTITUTE(ASC(Q9&""),"-","/"),".","/")&"/01"),""))) | AX9: =IF(R9="","",IF(ISNUMBER(R9),R9,IFERROR(DATEVALUE(SUBSTITUTE(SUBSTITUTE(ASC(R9&""),"-","/"),".","/")&"/01"),""))) | AY9: =IF(OR(AB9<>"OK",AW9=""),"",IF(AW9>='01_設定'!$C$26,1,0)) | AZ9: =IF(AND(AB9="OK",AD9<>"除外"),COUNTIFS($AB$5:AB9,"OK",$AD$5:AD9,"<>除外"),"") | BA9: =IF(OR(AZ9="",AI9=""),"",AI9+ROW()/1000000000) | BB9: =IF(E9="","",IF(OR(TRIM(E9&"")="-",TRIM(E9&"")="－",TRIM(E9&"")="ー"),"",TRIM(E9&""))) | BC9: =IF(AND(AB9="OK",BB9<>""),IF(COUNTIFS($BB$5:BB9,BB9,$AB$5:AB9,"OK")=1,1,""),"") | BD9: =IF(BC9=1,COUNTIF($BC$5:BC9,1),"") | BE9: =IF(BB9="","",IFERROR(INDEX('06_顧客別集計'!$G$5:$G$104,MATCH(BB9,'06_顧客別集計'!$C$5:$C$104,0)),BB9)) | BF9: =IF(AND(AZ9<>"",BE9<>""),IF(COUNTIFS($BE$5:BE9,BE9,$AZ$5:AZ9,">0")=1,1,""),"") | BG9: =IF(BF9=1,COUNTIF($BF$5:BF9,1),"")
AB10: =IF(AND(A10="",G10=""),"",IF(ISNUMBER(SEARCH("##END",AM10)),"（終わりの印）",IF(ISNUMBER(SEARCH("##続き",AM10)),"（続きありの印）",IF(AM10="調査ID","（見出し行）",IF(AND(AM10<>"R1",AM10<>"R2"),"×表以外の行（集計されない）",IF(COUNTIF($AN$5:AN10,AN10)>1,"△重複（集計されない）",IF(G10="","△タスク名なし",IF(ISNA(MATCH(AQ10,'M1_類型マスタ'!$A$5:$A$19,0)),"△類型が不正",IF(OR(AP10="",N(AP10)<1,N(AP10)>6),"△業務区分が不正",IF(OR(AS10="",AT10=""),"△回数・分が読めない",IF(SUMPRODUCT(--ISNUMBER(--T10:Z10))<7,"△採点が足りない",IF(SUMPRODUCT((--T10:Z10>2)+(--T10:Z10<0))>0,"△採点が範囲外","OK")))))))))))) | AC10: =IF(AB10<>"OK","",TRIM(IF(AND(AU10<>"",N(AU10)<=1),"根拠1件 ","")&IF(AV10<>"","同名あり ","")&IF(AND(NOT(ISNUMBER(N10)),N10<>""),"回数を換算 ","")&IF(J10="","詳細なし ","")&IF(AND(N(AP10)=1,BB10=""),"顧客名なし ",""))) | AH10: =IF(AB10<>"OK","",IF(AG10<>"",AG10,AJ10)) | AI10: =IF(AB10<>"OK","",IFERROR(IF(AE10<>"",AE10,AS10)*IF(AF10<>"",AF10,AT10)/60,"")) | AJ10: =IF(AB10<>"OK","",IF(OR(VALUE(T10)=2,VALUE(U10)=2,VALUE(V10)=2),"社内残置",IF(AND(VALUE(T10)=0,VALUE(W10)=0,VALUE(Y10)=0),"自動化候補",IF(AND(VALUE(U10)=0,VALUE(W10)<=1,VALUE(X10)<=1,VALUE(Y10)<=1,VALUE(Z10)<=1),"オフショア候補",IF(AND(VALUE(Y10)<=1,VALUE(Z10)<=1),"ニアショア候補","社内で手順化→再評価"))))) | AK10: =IF(AB10<>"OK","",14-SUMPRODUCT(--T10:Z10)) | AL10: =IF(AB10<>"OK","",AS10*AT10/60) | AM10: =IF(A10="","",UPPER(TRIM(ASC(A10&"")))) | AN10: =IF(AM10="","",AM10&"-"&B10) | AO10: =IF(C10="","",IFERROR(VALUE(ASC(SUBSTITUTE(C10&"","観点",""))),"")) | AP10: =IF(D10="","",IFERROR(VALUE(LEFT(TRIM(ASC(D10&"")),1)),IFERROR(MATCH(TRIM(D10&""),'M2_区分マスタ'!$I$5:$I$10,0),""))) | AQ10: =IF(H10="","",UPPER(LEFT(TRIM(ASC(H10&"")),3))) | AR10: =IF(N10="","",IFERROR(VALUE(SUBSTITUTE(SUBSTITUTE(SUBSTITUTE(SUBSTITUTE(SUBSTITUTE(SUBSTITUTE(SUBSTITUTE(SUBSTITUTE(SUBSTITUTE(SUBSTITUTE(SUBSTITUTE(SUBSTITUTE(ASC(N10&""),"約",""),"程度",""),"ほど",""),"回",""),"毎",""),"週",""),"月",""),"年",""),"日",""),"に",""),"/","")," ","")),"")) | AS10: =IF(N10="","",IF(ISNUMBER(N10),N10,IFERROR(VALUE(ASC(N10&"")),IF(AR10<>"",AR10*IF(ISNUMBER(SEARCH("週",N10)),4.3,IF(ISNUMBER(SEARCH("年",N10)),1/12,IF(ISNUMBER(SEARCH("日",N10)),20,1))),IF(ISNUMBER(SEARCH("日",N10)),20,IF(ISNUMBER(SEARCH("週",N10)),4.3,IF(ISNUMBER(SEARCH("月",N10)),1,""))))))) | AT10: =IF(O10="","",IF(ISNUMBER(O10),O10,IFERROR(VALUE(ASC(O10&"")),IF(ISNUMBER(SEARCH("時間",O10)),IFERROR(VALUE(SUBSTITUTE(SUBSTITUTE(SUBSTITUTE(SUBSTITUTE(SUBSTITUTE(ASC(O10&""),"約",""),"程度",""),"ほど",""),"時間","")," ",""))*60,""),IFERROR(VALUE(SUBSTITUTE(SUBSTITUTE(SUBSTITUTE(SUBSTITUTE(SUBSTITUTE(ASC(O10&""),"約",""),"程度",""),"ほど",""),"分","")," ","")),""))))) | AU10: =IF(P10="","",IF(ISNUMBER(P10),P10,IFERROR(VALUE(SUBSTITUTE(SUBSTITUTE(SUBSTITUTE(ASC(P10&""),"約",""),"件","")," ","")),""))) | AV10: =IF(AB10<>"OK","",IF(COUNTIFS($G$5:$G$404,G10&"",$F$5:$F$404,F10&"",$BE$5:$BE$404,BE10&"",$AB$5:$AB$404,"OK")>1,"同名あり","")) | AW10: =IF(Q10="","",IF(ISNUMBER(Q10),Q10,IFERROR(DATEVALUE(SUBSTITUTE(SUBSTITUTE(ASC(Q10&""),"-","/"),".","/")&"/01"),""))) | AX10: =IF(R10="","",IF(ISNUMBER(R10),R10,IFERROR(DATEVALUE(SUBSTITUTE(SUBSTITUTE(ASC(R10&""),"-","/"),".","/")&"/01"),""))) | AY10: =IF(OR(AB10<>"OK",AW10=""),"",IF(AW10>='01_設定'!$C$26,1,0)) | AZ10: =IF(AND(AB10="OK",AD10<>"除外"),COUNTIFS($AB$5:AB10,"OK",$AD$5:AD10,"<>除外"),"") | BA10: =IF(OR(AZ10="",AI10=""),"",AI10+ROW()/1000000000) | BB10: =IF(E10="","",IF(OR(TRIM(E10&"")="-",TRIM(E10&"")="－",TRIM(E10&"")="ー"),"",TRIM(E10&""))) | BC10: =IF(AND(AB10="OK",BB10<>""),IF(COUNTIFS($BB$5:BB10,BB10,$AB$5:AB10,"OK")=1,1,""),"") | BD10: =IF(BC10=1,COUNTIF($BC$5:BC10,1),"") | BE10: =IF(BB10="","",IFERROR(INDEX('06_顧客別集計'!$G$5:$G$104,MATCH(BB10,'06_顧客別集計'!$C$5:$C$104,0)),BB10)) | BF10: =IF(AND(AZ10<>"",BE10<>""),IF(COUNTIFS($BE$5:BE10,BE10,$AZ$5:AZ10,">0")=1,1,""),"") | BG10: =IF(BF10=1,COUNTIF($BF$5:BF10,1),"")
AB11: =IF(AND(A11="",G11=""),"",IF(ISNUMBER(SEARCH("##END",AM11)),"（終わりの印）",IF(ISNUMBER(SEARCH("##続き",AM11)),"（続きありの印）",IF(AM11="調査ID","（見出し行）",IF(AND(AM11<>"R1",AM11<>"R2"),"×表以外の行（集計されない）",IF(COUNTIF($AN$5:AN11,AN11)>1,"△重複（集計されない）",IF(G11="","△タスク名なし",IF(ISNA(MATCH(AQ11,'M1_類型マスタ'!$A$5:$A$19,0)),"△類型が不正",IF(OR(AP11="",N(AP11)<1,N(AP11)>6),"△業務区分が不正",IF(OR(AS11="",AT11=""),"△回数・分が読めない",IF(SUMPRODUCT(--ISNUMBER(--T11:Z11))<7,"△採点が足りない",IF(SUMPRODUCT((--T11:Z11>2)+(--T11:Z11<0))>0,"△採点が範囲外","OK")))))))))))) | AC11: =IF(AB11<>"OK","",TRIM(IF(AND(AU11<>"",N(AU11)<=1),"根拠1件 ","")&IF(AV11<>"","同名あり ","")&IF(AND(NOT(ISNUMBER(N11)),N11<>""),"回数を換算 ","")&IF(J11="","詳細なし ","")&IF(AND(N(AP11)=1,BB11=""),"顧客名なし ",""))) | AH11: =IF(AB11<>"OK","",IF(AG11<>"",AG11,AJ11)) | AI11: =IF(AB11<>"OK","",IFERROR(IF(AE11<>"",AE11,AS11)*IF(AF11<>"",AF11,AT11)/60,"")) | AJ11: =IF(AB11<>"OK","",IF(OR(VALUE(T11)=2,VALUE(U11)=2,VALUE(V11)=2),"社内残置",IF(AND(VALUE(T11)=0,VALUE(W11)=0,VALUE(Y11)=0),"自動化候補",IF(AND(VALUE(U11)=0,VALUE(W11)<=1,VALUE(X11)<=1,VALUE(Y11)<=1,VALUE(Z11)<=1),"オフショア候補",IF(AND(VALUE(Y11)<=1,VALUE(Z11)<=1),"ニアショア候補","社内で手順化→再評価"))))) | AK11: =IF(AB11<>"OK","",14-SUMPRODUCT(--T11:Z11)) | AL11: =IF(AB11<>"OK","",AS11*AT11/60) | AM11: =IF(A11="","",UPPER(TRIM(ASC(A11&"")))) | AN11: =IF(AM11="","",AM11&"-"&B11) | AO11: =IF(C11="","",IFERROR(VALUE(ASC(SUBSTITUTE(C11&"","観点",""))),"")) | AP11: =IF(D11="","",IFERROR(VALUE(LEFT(TRIM(ASC(D11&"")),1)),IFERROR(MATCH(TRIM(D11&""),'M2_区分マスタ'!$I$5:$I$10,0),""))) | AQ11: =IF(H11="","",UPPER(LEFT(TRIM(ASC(H11&"")),3))) | AR11: =IF(N11="","",IFERROR(VALUE(SUBSTITUTE(SUBSTITUTE(SUBSTITUTE(SUBSTITUTE(SUBSTITUTE(SUBSTITUTE(SUBSTITUTE(SUBSTITUTE(SUBSTITUTE(SUBSTITUTE(SUBSTITUTE(SUBSTITUTE(ASC(N11&""),"約",""),"程度",""),"ほど",""),"回",""),"毎",""),"週",""),"月",""),"年",""),"日",""),"に",""),"/","")," ","")),"")) | AS11: =IF(N11="","",IF(ISNUMBER(N11),N11,IFERROR(VALUE(ASC(N11&"")),IF(AR11<>"",AR11*IF(ISNUMBER(SEARCH("週",N11)),4.3,IF(ISNUMBER(SEARCH("年",N11)),1/12,IF(ISNUMBER(SEARCH("日",N11)),20,1))),IF(ISNUMBER(SEARCH("日",N11)),20,IF(ISNUMBER(SEARCH("週",N11)),4.3,IF(ISNUMBER(SEARCH("月",N11)),1,""))))))) | AT11: =IF(O11="","",IF(ISNUMBER(O11),O11,IFERROR(VALUE(ASC(O11&"")),IF(ISNUMBER(SEARCH("時間",O11)),IFERROR(VALUE(SUBSTITUTE(SUBSTITUTE(SUBSTITUTE(SUBSTITUTE(SUBSTITUTE(ASC(O11&""),"約",""),"程度",""),"ほど",""),"時間","")," ",""))*60,""),IFERROR(VALUE(SUBSTITUTE(SUBSTITUTE(SUBSTITUTE(SUBSTITUTE(SUBSTITUTE(ASC(O11&""),"約",""),"程度",""),"ほど",""),"分","")," ","")),""))))) | AU11: =IF(P11="","",IF(ISNUMBER(P11),P11,IFERROR(VALUE(SUBSTITUTE(SUBSTITUTE(SUBSTITUTE(ASC(P11&""),"約",""),"件","")," ","")),""))) | AV11: =IF(AB11<>"OK","",IF(COUNTIFS($G$5:$G$404,G11&"",$F$5:$F$404,F11&"",$BE$5:$BE$404,BE11&"",$AB$5:$AB$404,"OK")>1,"同名あり","")) | AW11: =IF(Q11="","",IF(ISNUMBER(Q11),Q11,IFERROR(DATEVALUE(SUBSTITUTE(SUBSTITUTE(ASC(Q11&""),"-","/"),".","/")&"/01"),""))) | AX11: =IF(R11="","",IF(ISNUMBER(R11),R11,IFERROR(DATEVALUE(SUBSTITUTE(SUBSTITUTE(ASC(R11&""),"-","/"),".","/")&"/01"),""))) | AY11: =IF(OR(AB11<>"OK",AW11=""),"",IF(AW11>='01_設定'!$C$26,1,0)) | AZ11: =IF(AND(AB11="OK",AD11<>"除外"),COUNTIFS($AB$5:AB11,"OK",$AD$5:AD11,"<>除外"),"") | BA11: =IF(OR(AZ11="",AI11=""),"",AI11+ROW()/1000000000) | BB11: =IF(E11="","",IF(OR(TRIM(E11&"")="-",TRIM(E11&"")="－",TRIM(E11&"")="ー"),"",TRIM(E11&""))) | BC11: =IF(AND(AB11="OK",BB11<>""),IF(COUNTIFS($BB$5:BB11,BB11,$AB$5:AB11,"OK")=1,1,""),"") | BD11: =IF(BC11=1,COUNTIF($BC$5:BC11,1),"") | BE11: =IF(BB11="","",IFERROR(INDEX('06_顧客別集計'!$G$5:$G$104,MATCH(BB11,'06_顧客別集計'!$C$5:$C$104,0)),BB11)) | BF11: =IF(AND(AZ11<>"",BE11<>""),IF(COUNTIFS($BE$5:BE11,BE11,$AZ$5:AZ11,">0")=1,1,""),"") | BG11: =IF(BF11=1,COUNTIF($BF$5:BF11,1),"")
AB12: =IF(AND(A12="",G12=""),"",IF(ISNUMBER(SEARCH("##END",AM12)),"（終わりの印）",IF(ISNUMBER(SEARCH("##続き",AM12)),"（続きありの印）",IF(AM12="調査ID","（見出し行）",IF(AND(AM12<>"R1",AM12<>"R2"),"×表以外の行（集計されない）",IF(COUNTIF($AN$5:AN12,AN12)>1,"△重複（集計されない）",IF(G12="","△タスク名なし",IF(ISNA(MATCH(AQ12,'M1_類型マスタ'!$A$5:$A$19,0)),"△類型が不正",IF(OR(AP12="",N(AP12)<1,N(AP12)>6),"△業務区分が不正",IF(OR(AS12="",AT12=""),"△回数・分が読めない",IF(SUMPRODUCT(--ISNUMBER(--T12:Z12))<7,"△採点が足りない",IF(SUMPRODUCT((--T12:Z12>2)+(--T12:Z12<0))>0,"△採点が範囲外","OK")))))))))))) | AC12: =IF(AB12<>"OK","",TRIM(IF(AND(AU12<>"",N(AU12)<=1),"根拠1件 ","")&IF(AV12<>"","同名あり ","")&IF(AND(NOT(ISNUMBER(N12)),N12<>""),"回数を換算 ","")&IF(J12="","詳細なし ","")&IF(AND(N(AP12)=1,BB12=""),"顧客名なし ",""))) | AH12: =IF(AB12<>"OK","",IF(AG12<>"",AG12,AJ12)) | AI12: =IF(AB12<>"OK","",IFERROR(IF(AE12<>"",AE12,AS12)*IF(AF12<>"",AF12,AT12)/60,"")) | AJ12: =IF(AB12<>"OK","",IF(OR(VALUE(T12)=2,VALUE(U12)=2,VALUE(V12)=2),"社内残置",IF(AND(VALUE(T12)=0,VALUE(W12)=0,VALUE(Y12)=0),"自動化候補",IF(AND(VALUE(U12)=0,VALUE(W12)<=1,VALUE(X12)<=1,VALUE(Y12)<=1,VALUE(Z12)<=1),"オフショア候補",IF(AND(VALUE(Y12)<=1,VALUE(Z12)<=1),"ニアショア候補","社内で手順化→再評価"))))) | AK12: =IF(AB12<>"OK","",14-SUMPRODUCT(--T12:Z12)) | AL12: =IF(AB12<>"OK","",AS12*AT12/60) | AM12: =IF(A12="","",UPPER(TRIM(ASC(A12&"")))) | AN12: =IF(AM12="","",AM12&"-"&B12) | AO12: =IF(C12="","",IFERROR(VALUE(ASC(SUBSTITUTE(C12&"","観点",""))),"")) | AP12: =IF(D12="","",IFERROR(VALUE(LEFT(TRIM(ASC(D12&"")),1)),IFERROR(MATCH(TRIM(D12&""),'M2_区分マスタ'!$I$5:$I$10,0),""))) | AQ12: =IF(H12="","",UPPER(LEFT(TRIM(ASC(H12&"")),3))) | AR12: =IF(N12="","",IFERROR(VALUE(SUBSTITUTE(SUBSTITUTE(SUBSTITUTE(SUBSTITUTE(SUBSTITUTE(SUBSTITUTE(SUBSTITUTE(SUBSTITUTE(SUBSTITUTE(SUBSTITUTE(SUBSTITUTE(SUBSTITUTE(ASC(N12&""),"約",""),"程度",""),"ほど",""),"回",""),"毎",""),"週",""),"月",""),"年",""),"日",""),"に",""),"/","")," ","")),"")) | AS12: =IF(N12="","",IF(ISNUMBER(N12),N12,IFERROR(VALUE(ASC(N12&"")),IF(AR12<>"",AR12*IF(ISNUMBER(SEARCH("週",N12)),4.3,IF(ISNUMBER(SEARCH("年",N12)),1/12,IF(ISNUMBER(SEARCH("日",N12)),20,1))),IF(ISNUMBER(SEARCH("日",N12)),20,IF(ISNUMBER(SEARCH("週",N12)),4.3,IF(ISNUMBER(SEARCH("月",N12)),1,""))))))) | AT12: =IF(O12="","",IF(ISNUMBER(O12),O12,IFERROR(VALUE(ASC(O12&"")),IF(ISNUMBER(SEARCH("時間",O12)),IFERROR(VALUE(SUBSTITUTE(SUBSTITUTE(SUBSTITUTE(SUBSTITUTE(SUBSTITUTE(ASC(O12&""),"約",""),"程度",""),"ほど",""),"時間","")," ",""))*60,""),IFERROR(VALUE(SUBSTITUTE(SUBSTITUTE(SUBSTITUTE(SUBSTITUTE(SUBSTITUTE(ASC(O12&""),"約",""),"程度",""),"ほど",""),"分","")," ","")),""))))) | AU12: =IF(P12="","",IF(ISNUMBER(P12),P12,IFERROR(VALUE(SUBSTITUTE(SUBSTITUTE(SUBSTITUTE(ASC(P12&""),"約",""),"件","")," ","")),""))) | AV12: =IF(AB12<>"OK","",IF(COUNTIFS($G$5:$G$404,G12&"",$F$5:$F$404,F12&"",$BE$5:$BE$404,BE12&"",$AB$5:$AB$404,"OK")>1,"同名あり","")) | AW12: =IF(Q12="","",IF(ISNUMBER(Q12),Q12,IFERROR(DATEVALUE(SUBSTITUTE(SUBSTITUTE(ASC(Q12&""),"-","/"),".","/")&"/01"),""))) | AX12: =IF(R12="","",IF(ISNUMBER(R12),R12,IFERROR(DATEVALUE(SUBSTITUTE(SUBSTITUTE(ASC(R12&""),"-","/"),".","/")&"/01"),""))) | AY12: =IF(OR(AB12<>"OK",AW12=""),"",IF(AW12>='01_設定'!$C$26,1,0)) | AZ12: =IF(AND(AB12="OK",AD12<>"除外"),COUNTIFS($AB$5:AB12,"OK",$AD$5:AD12,"<>除外"),"") | BA12: =IF(OR(AZ12="",AI12=""),"",AI12+ROW()/1000000000) | BB12: =IF(E12="","",IF(OR(TRIM(E12&"")="-",TRIM(E12&"")="－",TRIM(E12&"")="ー"),"",TRIM(E12&""))) | BC12: =IF(AND(AB12="OK",BB12<>""),IF(COUNTIFS($BB$5:BB12,BB12,$AB$5:AB12,"OK")=1,1,""),"") | BD12: =IF(BC12=1,COUNTIF($BC$5:BC12,1),"") | BE12: =IF(BB12="","",IFERROR(INDEX('06_顧客別集計'!$G$5:$G$104,MATCH(BB12,'06_顧客別集計'!$C$5:$C$104,0)),BB12)) | BF12: =IF(AND(AZ12<>"",BE12<>""),IF(COUNTIFS($BE$5:BE12,BE12,$AZ$5:AZ12,">0")=1,1,""),"") | BG12: =IF(BF12=1,COUNTIF($BF$5:BF12,1),"")
AB13: =IF(AND(A13="",G13=""),"",IF(ISNUMBER(SEARCH("##END",AM13)),"（終わりの印）",IF(ISNUMBER(SEARCH("##続き",AM13)),"（続きありの印）",IF(AM13="調査ID","（見出し行）",IF(AND(AM13<>"R1",AM13<>"R2"),"×表以外の行（集計されない）",IF(COUNTIF($AN$5:AN13,AN13)>1,"△重複（集計されない）",IF(G13="","△タスク名なし",IF(ISNA(MATCH(AQ13,'M1_類型マスタ'!$A$5:$A$19,0)),"△類型が不正",IF(OR(AP13="",N(AP13)<1,N(AP13)>6),"△業務区分が不正",IF(OR(AS13="",AT13=""),"△回数・分が読めない",IF(SUMPRODUCT(--ISNUMBER(--T13:Z13))<7,"△採点が足りない",IF(SUMPRODUCT((--T13:Z13>2)+(--T13:Z13<0))>0,"△採点が範囲外","OK")))))))))))) | AC13: =IF(AB13<>"OK","",TRIM(IF(AND(AU13<>"",N(AU13)<=1),"根拠1件 ","")&IF(AV13<>"","同名あり ","")&IF(AND(NOT(ISNUMBER(N13)),N13<>""),"回数を換算 ","")&IF(J13="","詳細なし ","")&IF(AND(N(AP13)=1,BB13=""),"顧客名なし ",""))) | AH13: =IF(AB13<>"OK","",IF(AG13<>"",AG13,AJ13)) | AI13: =IF(AB13<>"OK","",IFERROR(IF(AE13<>"",AE13,AS13)*IF(AF13<>"",AF13,AT13)/60,"")) | AJ13: =IF(AB13<>"OK","",IF(OR(VALUE(T13)=2,VALUE(U13)=2,VALUE(V13)=2),"社内残置",IF(AND(VALUE(T13)=0,VALUE(W13)=0,VALUE(Y13)=0),"自動化候補",IF(AND(VALUE(U13)=0,VALUE(W13)<=1,VALUE(X13)<=1,VALUE(Y13)<=1,VALUE(Z13)<=1),"オフショア候補",IF(AND(VALUE(Y13)<=1,VALUE(Z13)<=1),"ニアショア候補","社内で手順化→再評価"))))) | AK13: =IF(AB13<>"OK","",14-SUMPRODUCT(--T13:Z13)) | AL13: =IF(AB13<>"OK","",AS13*AT13/60) | AM13: =IF(A13="","",UPPER(TRIM(ASC(A13&"")))) | AN13: =IF(AM13="","",AM13&"-"&B13) | AO13: =IF(C13="","",IFERROR(VALUE(ASC(SUBSTITUTE(C13&"","観点",""))),"")) | AP13: =IF(D13="","",IFERROR(VALUE(LEFT(TRIM(ASC(D13&"")),1)),IFERROR(MATCH(TRIM(D13&""),'M2_区分マスタ'!$I$5:$I$10,0),""))) | AQ13: =IF(H13="","",UPPER(LEFT(TRIM(ASC(H13&"")),3))) | AR13: =IF(N13="","",IFERROR(VALUE(SUBSTITUTE(SUBSTITUTE(SUBSTITUTE(SUBSTITUTE(SUBSTITUTE(SUBSTITUTE(SUBSTITUTE(SUBSTITUTE(SUBSTITUTE(SUBSTITUTE(SUBSTITUTE(SUBSTITUTE(ASC(N13&""),"約",""),"程度",""),"ほど",""),"回",""),"毎",""),"週",""),"月",""),"年",""),"日",""),"に",""),"/","")," ","")),"")) | AS13: =IF(N13="","",IF(ISNUMBER(N13),N13,IFERROR(VALUE(ASC(N13&"")),IF(AR13<>"",AR13*IF(ISNUMBER(SEARCH("週",N13)),4.3,IF(ISNUMBER(SEARCH("年",N13)),1/12,IF(ISNUMBER(SEARCH("日",N13)),20,1))),IF(ISNUMBER(SEARCH("日",N13)),20,IF(ISNUMBER(SEARCH("週",N13)),4.3,IF(ISNUMBER(SEARCH("月",N13)),1,""))))))) | AT13: =IF(O13="","",IF(ISNUMBER(O13),O13,IFERROR(VALUE(ASC(O13&"")),IF(ISNUMBER(SEARCH("時間",O13)),IFERROR(VALUE(SUBSTITUTE(SUBSTITUTE(SUBSTITUTE(SUBSTITUTE(SUBSTITUTE(ASC(O13&""),"約",""),"程度",""),"ほど",""),"時間","")," ",""))*60,""),IFERROR(VALUE(SUBSTITUTE(SUBSTITUTE(SUBSTITUTE(SUBSTITUTE(SUBSTITUTE(ASC(O13&""),"約",""),"程度",""),"ほど",""),"分","")," ","")),""))))) | AU13: =IF(P13="","",IF(ISNUMBER(P13),P13,IFERROR(VALUE(SUBSTITUTE(SUBSTITUTE(SUBSTITUTE(ASC(P13&""),"約",""),"件","")," ","")),""))) | AV13: =IF(AB13<>"OK","",IF(COUNTIFS($G$5:$G$404,G13&"",$F$5:$F$404,F13&"",$BE$5:$BE$404,BE13&"",$AB$5:$AB$404,"OK")>1,"同名あり","")) | AW13: =IF(Q13="","",IF(ISNUMBER(Q13),Q13,IFERROR(DATEVALUE(SUBSTITUTE(SUBSTITUTE(ASC(Q13&""),"-","/"),".","/")&"/01"),""))) | AX13: =IF(R13="","",IF(ISNUMBER(R13),R13,IFERROR(DATEVALUE(SUBSTITUTE(SUBSTITUTE(ASC(R13&""),"-","/"),".","/")&"/01"),""))) | AY13: =IF(OR(AB13<>"OK",AW13=""),"",IF(AW13>='01_設定'!$C$26,1,0)) | AZ13: =IF(AND(AB13="OK",AD13<>"除外"),COUNTIFS($AB$5:AB13,"OK",$AD$5:AD13,"<>除外"),"") | BA13: =IF(OR(AZ13="",AI13=""),"",AI13+ROW()/1000000000) | BB13: =IF(E13="","",IF(OR(TRIM(E13&"")="-",TRIM(E13&"")="－",TRIM(E13&"")="ー"),"",TRIM(E13&""))) | BC13: =IF(AND(AB13="OK",BB13<>""),IF(COUNTIFS($BB$5:BB13,BB13,$AB$5:AB13,"OK")=1,1,""),"") | BD13: =IF(BC13=1,COUNTIF($BC$5:BC13,1),"") | BE13: =IF(BB13="","",IFERROR(INDEX('06_顧客別集計'!$G$5:$G$104,MATCH(BB13,'06_顧客別集計'!$C$5:$C$104,0)),BB13)) | BF13: =IF(AND(AZ13<>"",BE13<>""),IF(COUNTIFS($BE$5:BE13,BE13,$AZ$5:AZ13,">0")=1,1,""),"") | BG13: =IF(BF13=1,COUNTIF($BF$5:BF13,1),"")
AB14: =IF(AND(A14="",G14=""),"",IF(ISNUMBER(SEARCH("##END",AM14)),"（終わりの印）",IF(ISNUMBER(SEARCH("##続き",AM14)),"（続きありの印）",IF(AM14="調査ID","（見出し行）",IF(AND(AM14<>"R1",AM14<>"R2"),"×表以外の行（集計されない）",IF(COUNTIF($AN$5:AN14,AN14)>1,"△重複（集計されない）",IF(G14="","△タスク名なし",IF(ISNA(MATCH(AQ14,'M1_類型マスタ'!$A$5:$A$19,0)),"△類型が不正",IF(OR(AP14="",N(AP14)<1,N(AP14)>6),"△業務区分が不正",IF(OR(AS14="",AT14=""),"△回数・分が読めない",IF(SUMPRODUCT(--ISNUMBER(--T14:Z14))<7,"△採点が足りない",IF(SUMPRODUCT((--T14:Z14>2)+(--T14:Z14<0))>0,"△採点が範囲外","OK")))))))))))) | AC14: =IF(AB14<>"OK","",TRIM(IF(AND(AU14<>"",N(AU14)<=1),"根拠1件 ","")&IF(AV14<>"","同名あり ","")&IF(AND(NOT(ISNUMBER(N14)),N14<>""),"回数を換算 ","")&IF(J14="","詳細なし ","")&IF(AND(N(AP14)=1,BB14=""),"顧客名なし ",""))) | AH14: =IF(AB14<>"OK","",IF(AG14<>"",AG14,AJ14)) | AI14: =IF(AB14<>"OK","",IFERROR(IF(AE14<>"",AE14,AS14)*IF(AF14<>"",AF14,AT14)/60,"")) | AJ14: =IF(AB14<>"OK","",IF(OR(VALUE(T14)=2,VALUE(U14)=2,VALUE(V14)=2),"社内残置",IF(AND(VALUE(T14)=0,VALUE(W14)=0,VALUE(Y14)=0),"自動化候補",IF(AND(VALUE(U14)=0,VALUE(W14)<=1,VALUE(X14)<=1,VALUE(Y14)<=1,VALUE(Z14)<=1),"オフショア候補",IF(AND(VALUE(Y14)<=1,VALUE(Z14)<=1),"ニアショア候補","社内で手順化→再評価"))))) | AK14: =IF(AB14<>"OK","",14-SUMPRODUCT(--T14:Z14)) | AL14: =IF(AB14<>"OK","",AS14*AT14/60) | AM14: =IF(A14="","",UPPER(TRIM(ASC(A14&"")))) | AN14: =IF(AM14="","",AM14&"-"&B14) | AO14: =IF(C14="","",IFERROR(VALUE(ASC(SUBSTITUTE(C14&"","観点",""))),"")) | AP14: =IF(D14="","",IFERROR(VALUE(LEFT(TRIM(ASC(D14&"")),1)),IFERROR(MATCH(TRIM(D14&""),'M2_区分マスタ'!$I$5:$I$10,0),""))) | AQ14: =IF(H14="","",UPPER(LEFT(TRIM(ASC(H14&"")),3))) | AR14: =IF(N14="","",IFERROR(VALUE(SUBSTITUTE(SUBSTITUTE(SUBSTITUTE(SUBSTITUTE(SUBSTITUTE(SUBSTITUTE(SUBSTITUTE(SUBSTITUTE(SUBSTITUTE(SUBSTITUTE(SUBSTITUTE(SUBSTITUTE(ASC(N14&""),"約",""),"程度",""),"ほど",""),"回",""),"毎",""),"週",""),"月",""),"年",""),"日",""),"に",""),"/","")," ","")),"")) | AS14: =IF(N14="","",IF(ISNUMBER(N14),N14,IFERROR(VALUE(ASC(N14&"")),IF(AR14<>"",AR14*IF(ISNUMBER(SEARCH("週",N14)),4.3,IF(ISNUMBER(SEARCH("年",N14)),1/12,IF(ISNUMBER(SEARCH("日",N14)),20,1))),IF(ISNUMBER(SEARCH("日",N14)),20,IF(ISNUMBER(SEARCH("週",N14)),4.3,IF(ISNUMBER(SEARCH("月",N14)),1,""))))))) | AT14: =IF(O14="","",IF(ISNUMBER(O14),O14,IFERROR(VALUE(ASC(O14&"")),IF(ISNUMBER(SEARCH("時間",O14)),IFERROR(VALUE(SUBSTITUTE(SUBSTITUTE(SUBSTITUTE(SUBSTITUTE(SUBSTITUTE(ASC(O14&""),"約",""),"程度",""),"ほど",""),"時間","")," ",""))*60,""),IFERROR(VALUE(SUBSTITUTE(SUBSTITUTE(SUBSTITUTE(SUBSTITUTE(SUBSTITUTE(ASC(O14&""),"約",""),"程度",""),"ほど",""),"分","")," ","")),""))))) | AU14: =IF(P14="","",IF(ISNUMBER(P14),P14,IFERROR(VALUE(SUBSTITUTE(SUBSTITUTE(SUBSTITUTE(ASC(P14&""),"約",""),"件","")," ","")),""))) | AV14: =IF(AB14<>"OK","",IF(COUNTIFS($G$5:$G$404,G14&"",$F$5:$F$404,F14&"",$BE$5:$BE$404,BE14&"",$AB$5:$AB$404,"OK")>1,"同名あり","")) | AW14: =IF(Q14="","",IF(ISNUMBER(Q14),Q14,IFERROR(DATEVALUE(SUBSTITUTE(SUBSTITUTE(ASC(Q14&""),"-","/"),".","/")&"/01"),""))) | AX14: =IF(R14="","",IF(ISNUMBER(R14),R14,IFERROR(DATEVALUE(SUBSTITUTE(SUBSTITUTE(ASC(R14&""),"-","/"),".","/")&"/01"),""))) | AY14: =IF(OR(AB14<>"OK",AW14=""),"",IF(AW14>='01_設定'!$C$26,1,0)) | AZ14: =IF(AND(AB14="OK",AD14<>"除外"),COUNTIFS($AB$5:AB14,"OK",$AD$5:AD14,"<>除外"),"") | BA14: =IF(OR(AZ14="",AI14=""),"",AI14+ROW()/1000000000) | BB14: =IF(E14="","",IF(OR(TRIM(E14&"")="-",TRIM(E14&"")="－",TRIM(E14&"")="ー"),"",TRIM(E14&""))) | BC14: =IF(AND(AB14="OK",BB14<>""),IF(COUNTIFS($BB$5:BB14,BB14,$AB$5:AB14,"OK")=1,1,""),"") | BD14: =IF(BC14=1,COUNTIF($BC$5:BC14,1),"") | BE14: =IF(BB14="","",IFERROR(INDEX('06_顧客別集計'!$G$5:$G$104,MATCH(BB14,'06_顧客別集計'!$C$5:$C$104,0)),BB14)) | BF14: =IF(AND(AZ14<>"",BE14<>""),IF(COUNTIFS($BE$5:BE14,BE14,$AZ$5:AZ14,">0")=1,1,""),"") | BG14: =IF(BF14=1,COUNTIF($BF$5:BF14,1),"")
AB15: =IF(AND(A15="",G15=""),"",IF(ISNUMBER(SEARCH("##END",AM15)),"（終わりの印）",IF(ISNUMBER(SEARCH("##続き",AM15)),"（続きありの印）",IF(AM15="調査ID","（見出し行）",IF(AND(AM15<>"R1",AM15<>"R2"),"×表以外の行（集計されない）",IF(COUNTIF($AN$5:AN15,AN15)>1,"△重複（集計されない）",IF(G15="","△タスク名なし",IF(ISNA(MATCH(AQ15,'M1_類型マスタ'!$A$5:$A$19,0)),"△類型が不正",IF(OR(AP15="",N(AP15)<1,N(AP15)>6),"△業務区分が不正",IF(OR(AS15="",AT15=""),"△回数・分が読めない",IF(SUMPRODUCT(--ISNUMBER(--T15:Z15))<7,"△採点が足りない",IF(SUMPRODUCT((--T15:Z15>2)+(--T15:Z15<0))>0,"△採点が範囲外","OK")))))))))))) | AC15: =IF(AB15<>"OK","",TRIM(IF(AND(AU15<>"",N(AU15)<=1),"根拠1件 ","")&IF(AV15<>"","同名あり ","")&IF(AND(NOT(ISNUMBER(N15)),N15<>""),"回数を換算 ","")&IF(J15="","詳細なし ","")&IF(AND(N(AP15)=1,BB15=""),"顧客名なし ",""))) | AH15: =IF(AB15<>"OK","",IF(AG15<>"",AG15,AJ15)) | AI15: =IF(AB15<>"OK","",IFERROR(IF(AE15<>"",AE15,AS15)*IF(AF15<>"",AF15,AT15)/60,"")) | AJ15: =IF(AB15<>"OK","",IF(OR(VALUE(T15)=2,VALUE(U15)=2,VALUE(V15)=2),"社内残置",IF(AND(VALUE(T15)=0,VALUE(W15)=0,VALUE(Y15)=0),"自動化候補",IF(AND(VALUE(U15)=0,VALUE(W15)<=1,VALUE(X15)<=1,VALUE(Y15)<=1,VALUE(Z15)<=1),"オフショア候補",IF(AND(VALUE(Y15)<=1,VALUE(Z15)<=1),"ニアショア候補","社内で手順化→再評価"))))) | AK15: =IF(AB15<>"OK","",14-SUMPRODUCT(--T15:Z15)) | AL15: =IF(AB15<>"OK","",AS15*AT15/60) | AM15: =IF(A15="","",UPPER(TRIM(ASC(A15&"")))) | AN15: =IF(AM15="","",AM15&"-"&B15) | AO15: =IF(C15="","",IFERROR(VALUE(ASC(SUBSTITUTE(C15&"","観点",""))),"")) | AP15: =IF(D15="","",IFERROR(VALUE(LEFT(TRIM(ASC(D15&"")),1)),IFERROR(MATCH(TRIM(D15&""),'M2_区分マスタ'!$I$5:$I$10,0),""))) | AQ15: =IF(H15="","",UPPER(LEFT(TRIM(ASC(H15&"")),3))) | AR15: =IF(N15="","",IFERROR(VALUE(SUBSTITUTE(SUBSTITUTE(SUBSTITUTE(SUBSTITUTE(SUBSTITUTE(SUBSTITUTE(SUBSTITUTE(SUBSTITUTE(SUBSTITUTE(SUBSTITUTE(SUBSTITUTE(SUBSTITUTE(ASC(N15&""),"約",""),"程度",""),"ほど",""),"回",""),"毎",""),"週",""),"月",""),"年",""),"日",""),"に",""),"/","")," ","")),"")) | AS15: =IF(N15="","",IF(ISNUMBER(N15),N15,IFERROR(VALUE(ASC(N15&"")),IF(AR15<>"",AR15*IF(ISNUMBER(SEARCH("週",N15)),4.3,IF(ISNUMBER(SEARCH("年",N15)),1/12,IF(ISNUMBER(SEARCH("日",N15)),20,1))),IF(ISNUMBER(SEARCH("日",N15)),20,IF(ISNUMBER(SEARCH("週",N15)),4.3,IF(ISNUMBER(SEARCH("月",N15)),1,""))))))) | AT15: =IF(O15="","",IF(ISNUMBER(O15),O15,IFERROR(VALUE(ASC(O15&"")),IF(ISNUMBER(SEARCH("時間",O15)),IFERROR(VALUE(SUBSTITUTE(SUBSTITUTE(SUBSTITUTE(SUBSTITUTE(SUBSTITUTE(ASC(O15&""),"約",""),"程度",""),"ほど",""),"時間","")," ",""))*60,""),IFERROR(VALUE(SUBSTITUTE(SUBSTITUTE(SUBSTITUTE(SUBSTITUTE(SUBSTITUTE(ASC(O15&""),"約",""),"程度",""),"ほど",""),"分","")," ","")),""))))) | AU15: =IF(P15="","",IF(ISNUMBER(P15),P15,IFERROR(VALUE(SUBSTITUTE(SUBSTITUTE(SUBSTITUTE(ASC(P15&""),"約",""),"件","")," ","")),""))) | AV15: =IF(AB15<>"OK","",IF(COUNTIFS($G$5:$G$404,G15&"",$F$5:$F$404,F15&"",$BE$5:$BE$404,BE15&"",$AB$5:$AB$404,"OK")>1,"同名あり","")) | AW15: =IF(Q15="","",IF(ISNUMBER(Q15),Q15,IFERROR(DATEVALUE(SUBSTITUTE(SUBSTITUTE(ASC(Q15&""),"-","/"),".","/")&"/01"),""))) | AX15: =IF(R15="","",IF(ISNUMBER(R15),R15,IFERROR(DATEVALUE(SUBSTITUTE(SUBSTITUTE(ASC(R15&""),"-","/"),".","/")&"/01"),""))) | AY15: =IF(OR(AB15<>"OK",AW15=""),"",IF(AW15>='01_設定'!$C$26,1,0)) | AZ15: =IF(AND(AB15="OK",AD15<>"除外"),COUNTIFS($AB$5:AB15,"OK",$AD$5:AD15,"<>除外"),"") | BA15: =IF(OR(AZ15="",AI15=""),"",AI15+ROW()/1000000000) | BB15: =IF(E15="","",IF(OR(TRIM(E15&"")="-",TRIM(E15&"")="－",TRIM(E15&"")="ー"),"",TRIM(E15&""))) | BC15: =IF(AND(AB15="OK",BB15<>""),IF(COUNTIFS($BB$5:BB15,BB15,$AB$5:AB15,"OK")=1,1,""),"") | BD15: =IF(BC15=1,COUNTIF($BC$5:BC15,1),"") | BE15: =IF(BB15="","",IFERROR(INDEX('06_顧客別集計'!$G$5:$G$104,MATCH(BB15,'06_顧客別集計'!$C$5:$C$104,0)),BB15)) | BF15: =IF(AND(AZ15<>"",BE15<>""),IF(COUNTIFS($BE$5:BE15,BE15,$AZ$5:AZ15,">0")=1,1,""),"") | BG15: =IF(BF15=1,COUNTIF($BF$5:BF15,1),"")
AB16: =IF(AND(A16="",G16=""),"",IF(ISNUMBER(SEARCH("##END",AM16)),"（終わりの印）",IF(ISNUMBER(SEARCH("##続き",AM16)),"（続きありの印）",IF(AM16="調査ID","（見出し行）",IF(AND(AM16<>"R1",AM16<>"R2"),"×表以外の行（集計されない）",IF(COUNTIF($AN$5:AN16,AN16)>1,"△重複（集計されない）",IF(G16="","△タスク名なし",IF(ISNA(MATCH(AQ16,'M1_類型マスタ'!$A$5:$A$19,0)),"△類型が不正",IF(OR(AP16="",N(AP16)<1,N(AP16)>6),"△業務区分が不正",IF(OR(AS16="",AT16=""),"△回数・分が読めない",IF(SUMPRODUCT(--ISNUMBER(--T16:Z16))<7,"△採点が足りない",IF(SUMPRODUCT((--T16:Z16>2)+(--T16:Z16<0))>0,"△採点が範囲外","OK")))))))))))) | AC16: =IF(AB16<>"OK","",TRIM(IF(AND(AU16<>"",N(AU16)<=1),"根拠1件 ","")&IF(AV16<>"","同名あり ","")&IF(AND(NOT(ISNUMBER(N16)),N16<>""),"回数を換算 ","")&IF(J16="","詳細なし ","")&IF(AND(N(AP16)=1,BB16=""),"顧客名なし ",""))) | AH16: =IF(AB16<>"OK","",IF(AG16<>"",AG16,AJ16)) | AI16: =IF(AB16<>"OK","",IFERROR(IF(AE16<>"",AE16,AS16)*IF(AF16<>"",AF16,AT16)/60,"")) | AJ16: =IF(AB16<>"OK","",IF(OR(VALUE(T16)=2,VALUE(U16)=2,VALUE(V16)=2),"社内残置",IF(AND(VALUE(T16)=0,VALUE(W16)=0,VALUE(Y16)=0),"自動化候補",IF(AND(VALUE(U16)=0,VALUE(W16)<=1,VALUE(X16)<=1,VALUE(Y16)<=1,VALUE(Z16)<=1),"オフショア候補",IF(AND(VALUE(Y16)<=1,VALUE(Z16)<=1),"ニアショア候補","社内で手順化→再評価"))))) | AK16: =IF(AB16<>"OK","",14-SUMPRODUCT(--T16:Z16)) | AL16: =IF(AB16<>"OK","",AS16*AT16/60) | AM16: =IF(A16="","",UPPER(TRIM(ASC(A16&"")))) | AN16: =IF(AM16="","",AM16&"-"&B16) | AO16: =IF(C16="","",IFERROR(VALUE(ASC(SUBSTITUTE(C16&"","観点",""))),"")) | AP16: =IF(D16="","",IFERROR(VALUE(LEFT(TRIM(ASC(D16&"")),1)),IFERROR(MATCH(TRIM(D16&""),'M2_区分マスタ'!$I$5:$I$10,0),""))) | AQ16: =IF(H16="","",UPPER(LEFT(TRIM(ASC(H16&"")),3))) | AR16: =IF(N16="","",IFERROR(VALUE(SUBSTITUTE(SUBSTITUTE(SUBSTITUTE(SUBSTITUTE(SUBSTITUTE(SUBSTITUTE(SUBSTITUTE(SUBSTITUTE(SUBSTITUTE(SUBSTITUTE(SUBSTITUTE(SUBSTITUTE(ASC(N16&""),"約",""),"程度",""),"ほど",""),"回",""),"毎",""),"週",""),"月",""),"年",""),"日",""),"に",""),"/","")," ","")),"")) | AS16: =IF(N16="","",IF(ISNUMBER(N16),N16,IFERROR(VALUE(ASC(N16&"")),IF(AR16<>"",AR16*IF(ISNUMBER(SEARCH("週",N16)),4.3,IF(ISNUMBER(SEARCH("年",N16)),1/12,IF(ISNUMBER(SEARCH("日",N16)),20,1))),IF(ISNUMBER(SEARCH("日",N16)),20,IF(ISNUMBER(SEARCH("週",N16)),4.3,IF(ISNUMBER(SEARCH("月",N16)),1,""))))))) | AT16: =IF(O16="","",IF(ISNUMBER(O16),O16,IFERROR(VALUE(ASC(O16&"")),IF(ISNUMBER(SEARCH("時間",O16)),IFERROR(VALUE(SUBSTITUTE(SUBSTITUTE(SUBSTITUTE(SUBSTITUTE(SUBSTITUTE(ASC(O16&""),"約",""),"程度",""),"ほど",""),"時間","")," ",""))*60,""),IFERROR(VALUE(SUBSTITUTE(SUBSTITUTE(SUBSTITUTE(SUBSTITUTE(SUBSTITUTE(ASC(O16&""),"約",""),"程度",""),"ほど",""),"分","")," ","")),""))))) | AU16: =IF(P16="","",IF(ISNUMBER(P16),P16,IFERROR(VALUE(SUBSTITUTE(SUBSTITUTE(SUBSTITUTE(ASC(P16&""),"約",""),"件","")," ","")),""))) | AV16: =IF(AB16<>"OK","",IF(COUNTIFS($G$5:$G$404,G16&"",$F$5:$F$404,F16&"",$BE$5:$BE$404,BE16&"",$AB$5:$AB$404,"OK")>1,"同名あり","")) | AW16: =IF(Q16="","",IF(ISNUMBER(Q16),Q16,IFERROR(DATEVALUE(SUBSTITUTE(SUBSTITUTE(ASC(Q16&""),"-","/"),".","/")&"/01"),""))) | AX16: =IF(R16="","",IF(ISNUMBER(R16),R16,IFERROR(DATEVALUE(SUBSTITUTE(SUBSTITUTE(ASC(R16&""),"-","/"),".","/")&"/01"),""))) | AY16: =IF(OR(AB16<>"OK",AW16=""),"",IF(AW16>='01_設定'!$C$26,1,0)) | AZ16: =IF(AND(AB16="OK",AD16<>"除外"),COUNTIFS($AB$5:AB16,"OK",$AD$5:AD16,"<>除外"),"") | BA16: =IF(OR(AZ16="",AI16=""),"",AI16+ROW()/1000000000) | BB16: =IF(E16="","",IF(OR(TRIM(E16&"")="-",TRIM(E16&"")="－",TRIM(E16&"")="ー"),"",TRIM(E16&""))) | BC16: =IF(AND(AB16="OK",BB16<>""),IF(COUNTIFS($BB$5:BB16,BB16,$AB$5:AB16,"OK")=1,1,""),"") | BD16: =IF(BC16=1,COUNTIF($BC$5:BC16,1),"") | BE16: =IF(BB16="","",IFERROR(INDEX('06_顧客別集計'!$G$5:$G$104,MATCH(BB16,'06_顧客別集計'!$C$5:$C$104,0)),BB16)) | BF16: =IF(AND(AZ16<>"",BE16<>""),IF(COUNTIFS($BE$5:BE16,BE16,$AZ$5:AZ16,">0")=1,1,""),"") | BG16: =IF(BF16=1,COUNTIF($BF$5:BF16,1),"")
