Workbook

Sheet 00_はじめに
B1: 暗黙タスク棚卸し台帳 v3.1（Researcher 1回版）
B2: 対象：管理職（不特定多数への配布を想定） ／ 人の操作：Researcher への依頼1回・貼り付け1回・本人確認 ／ 待ち時間：5〜45分
B4: 1. この台帳でやること
B5: ・Microsoft 365 Copilot の Researcher に1回だけ依頼し、保存期間（既定14か月）分のメール・Teams チャット・会議から、調整・連絡・確認などで時間が過ぎていく「暗黙のタスク」を洗い出す。
B6: ・Researcher は6つの観点を順番に調べ、タスク名・頻度と時間の目安・根拠の件数・任せやすさの採点（A1〜A7）までを1つの表で返す。
B7: ・台帳は貼り付けた表を自動でチェックし、月あたりの時間と「自動化／オフショア／ニアショア／社内」の区分を計算する。提出するのは 05_タスク一覧（提出用）。
B9: 2. 手順（02_ダッシュボードの「次にやること」が自動で切り替わる）
B10: ① 02_ダッシュボードの「このセルをコピー」を選んでコピーする（Ctrl+C）
B11: ② Microsoft 365 Copilot で Researcher を開き、新しいチャットに貼り付けて送る。調べる範囲を選べる場合は「メール」「会議」「チャット」を選び、Web は外す
B12: ③ 終わるまで待つ（5〜45分。ほかの仕事をしていてよい）。確認の質問が来たら「指示どおりに進めてください」と返す
B13: ④ 回答の表を見出し行ごとコピーし、04_調査結果の A5 から下の最初の空き行に貼り付ける
B14: ⑤ 表が途中で終わっていれば、ダッシュボードが「続きプロンプト」に切り替わる。同じチャットに送り、続きを④と同じように貼る
... B40: ・類型コード・採点基準・移管区分は全員共通なので、部署・役職をまたいで集計できる。調査の文面は 03_プロンプトの原本（黄色）で一括して直せる。

Sheet 01_設定
A1: 01_設定
A2: 黄色のセルだけを入力・選択する。灰色は自動計算。
B3: 項目 | C3: 値 | D3: 説明
B4: 実行者ID（匿名） | C4: MGR-0001 | D4: 配布元が割り当てた匿名ID。氏名は書かない。
B5: 部署区分 | C5: 企画・管理 | D5: プルダウンから選ぶ。
B6: 役職区分 | C6: 課長級 | D6: プルダウンから選ぶ。
B7: 実行日 | D7: Researcher を実行する（した）日。空欄の間は今日の日付が使われる。本人確認のときに日付を入れて固定する。
B8: 保存期間（月） | C8: 14 | D8: 会社のメール・チャットの保存期間。対象期間の長さになる。
B9: 最大行数 | C9: 50 | D9: Researcher に挙げてもらうタスクの上限。
B10: 直近とみなす月数 | C10: 3 | D10: 偏りチェック用。根拠の最初がこの月数以内のタスクを「直近」とみなす。
B11: 偏りの判定基準 | C11: 0.7 | D11: 直近のタスクがこの割合以上なら、ダッシュボードに注意を出す。
B12: 調査の完了 | C12: 自動 | D12: 通常は「自動」。終わりの印（##END##）がないが表は全部出ていると判断した場合だけ「完了」にする。
B13: 本人確認 | C13: 未完了 | D13: 本人確認が終わったら「完了」にする。
B14: 提出状況 | C14: 未提出 | D14: 提出したら「提出済み」にする。
B16: ■ 実行の記録（任意）
B17: Researcher を実行した日時
B18: かかった時間（分）
B19: メモ
B21: ■ 自動計算（触らない）
B22: 実行日（使用する値） | C22: =IF(C7="",TODAY(),C7)
B23: 対象開始日 | C23: =EDATE(C22,-C8)
B24: 対象月数 | C24: =ROUND((C22-C23)/30.44,0)
B25: 前半の終了日 | C25: =C23+INT((C22-C23)/2)
B26: 直近の境界日 | C26: =EDATE(C22,-C10)
B27: 直近に偏っている割合（観点6を除く） | C27: =IFERROR(COUNTIFS('04_調査結果'!$AS$5:$AS$404,1,'04_調査結果'!$AJ$5:$AJ$404,"<>6")/(COUNTIFS('04_調査結果'!$AS$5:$AS$404,1,'04_調査結果'!$AJ$5:$AJ$404,"<>6")+COUNTIFS('04_調査結果'!$AS$5:$AS$404,0,'04_調査結果'!$AJ$5:$AJ$404,"<>6")),"")
B28: OKの件数 | C28: =COUNTIF('04_調査結果'!$W$5:$W$404,"OK")
B29: 終わりの印の数 | C29: =COUNTIF('04_調査結果'!$W$5:$W$404,"（終わりの印）")
B30: 状態コード | C30: =IF(C28=0,1,IF(AND(C29=0,C12<>"完了"),2,IF(C13<>"完了",3,IF(C14<>"提出済み",4,5))))
B31: 列の並びチェック | C31: =IF(ISNA(MATCH("調査ID",'04_調査結果'!$AH$5:$AH$404,0)),"見出し行なし（確認できない）",IF(AND(INDEX('04_調査結果'!$E$5:$E$404,MATCH("調査ID",'04_調査結果'!$AH$5:$AH$404,0))="類型",INDEX('04_調査結果'!$K$5:$K$404,MATCH("調査ID",'04_調査結果'!$AH$5:$AH$404,0))="根拠の件数",INDEX('04_調査結果'!$V$5:$V$404,MATCH("調査ID",'04_調査結果'!$AH$5:$AH$404,0))="任せるための前提条件"),"OK","列がずれている可能性"))
B32: 台帳の版 | C32: v3.1

Sheet 02_ダッシュボード
A1: 02_ダッシュボード
A2: 「次にやること」を上から順に行う。Researcher に送るのは基本的に1回だけ。
B4: 実行者ID | C4: ='01_設定'!C4
B5: 対象期間 | C5: =TEXT('01_設定'!C23,"yyyy/mm/dd")&"〜"&TEXT('01_設定'!C22,"yyyy/mm/dd")&"（約"&'01_設定'!C24&"か月）"&IF('01_設定'!C7=""," ※実行日が未入力のため今日の日付で計算中","")
B7: ■ 次にやること
B8: 状態 | C8: =CHOOSE('01_設定'!$C$30,"① 調査プロンプトを Researcher の新しいチャットに送り、表を 04_調査結果に貼る","② 終わりの印がまだない。表が途中なら続きプロンプトを同じチャットに送り、続きを貼る（全部出ていれば 01_設定の「調査の完了」を「完了」に）","③ 本人確認（手順は下のセル）","④ 提出（手順は下のセル）","すべて完了")
B9: このセルをコピー | C9: =CHOOSE('01_設定'!$C$30,'03_プロンプト'!$E$13,'03_プロンプト'!$E$14,'03_プロンプト'!$E$8,'03_プロンプト'!$E$9,"")
B10: 文字数 | C10: =IF(C9="","",LEN(C9))
B11: ※ セルを選んで Ctrl+C → Researcher の入力欄に Ctrl+V。先頭と末尾に " が付いてもそのまま送ってよい。
B12: ※ Researcher で調べる範囲を選べる場合は、メール・会議・チャットを選び、Web は外す。
B13: ※ Researcher から確認の質問が来たら「指示どおりに進めてください」と返す。
B14: ※ 表にならなかった・表が分かれた・列がずれた場合は、03_プロンプトの「出し直し」を同じチャットに送る。
B16: ■ 品質チェック
B17: 項目 | C17: 値 | D17: 見方・対処
B18: OK のタスク数 | C18: ='01_設定'!C28 | D18: 少なすぎる（10件未満など）場合は、貼り付け漏れや途中終了がないか確認する
B19: 列の並び | C19: ='01_設定'!C31 | D19: 「列がずれている可能性」なら、03_プロンプトの「出し直し」を同じチャットに送り、貼り直す
B20: 直さないと集計されない行（△） | C20: =COUNTIF('04_調査結果'!$W$5:$W$404,"△*") | D20: 値を直すと集計の対象になる（直さなくても他の行には影響しない）
B21: 要確認のタスク | C21: =COUNTIF('04_調査結果'!$X$5:$X$404,"?*") | D21: 根拠1件・同名あり・回数を換算したもの。本人確認で優先して見る
B22: 直近に偏っている割合 | C22: ='01_設定'!C27 | D22: 基準以上なら注意。気になる場合だけ、03_プロンプトの R2（前半の追加調査・任意）を使う
B24: ■ 観点別のタスク数（0件の観点は漏れの可能性がある）
B25: 観点 | C25: タスク数 | D25: 内容
B26: 1 | C26: =COUNTIFS('04_調査結果'!$AJ$5:$AJ$404,B26,'04_調査結果'!$W$5:$W$404,"OK") | D26: 中継・調整・催促・取りまとめ
B27: 2 | C27: =COUNTIFS('04_調査結果'!$AJ$5:$AJ$404,B27,'04_調査結果'!$W$5:$W$404,"OK") | D27: 確認・承認・問い合わせ対応
B28: 3 | C28: =COUNTIFS('04_調査結果'!$AJ$5:$AJ$404,B28,'04_調査結果'!$W$5:$W$404,"OK") | D28: 利害調整・トラブル・相談対応
B29: 4 | C29: =COUNTIFS('04_調査結果'!$AJ$5:$AJ$404,B29,'04_調査結果'!$W$5:$W$404,"OK") | D29: 定例報告・会議運営
B30: 5 | C30: =COUNTIFS('04_調査結果'!$AJ$5:$AJ$404,B30,'04_調査結果'!$W$5:$W$404,"OK") | D30: 申請・手配・調べもの・資料作成
B31: 6 | C31: =COUNTIFS('04_調査結果'!$AJ$5:$AJ$404,B31,'04_調査結果'!$W$5:$W$404,"OK") | D31: 年に数回の業務
B33: ■ 類型別の集計（除外したタスクを除く）
B34: 類型 | C34: タスク数 | D34: 類型名 | E34: 暗黙の数 | F34: 月あたり時間h
B35: T01 | C35: =COUNTIFS('04_調査結果'!$AK$5:$AK$404,B35,'04_調査結果'!$AT$5:$AT$404,">0") | D35: 中継・転送 | E35: =COUNTIFS('04_調査結果'!$AK$5:$AK$404,B35,'04_調査結果'!$AT$5:$AT$404,">0",'04_調査結果'!$H$5:$H$404,"暗黙") | F35: =SUMIFS('04_調査結果'!$AD$5:$AD$404,'04_調査結果'!$AK$5:$AK$404,B35,'04_調査結果'!$AT$5:$AT$404,">0")
B36: T02 | C36: =COUNTIFS('04_調査結果'!$AK$5:$AK$404,B36,'04_調査結果'!$AT$5:$AT$404,">0") | D36: 日程・会議調整 | E36: =COUNTIFS('04_調査結果'!$AK$5:$AK$404,B36,'04_調査結果'!$AT$5:$AT$404,">0",'04_調査結果'!$H$5:$H$404,"暗黙") | F36: =SUMIFS('04_調査結果'!$AD$5:$AD$404,'04_調査結果'!$AK$5:$AK$404,B36,'04_調査結果'!$AT$5:$AT$404,">0")
B37: T03 | C37: =COUNTIFS('04_調査結果'!$AK$5:$AK$404,B37,'04_調査結果'!$AT$5:$AT$404,">0") | D37: 催促・フォローアップ | E37: =COUNTIFS('04_調査結果'!$AK$5:$AK$404,B37,'04_調査結果'!$AT$5:$AT$404,">0",'04_調査結果'!$H$5:$H$404,"暗黙") | F37: =SUMIFS('04_調査結果'!$AD$5:$AD$404,'04_調査結果'!$AK$5:$AK$404,B37,'04_調査結果'!$AT$5:$AT$404,">0")
B38: T04 | C38: =COUNTIFS('04_調査結果'!$AK$5:$AK$404,B38,'04_調査結果'!$AT$5:$AT$404,">0") | D38: 取りまとめ・集約 | E38: =COUNTIFS('04_調査結果'!$AK$5:$AK$404,B38,'04_調査結果'!$AT$5:$AT$404,">0",'04_調査結果'!$H$5:$H$404,"暗黙") | F38: =SUMIFS('04_調査結果'!$AD$5:$AD$404,'04_調査結果'!$AK$5:$AK$404,B38,'04_調査結果'!$AT$5:$AT$404,">0")
B39: T05 | C39: =COUNTIFS('04_調査結果'!$AK$5:$AK$404,B39,'04_調査結果'!$AT$5:$AT$404,">0") | D39: 確認・承認・レビュー | E39: =COUNTIFS('04_調査結果'!$AK$5:$AK$404,B39,'04_調査結果'!$AT$5:$AT$404,">0",'04_調査結果'!$H$5:$H$404,"暗黙") | F39: =SUMIFS('04_調査結果'!$AD$5:$AD$404,'04_調査結果'!$AK$5:$AK$404,B39,'04_調査結果'!$AT$5:$AT$404,">0")
B40: T06 | C40: =COUNTIFS('04_調査結果'!$AK$5:$AK$404,B40,'04_調査結果'!$AT$5:$AT$404,">0") | D40: 問い合わせ対応・振り分け | E40: =COUNTIFS('04_調査結果'!$AK$5:$AK$404,B40,'04_調査結果'!$AT$5:$AT$404,">0",'04_調査結果'!$H$5:$H$404,"暗黙") | F40: =SUMIFS('04_調査結果'!$AD$5:$AD$404,'04_調査結果'!$AK$5:$AK$404,B40,'04_調査結果'!$AT$5:$AT$404,">0")
B41: T07 | C41: =COUNTIFS('04_調査結果'!$AK$5:$AK$404,B41,'04_調査結果'!$AT$5:$AT$404,">0") | D41: 利害調整・合意形成 | E41: =COUNTIFS('04_調査結果'!$AK$5:$AK$404,B41,'04_調査結果'!$AT$5:$AT$404,">0",'04_調査結果'!$H$5:$H$404,"暗黙") | F41: =SUMIFS('04_調査結果'!$AD$5:$AD$404,'04_調査結果'!$AK$5:$AK$404,B41,'04_調査結果'!$AT$5:$AT$404,">0")
B42: T08 | C42: =COUNTIFS('04_調査結果'!$AK$5:$AK$404,B42,'04_調査結果'!$AT$5:$AT$404,">0") | D42: 定例報告・数値更新 | E42: =COUNTIFS('04_調査結果'!$AK$5:$AK$404,B42,'04_調査結果'!$AT$5:$AT$404,">0",'04_調査結果'!$H$5:$H$404,"暗黙") | F42: =SUMIFS('04_調査結果'!$AD$5:$AD$404,'04_調査結果'!$AK$5:$AK$404,B42,'04_調査結果'!$AT$5:$AT$404,">0")
B43: T09 | C43: =COUNTIFS('04_調査結果'!$AK$5:$AK$404,B43,'04_調査結果'!$AT$5:$AT$404,">0") | D43: 申請・手配・事務手続き | E43: =COUNTIFS('04_調査結果'!$AK$5:$AK$404,B43,'04_調査結果'!$AT$5:$AT$404,">0",'04_調査結果'!$H$5:$H$404,"暗黙") | F43: =SUMIFS('04_調査結果'!$AD$5:$AD$404,'04_調査結果'!$AK$5:$AK$404,B43,'04_調査結果'!$AT$5:$AT$404,">0")
B44: T10 | C44: =COUNTIFS('04_調査結果'!$AK$5:$AK$404,B44,'04_調査結果'!$AT$5:$AT$404,">0") | D44: 調査・情報探し | E44: =COUNTIFS('04_調査結果'!$AK$5:$AK$404,B44,'04_調査結果'!$AT$5:$AT$404,">0",'04_調査結果'!$H$5:$H$404,"暗黙") | F44: =SUMIFS('04_調査結果'!$AD$5:$AD$404,'04_調査結果'!$AK$5:$AK$404,B44,'04_調査結果'!$AT$5:$AT$404,">0")
B45: T11 | C45: =COUNTIFS('04_調査結果'!$AK$5:$AK$404,B45,'04_調査結果'!$AT$5:$AT$404,">0") | D45: トラブル・例外対応 | E45: =COUNTIFS('04_調査結果'!$AK$5:$AK$404,B45,'04_調査結果'!$AT$5:$AT$404,">0",'04_調査結果'!$H$5:$H$404,"暗黙") | F45: =SUMIFS('04_調査結果'!$AD$5:$AD$404,'04_調査結果'!$AK$5:$AK$404,B45,'04_調査結果'!$AT$5:$AT$404,">0")
...

Sheet 03_プロンプト
A1: 03_プロンプト
A2: Researcher に送る文面。上（黄色）が原本で、下が日付などを差し込んだ完成版。普段は 02_ダッシュボードのセルをコピーすればよい。
B4: ID | C4: 名称 | D4: 使う場面 | E4: 本文 | F4: 文字数
B5: RT | C5: 調査（原本） | D5: Researcher の新しいチャットで1回だけ。 | E5: 【業務の棚卸し {調査ID}】暗黙のタスクの洗い出し ■対象期間：{期間開始}〜{期間終了}（約{月数}か月） ■調べる範囲：私のメール（特に私が送信したもの）、Teamsのチャット、会議。Webは使わない。 ■目的：依頼された仕事だけでなく、誰にも頼まれていないのに私の時間を使っている「暗黙のタスク」を洗い出し、自動化や、他の拠点・委託先に任せられるかを判断したい。{追加の指示} ■調べ方（確認の質問はせず、このまま進めてください） 次の6つの観点を、1つずつ順番に検索してください。 観点1：転送・共有による中継、日程・会議の調整、返事の催促・再確認、複数人からの回収・取りまとめ 観点2：他人の作成物や申請の確認・承認・差し戻し、問い合わせへの一次対応と担当の振り分け 観点3：関係者間の意見調整・根回し、トラブルや例外への一次対応、部下・同僚からの相談対応・指導 観点4：定例の報告・数値の更新、会議の準備・進行・議事録・宿題の管理 観点5：申請・手配・事務手続き、回答や判断のための調べもの、資料・文書の作成 観点6：年に数回だけ発生する業務（予算策定・人事評価・目標設定・年度計画・決算・監査対応・棚卸・人事異動・年次イベントなど） ・どの観点も、対象期間の前半と後半の両方から根拠となるやり取りを確認してください（直近に偏らないこと）。 ・繰り返し発生している作業を優先し、個々のメールではなく、同じ種類の作業を1つのタスクにまとめてください。 ・実際のやり取りで確認できたものだけを挙げてください。推測で作らないでください。該当がない観点は0件でかまいません。 ■出力のルール ・前置き・まとめは書かず、1つの表だけを出す（観点ごとに表を分けない）。最大{最大行数}行。 ・表のどの列にも、人名・会社名・製品名・金額・メールアドレスを書かない。表の中に出典番号やリンクを入れない。 ・全部出し終えたら、表の最後の行として、調査IDの列に「##END##」とだけ書いた行を加える。途中で止める場合は、同じように「##続きあり##」の行を加える。 ・表の列（この順番、この見出しのまま）： | 調査ID | No | 観点 | タスク名 | 類型 | 説明 | 主な相手 | 明示暗黙 | 月あたり回数 | 1回あたり分 | 根拠の件数 | 根拠の最初 | 根拠の最後 | 暗黙の理由 | A1 | A2 | A3 | A4 | A5 | A6 | A7 | 任せるための前提条件 | ・調査ID：すべての行に {調査ID} と書く ・No：1からの連番 ・観点：1〜6の数字だけ ・タスク名：「業務対象＋動作」で20字以内（例：部門定例会議の日程調整） ・類型：次のコードだけを書く（例：T02） T01 中継・転送／T02 日程・会議調整／T03 催促・フォローアップ／T04 取りまとめ・集約／T05 確認・承認・レビュー／T06 問い合わせ対応・振り分け／T07 利害調整・合意形成／T08 定例報告・数値更新／T09 申請・手配・事務手続き／T10 調査・情報探し／T11 トラブル・例外対応／T12 相談対応・指導／T13 会議運営／T14 資料・文書作成／T99 その他 ・説明：40字以内 ・主な相手：上司／部下／自部署／他部署／経営層／顧客／取引先／社外その他／複数 のどれか ・明示暗黙：私宛てに具体的な依頼があり、成果物か期限がはっきりしているものは「明示」、それ以外は「暗黙」 ・月あたり回数：数字だけ（週1回なら4、月2回なら2、年1回なら0.1、四半期ごとなら0.3） ・1回あたり分：数字だけ（1回分のやり取り全体にかかる時間の目安） ・根拠の件数：このタスクの根拠として確認したやり取りの件数（数字だけ） ・根拠の最初、根拠の最後：根拠にしたやり取りの最初と最後の年月（yyyy/mm） ・暗黙の理由：30字以内（例：依頼がないのに自分から催促している）。明示なら - ・A1〜A7：下の基準で 0・1・2 の数字だけ（大きいほど任せにくい。迷ったら大きい方） A1 判断・裁量：0=手順どおりで判断不要／1=軽い判断がある／2=管理職の判断・決裁が必要 A2 機密性：0=社内の一般的な情報／1=社外秘／2=人事・評価・個人情報・未公表の経営情報 A3 関係性：0=誰が対応しても同じ／1=相手との一定の関係が必要／2=私本人との信頼関係が前提 A4 言語・文脈：0=定型文で足りる／1=日本語の言い回し・社内用語が必要／2=経緯や空気を読む高度な日本語が必要 A5 即時性：0=翌営業日でよい／1=当日中に必要／2=即時、または日本の勤務時間内の対応が必須 A6 非定型度：0=毎回同じ手順／1=いくつかのパターンがある／2=毎回内容が違う A7 システム権限：0=メール・Teamsだけで完結／1=社内システムの閲覧が必要／2=承認権限・特別なIDが必要 ・任せるための前提条件：40字以内（例：手順書と定型文の整備、閲覧権限の付与） | F5: =LEN(E5)
B6: RC | C6: 続き（原本） | D6: 表が途中で終わったとき、同じチャットで。 | E6: 【続き {調査ID}】表が途中で終わっています。続きを No.{次No} から、同じ列・同じルールの1つの表で出してください。すでに出した行は繰り返さないでください。前置きは不要です。全部出し終えたら、表の最後の行として、調査IDの列に「##END##」とだけ書いた行を加えてください。 | F6: =LEN(E6)
B7: RF | C7: 出し直し（原本） | D7: 表にならなかった・表が分かれた・列がずれたとき、同じチャットで。 | E7: 【出し直し {調査ID}】上の調査結果を、最初に指定した22列の表1つだけで出し直してください。列の順番と見出しは指定どおりにし、数字の列には数字だけを書いてください。前置き・まとめは不要です。表の最後の行として、調査IDの列に「##END##」とだけ書いた行を加えてください。 | F7: =LEN(E7)
B8: MR | C8: 手作業：本人確認 | D8: 調査のあと。 | E8: 【手作業】本人確認（目安20分） 1. 01_設定の「実行日」が空欄なら、Researcher を実行した日を入れる（空欄のままだと毎日変わる）。 2. 04_調査結果の判定列（W列）に「△」が出ている行は、値を直すと集計の対象になる（直さなければ集計されないだけ）。「×」や見出し行・終わりの印はそのままでよい。 3. 05_タスク一覧を上から見て、明らかな誤り・業務ではないもの・重複があれば、04_調査結果のY列（本人確認）で「除外」を選ぶ。X列（要確認）に「根拠1件」「同名あり」と出ているものを優先して見る。何もしなければ提出の対象になる。 4. 回数や時間が実感と大きく違うものだけ、Z列・AA列に自分の見積もりを入れる。移管区分に異論があるものだけ、AB列で選び直す。 5. タスク名・説明などに人名・社名・製品名が残っていれば、04_調査結果で書き換える。 6. 終わったら、01_設定の「本人確認」を「完了」にする。 | F8: =LEN(E8)
B9: MS | C9: 手作業：提出 | D9: 本人確認のあと。 | E9: 【手作業】提出 1. 05_タスク一覧（提出用）に、除外していないタスクだけが並んでいることを確認する（氏名・メール本文は含まれない）。 2. 配布元の指示に従い、このファイル、または 05_タスク一覧（提出用）を値で貼り付けた新しいブックを、提出先に保存する。 3. 01_設定の「提出状況」を「提出済み」にする。 | F9: =LEN(E9)
B11: ■ 完成版（自動で差し込み済み）
B12: ID | C12: 名称 | D12: 使う場面 | E12: 本文（このセルをコピー） | F12: 文字数
B13: R1 | C13: 調査（送るもの） | D13: Researcher の新しいチャットで1回だけ。 | E13: =SUBSTITUTE(SUBSTITUTE(SUBSTITUTE(SUBSTITUTE(SUBSTITUTE(SUBSTITUTE($E$5,"{調査ID}","R1"),"{期間開始}",TEXT('01_設定'!$C$23,"yyyy年m月d日")),"{期間終了}",TEXT('01_設定'!$C$22,"yyyy年m月d日")),"{月数}",ROUND(('01_設定'!$C$22-'01_設定'!$C$23)/30.44,0)),"{最大行数}",'01_設定'!$C$9),"{追加の指示}","") | F13: =LEN(E13)
B14: R1続き | C14: 続き（送るもの） | D14: 表が途中で終わったとき、同じチャットで。 | E14: =SUBSTITUTE(SUBSTITUTE($E$6,"{調査ID}","R1"),"{次No}",IFERROR(_xlfn.MAXIFS('04_調査結果'!$B$5:$B$404,'04_調査結果'!$AH$5:$AH$404,"R1"),0)+1) | F14: =LEN(E14)
B15: R1出し直し | C15: 出し直し（送るもの） | D15: 表にならなかった・表が分かれた・列がずれたとき、同じチャットで。 | E15: =SUBSTITUTE($E$7,"{調査ID}","R1") | F15: =LEN(E15)
B16: R2 | C16: 前半の追加調査（任意） | D16: 結果が直近に偏っていた場合だけ。Researcher の新しいチャットで。 | E16: =SUBSTITUTE(SUBSTITUTE(SUBSTITUTE(SUBSTITUTE(SUBSTITUTE(SUBSTITUTE($E$5,"{調査ID}","R2"),"{期間開始}",TEXT('01_設定'!$C$23,"yyyy年m月d日")),"{期間終了}",TEXT('01_設定'!$C$25,"yyyy年m月d日")),"{月数}",ROUND(('01_設定'!$C$25-'01_設定'!$C$23)/30.44,0)),"{最大行数}",'01_設定'!$C$9),"{追加の指示}"," ※ 直近の業務は別の調査で確認済みです。この期間に繰り返し発生していた業務を中心に挙げてください。") | F16: =LEN(E16)

Sheet 04_調査結果
A1: 04_調査結果（Researcher の表の貼り付け先・本人確認もここで行う）
A2: Researcher の表を見出し行ごとコピーし、A5 から下の最初の空き行に貼る（緑の見出しの列 A〜V）。判定が OK の行だけが集計される。黄色の見出しの列（Y〜AB）は本人確認のときだけ入力する。
A3: 調査ID | B3: No | C3: 観点 | D3: タスク名 | E3: 類型 | F3: 説明 | G3: 主な相手 | H3: 明示暗黙 | I3: 月あたり回数 | J3: 1回あたり分 | K3: 根拠の件数 | L3: 根拠の最初 | M3: 根拠の最後 | N3: 暗黙の理由 | O3: A1 | P3: A2 | Q3: A3 | R3: A4 | S3: A5 | T3: A6 | U3: A7 | V3: 任せるための前提条件 | W3: 判定 | X3: 要確認 | Y3: 本人確認 | Z3: 補正：月あたり回数 | AA3: 補正：1回あたり分 | AB3: 本人判断（上書き） | AC3: 採用区分 | AD3: 採用：月あたり時間h | AE3: 自動判定 | AF3: 任せやすさ（14点満点） | AG3: 月あたり時間h（推定） | AH3: 調査ID（整形） | AI3: キー | AJ3: 観点（数値） | AK3: 類型コード | AL3: 回数の数字部分 | AM3: 回数（数値） | AN3: 分（数値） | AO3: 根拠の件数（数値） | AP3: 同名チェック | AQ3: 根拠の最初（日付） | AR3: 根拠の最後（日付） | AS3: 直近フラグ | AT3: 一覧番号 | AU3: 順位用
A4: ↓ A5 のセルを選んで貼り付ける（見出し行ごと貼ってよい）。×の行や見出し行は消さなくてよい（集計されない）。
W5: =IF(AND(A5="",D5=""),"",IF(ISNUMBER(SEARCH("##END",AH5)),"（終わりの印）",IF(ISNUMBER(SEARCH("##続き",AH5)),"（続きありの印）",IF(AH5="調査ID","（見出し行）",IF(AND(AH5<>"R1",AH5<>"R2"),"×表以外の行（集計されない）",IF(COUNTIF($AI$5:AI5,AI5)>1,"△重複（集計されない）",IF(D5="","△タスク名なし",IF(ISNA(MATCH(AK5,'M1_類型マスタ'!$A$5:$A$19,0)),"△類型が不正",IF(OR(AM5="",AN5=""),"△回数・分が読めない",IF(SUMPRODUCT(--ISNUMBER(--O5:U5))<7,"△採点が足りない",IF(SUMPRODUCT((--O5:U5>2)+(--O5:U5<0))>0,"△採点が範囲外","OK"))))))))))) | X5: =IF(W5<>"OK","",TRIM(IF(AND(AO5<>"",N(AO5)<=1),"根拠1件 ","")&IF(AP5<>"","同名あり ","")&IF(AND(NOT(ISNUMBER(I5)),I5<>""),"回数を換算 ",""))) | AC5: =IF(W5<>"OK","",IF(AB5<>"",AB5,AE5)) | AD5: =IF(W5<>"OK","",IFERROR(IF(Z5<>"",Z5,AM5)*IF(AA5<>"",AA5,AN5)/60,"")) | AE5: =IF(W5<>"OK","",IF(OR(VALUE(O5)=2,VALUE(P5)=2,VALUE(Q5)=2),"社内残置",IF(AND(VALUE(O5)=0,VALUE(R5)=0,VALUE(T5)=0),"自動化候補",IF(AND(VALUE(P5)=0,VALUE(R5)<=1,VALUE(S5)<=1,VALUE(T5)<=1,VALUE(U5)<=1),"オフショア候補",IF(AND(VALUE(T5)<=1,VALUE(U5)<=1),"ニアショア候補","社内で手順化→再評価"))))) | AF5: =IF(W5<>"OK","",14-SUMPRODUCT(--O5:U5)) | AG5: =IF(W5<>"OK","",AM5*AN5/60) | AH5: =IF(A5="","",UPPER(TRIM(ASC(A5&"")))) | AI5: =IF(AH5="","",AH5&"-"&B5) | AJ5: =IF(C5="","",IFERROR(VALUE(ASC(SUBSTITUTE(C5&"","観点",""))),"")) | AK5: =IF(E5="","",UPPER(LEFT(TRIM(ASC(E5&"")),3))) | AL5: =IF(I5="","",IFERROR(VALUE(SUBSTITUTE(SUBSTITUTE(SUBSTITUTE(SUBSTITUTE(SUBSTITUTE(SUBSTITUTE(SUBSTITUTE(SUBSTITUTE(SUBSTITUTE(SUBSTITUTE(SUBSTITUTE(SUBSTITUTE(ASC(I5&""),"約",""),"程度",""),"ほど",""),"回",""),"毎",""),"週",""),"月",""),"年",""),"日",""),"に",""),"/","")," ","")),"")) | AM5: =IF(I5="","",IF(ISNUMBER(I5),I5,IFERROR(VALUE(ASC(I5&"")),IF(AL5<>"",AL5*IF(ISNUMBER(SEARCH("週",I5)),4.3,IF(ISNUMBER(SEARCH("年",I5)),1/12,IF(ISNUMBER(SEARCH("日",I5)),20,1))),IF(ISNUMBER(SEARCH("日",I5)),20,IF(ISNUMBER(SEARCH("週",I5)),4.3,IF(ISNUMBER(SEARCH("月",I5)),1,""))))))) | AN5: =IF(J5="","",IF(ISNUMBER(J5),J5,IFERROR(VALUE(ASC(J5&"")),IF(ISNUMBER(SEARCH("時間",J5)),IFERROR(VALUE(SUBSTITUTE(SUBSTITUTE(SUBSTITUTE(SUBSTITUTE(SUBSTITUTE(ASC(J5&""),"約",""),"程度",""),"ほど",""),"時間","")," ",""))*60,""),IFERROR(VALUE(SUBSTITUTE(SUBSTITUTE(SUBSTITUTE(SUBSTITUTE(SUBSTITUTE(ASC(J5&""),"約",""),"程度",""),"ほど",""),"分","")," ","")),""))))) | AO5: =IF(K5="","",IF(ISNUMBER(K5),K5,IFERROR(VALUE(SUBSTITUTE(SUBSTITUTE(SUBSTITUTE(ASC(K5&""),"約",""),"件","")," ","")),""))) | AP5: =IF(W5<>"OK","",IF(COUNTIFS($D$5:$D$404,D5,$W$5:$W$404,"OK")>1,"同名あり","")) | AQ5: =IF(L5="","",IF(ISNUMBER(L5),L5,IFERROR(DATEVALUE(SUBSTITUTE(SUBSTITUTE(ASC(L5&""),"-","/"),".","/")&"/01"),""))) | AR5: =IF(M5="","",IF(ISNUMBER(M5),M5,IFERROR(DATEVALUE(SUBSTITUTE(SUBSTITUTE(ASC(M5&""),"-","/"),".","/")&"/01"),""))) | AS5: =IF(OR(W5<>"OK",AQ5=""),"",IF(AQ5>='01_設定'!$C$26,1,0)) | AT5: =IF(AND(W5="OK",Y5<>"除外"),COUNTIFS($W$5:W5,"OK",$Y$5:Y5,"<>除外"),"") | AU5: =IF(OR(AT5="",AD5=""),"",AD5+ROW()/1000000000)
W6: =IF(AND(A6="",D6=""),"",IF(ISNUMBER(SEARCH("##END",AH6)),"（終わりの印）",IF(ISNUMBER(SEARCH("##続き",AH6)),"（続きありの印）",IF(AH6="調査ID","（見出し行）",IF(AND(AH6<>"R1",AH6<>"R2"),"×表以外の行（集計されない）",IF(COUNTIF($AI$5:AI6,AI6)>1,"△重複（集計されない）",IF(D6="","△タスク名なし",IF(ISNA(MATCH(AK6,'M1_類型マスタ'!$A$5:$A$19,0)),"△類型が不正",IF(OR(AM6="",AN6=""),"△回数・分が読めない",IF(SUMPRODUCT(--ISNUMBER(--O6:U6))<7,"△採点が足りない",IF(SUMPRODUCT((--O6:U6>2)+(--O6:U6<0))>0,"△採点が範囲外","OK"))))))))))) | X6: =IF(W6<>"OK","",TRIM(IF(AND(AO6<>"",N(AO6)<=1),"根拠1件 ","")&IF(AP6<>"","同名あり ","")&IF(AND(NOT(ISNUMBER(I6)),I6<>""),"回数を換算 ",""))) | AC6: =IF(W6<>"OK","",IF(AB6<>"",AB6,AE6)) | AD6: =IF(W6<>"OK","",IFERROR(IF(Z6<>"",Z6,AM6)*IF(AA6<>"",AA6,AN6)/60,"")) | AE6: =IF(W6<>"OK","",IF(OR(VALUE(O6)=2,VALUE(P6)=2,VALUE(Q6)=2),"社内残置",IF(AND(VALUE(O6)=0,VALUE(R6)=0,VALUE(T6)=0),"自動化候補",IF(AND(VALUE(P6)=0,VALUE(R6)<=1,VALUE(S6)<=1,VALUE(T6)<=1,VALUE(U6)<=1),"オフショア候補",IF(AND(VALUE(T6)<=1,VALUE(U6)<=1),"ニアショア候補","社内で手順化→再評価"))))) | AF6: =IF(W6<>"OK","",14-SUMPRODUCT(--O6:U6)) | AG6: =IF(W6<>"OK","",AM6*AN6/60) | AH6: =IF(A6="","",UPPER(TRIM(ASC(A6&"")))) | AI6: =IF(AH6="","",AH6&"-"&B6) | AJ6: =IF(C6="","",IFERROR(VALUE(ASC(SUBSTITUTE(C6&"","観点",""))),"")) | AK6: =IF(E6="","",UPPER(LEFT(TRIM(ASC(E6&"")),3))) | AL6: =IF(I6="","",IFERROR(VALUE(SUBSTITUTE(SUBSTITUTE(SUBSTITUTE(SUBSTITUTE(SUBSTITUTE(SUBSTITUTE(SUBSTITUTE(SUBSTITUTE(SUBSTITUTE(SUBSTITUTE(SUBSTITUTE(SUBSTITUTE(ASC(I6&""),"約",""),"程度",""),"ほど",""),"回",""),"毎",""),"週",""),"月",""),"年",""),"日",""),"に",""),"/","")," ","")),"")) | AM6: =IF(I6="","",IF(ISNUMBER(I6),I6,IFERROR(VALUE(ASC(I6&"")),IF(AL6<>"",AL6*IF(ISNUMBER(SEARCH("週",I6)),4.3,IF(ISNUMBER(SEARCH("年",I6)),1/12,IF(ISNUMBER(SEARCH("日",I6)),20,1))),IF(ISNUMBER(SEARCH("日",I6)),20,IF(ISNUMBER(SEARCH("週",I6)),4.3,IF(ISNUMBER(SEARCH("月",I6)),1,""))))))) | AN6: =IF(J6="","",IF(ISNUMBER(J6),J6,IFERROR(VALUE(ASC(J6&"")),IF(ISNUMBER(SEARCH("時間",J6)),IFERROR(VALUE(SUBSTITUTE(SUBSTITUTE(SUBSTITUTE(SUBSTITUTE(SUBSTITUTE(ASC(J6&""),"約",""),"程度",""),"ほど",""),"時間","")," ",""))*60,""),IFERROR(VALUE(SUBSTITUTE(SUBSTITUTE(SUBSTITUTE(SUBSTITUTE(SUBSTITUTE(ASC(J6&""),"約",""),"程度",""),"ほど",""),"分","")," ","")),""))))) | AO6: =IF(K6="","",IF(ISNUMBER(K6),K6,IFERROR(VALUE(SUBSTITUTE(SUBSTITUTE(SUBSTITUTE(ASC(K6&""),"約",""),"件","")," ","")),""))) | AP6: =IF(W6<>"OK","",IF(COUNTIFS($D$5:$D$404,D6,$W$5:$W$404,"OK")>1,"同名あり","")) | AQ6: =IF(L6="","",IF(ISNUMBER(L6),L6,IFERROR(DATEVALUE(SUBSTITUTE(SUBSTITUTE(ASC(L6&""),"-","/"),".","/")&"/01"),""))) | AR6: =IF(M6="","",IF(ISNUMBER(M6),M6,IFERROR(DATEVALUE(SUBSTITUTE(SUBSTITUTE(ASC(M6&""),"-","/"),".","/")&"/01"),""))) | AS6: =IF(OR(W6<>"OK",AQ6=""),"",IF(AQ6>='01_設定'!$C$26,1,0)) | AT6: =IF(AND(W6="OK",Y6<>"除外"),COUNTIFS($W$5:W6,"OK",$Y$5:Y6,"<>除外"),"") | AU6: =IF(OR(AT6="",AD6=""),"",AD6+ROW()/1000000000)
W7: =IF(AND(A7="",D7=""),"",IF(ISNUMBER(SEARCH("##END",AH7)),"（終わりの印）",IF(ISNUMBER(SEARCH("##続き",AH7)),"（続きありの印）",IF(AH7="調査ID","（見出し行）",IF(AND(AH7<>"R1",AH7<>"R2"),"×表以外の行（集計されない）",IF(COUNTIF($AI$5:AI7,AI7)>1,"△重複（集計されない）",IF(D7="","△タスク名なし",IF(ISNA(MATCH(AK7,'M1_類型マスタ'!$A$5:$A$19,0)),"△類型が不正",IF(OR(AM7="",AN7=""),"△回数・分が読めない",IF(SUMPRODUCT(--ISNUMBER(--O7:U7))<7,"△採点が足りない",IF(SUMPRODUCT((--O7:U7>2)+(--O7:U7<0))>0,"△採点が範囲外","OK"))))))))))) | X7: =IF(W7<>"OK","",TRIM(IF(AND(AO7<>"",N(AO7)<=1),"根拠1件 ","")&IF(AP7<>"","同名あり ","")&IF(AND(NOT(ISNUMBER(I7)),I7<>""),"回数を換算 ",""))) | AC7: =IF(W7<>"OK","",IF(AB7<>"",AB7,AE7)) | AD7: =IF(W7<>"OK","",IFERROR(IF(Z7<>"",Z7,AM7)*IF(AA7<>"",AA7,AN7)/60,"")) | AE7: =IF(W7<>"OK","",IF(OR(VALUE(O7)=2,VALUE(P7)=2,VALUE(Q7)=2),"社内残置",IF(AND(VALUE(O7)=0,VALUE(R7)=0,VALUE(T7)=0),"自動化候補",IF(AND(VALUE(P7)=0,VALUE(R7)<=1,VALUE(S7)<=1,VALUE(T7)<=1,VALUE(U7)<=1),"オフショア候補",IF(AND(VALUE(T7)<=1,VALUE(U7)<=1),"ニアショア候補","社内で手順化→再評価"))))) | AF7: =IF(W7<>"OK","",14-SUMPRODUCT(--O7:U7)) | AG7: =IF(W7<>"OK","",AM7*AN7/60) | AH7: =IF(A7="","",UPPER(TRIM(ASC(A7&"")))) | AI7: =IF(AH7="","",AH7&"-"&B7) | AJ7: =IF(C7="","",IFERROR(VALUE(ASC(SUBSTITUTE(C7&"","観点",""))),"")) | AK7: =IF(E7="","",UPPER(LEFT(TRIM(ASC(E7&"")),3))) | AL7: =IF(I7="","",IFERROR(VALUE(SUBSTITUTE(SUBSTITUTE(SUBSTITUTE(SUBSTITUTE(SUBSTITUTE(SUBSTITUTE(SUBSTITUTE(SUBSTITUTE(SUBSTITUTE(SUBSTITUTE(SUBSTITUTE(SUBSTITUTE(ASC(I7&""),"約",""),"程度",""),"ほど",""),"回",""),"毎",""),"週",""),"月",""),"年",""),"日",""),"に",""),"/","")," ","")),"")) | AM7: =IF(I7="","",IF(ISNUMBER(I7),I7,IFERROR(VALUE(ASC(I7&"")),IF(AL7<>"",AL7*IF(ISNUMBER(SEARCH("週",I7)),4.3,IF(ISNUMBER(SEARCH("年",I7)),1/12,IF(ISNUMBER(SEARCH("日",I7)),20,1))),IF(ISNUMBER(SEARCH("日",I7)),20,IF(ISNUMBER(SEARCH("週",I7)),4.3,IF(ISNUMBER(SEARCH("月",I7)),1,""))))))) | AN7: =IF(J7="","",IF(ISNUMBER(J7),J7,IFERROR(VALUE(ASC(J7&"")),IF(ISNUMBER(SEARCH("時間",J7)),IFERROR(VALUE(SUBSTITUTE(SUBSTITUTE(SUBSTITUTE(SUBSTITUTE(SUBSTITUTE(ASC(J7&""),"約",""),"程度",""),"ほど",""),"時間","")," ",""))*60,""),IFERROR(VALUE(SUBSTITUTE(SUBSTITUTE(SUBSTITUTE(SUBSTITUTE(SUBSTITUTE(ASC(J7&""),"約",""),"程度",""),"ほど",""),"分","")," ","")),""))))) | AO7: =IF(K7="","",IF(ISNUMBER(K7),K7,IFERROR(VALUE(SUBSTITUTE(SUBSTITUTE(SUBSTITUTE(ASC(K7&""),"約",""),"件","")," ","")),""))) | AP7: =IF(W7<>"OK","",IF(COUNTIFS($D$5:$D$404,D7,$W$5:$W$404,"OK")>1,"同名あり","")) | AQ7: =IF(L7="","",IF(ISNUMBER(L7),L7,IFERROR(DATEVALUE(SUBSTITUTE(SUBSTITUTE(ASC(L7&""),"-","/"),".","/")&"/01"),""))) | AR7: =IF(M7="","",IF(ISNUMBER(M7),M7,IFERROR(DATEVALUE(SUBSTITUTE(SUBSTITUTE(ASC(M7&""),"-","/"),".","/")&"/01"),""))) | AS7: =IF(OR(W7<>"OK",AQ7=""),"",IF(AQ7>='01_設定'!$C$26,1,0)) | AT7: =IF(AND(W7="OK",Y7<>"除外"),COUNTIFS($W$5:W7,"OK",$Y$5:Y7,"<>除外"),"") | AU7: =IF(OR(AT7="",AD7=""),"",AD7+ROW()/1000000000)
W8: =IF(AND(A8="",D8=""),"",IF(ISNUMBER(SEARCH("##END",AH8)),"（終わりの印）",IF(ISNUMBER(SEARCH("##続き",AH8)),"（続きありの印）",IF(AH8="調査ID","（見出し行）",IF(AND(AH8<>"R1",AH8<>"R2"),"×表以外の行（集計されない）",IF(COUNTIF($AI$5:AI8,AI8)>1,"△重複（集計されない）",IF(D8="","△タスク名なし",IF(ISNA(MATCH(AK8,'M1_類型マスタ'!$A$5:$A$19,0)),"△類型が不正",IF(OR(AM8="",AN8=""),"△回数・分が読めない",IF(SUMPRODUCT(--ISNUMBER(--O8:U8))<7,"△採点が足りない",IF(SUMPRODUCT((--O8:U8>2)+(--O8:U8<0))>0,"△採点が範囲外","OK"))))))))))) | X8: =IF(W8<>"OK","",TRIM(IF(AND(AO8<>"",N(AO8)<=1),"根拠1件 ","")&IF(AP8<>"","同名あり ","")&IF(AND(NOT(ISNUMBER(I8)),I8<>""),"回数を換算 ",""))) | AC8: =IF(W8<>"OK","",IF(AB8<>"",AB8,AE8)) | AD8: =IF(W8<>"OK","",IFERROR(IF(Z8<>"",Z8,AM8)*IF(AA8<>"",AA8,AN8)/60,"")) | AE8: =IF(W8<>"OK","",IF(OR(VALUE(O8)=2,VALUE(P8)=2,VALUE(Q8)=2),"社内残置",IF(AND(VALUE(O8)=0,VALUE(R8)=0,VALUE(T8)=0),"自動化候補",IF(AND(VALUE(P8)=0,VALUE(R8)<=1,VALUE(S8)<=1,VALUE(T8)<=1,VALUE(U8)<=1),"オフショア候補",IF(AND(VALUE(T8)<=1,VALUE(U8)<=1),"ニアショア候補","社内で手順化→再評価"))))) | AF8: =IF(W8<>"OK","",14-SUMPRODUCT(--O8:U8)) | AG8: =IF(W8<>"OK","",AM8*AN8/60) | AH8: =IF(A8="","",UPPER(TRIM(ASC(A8&"")))) | AI8: =IF(AH8="","",AH8&"-"&B8) | AJ8: =IF(C8="","",IFERROR(VALUE(ASC(SUBSTITUTE(C8&"","観点",""))),"")) | AK8: =IF(E8="","",UPPER(LEFT(TRIM(ASC(E8&"")),3))) | AL8: =IF(I8="","",IFERROR(VALUE(SUBSTITUTE(SUBSTITUTE(SUBSTITUTE(SUBSTITUTE(SUBSTITUTE(SUBSTITUTE(SUBSTITUTE(SUBSTITUTE(SUBSTITUTE(SUBSTITUTE(SUBSTITUTE(SUBSTITUTE(ASC(I8&""),"約",""),"程度",""),"ほど",""),"回",""),"毎",""),"週",""),"月",""),"年",""),"日",""),"に",""),"/","")," ","")),"")) | AM8: =IF(I8="","",IF(ISNUMBER(I8),I8,IFERROR(VALUE(ASC(I8&"")),IF(AL8<>"",AL8*IF(ISNUMBER(SEARCH("週",I8)),4.3,IF(ISNUMBER(SEARCH("年",I8)),1/12,IF(ISNUMBER(SEARCH("日",I8)),20,1))),IF(ISNUMBER(SEARCH("日",I8)),20,IF(ISNUMBER(SEARCH("週",I8)),4.3,IF(ISNUMBER(SEARCH("月",I8)),1,""))))))) | AN8: =IF(J8="","",IF(ISNUMBER(J8),J8,IFERROR(VALUE(ASC(J8&"")),IF(ISNUMBER(SEARCH("時間",J8)),IFERROR(VALUE(SUBSTITUTE(SUBSTITUTE(SUBSTITUTE(SUBSTITUTE(SUBSTITUTE(ASC(J8&""),"約",""),"程度",""),"ほど",""),"時間","")," ",""))*60,""),IFERROR(VALUE(SUBSTITUTE(SUBSTITUTE(SUBSTITUTE(SUBSTITUTE(SUBSTITUTE(ASC(J8&""),"約",""),"程度",""),"ほど",""),"分","")," ","")),""))))) | AO8: =IF(K8="","",IF(ISNUMBER(K8),K8,IFERROR(VALUE(SUBSTITUTE(SUBSTITUTE(SUBSTITUTE(ASC(K8&""),"約",""),"件","")," ","")),""))) | AP8: =IF(W8<>"OK","",IF(COUNTIFS($D$5:$D$404,D8,$W$5:$W$404,"OK")>1,"同名あり","")) | AQ8: =IF(L8="","",IF(ISNUMBER(L8),L8,IFERROR(DATEVALUE(SUBSTITUTE(SUBSTITUTE(ASC(L8&""),"-","/"),".","/")&"/01"),""))) | AR8: =IF(M8="","",IF(ISNUMBER(M8),M8,IFERROR(DATEVALUE(SUBSTITUTE(SUBSTITUTE(ASC(M8&""),"-","/"),".","/")&"/01"),""))) | AS8: =IF(OR(W8<>"OK",AQ8=""),"",IF(AQ8>='01_設定'!$C$26,1,0)) | AT8: =IF(AND(W8="OK",Y8<>"除外"),COUNTIFS($W$5:W8,"OK",$Y$5:Y8,"<>除外"),"") | AU8: =IF(OR(AT8="",AD8=""),"",AD8+ROW()/1000000000)
W9: =IF(AND(A9="",D9=""),"",IF(ISNUMBER(SEARCH("##END",AH9)),"（終わりの印）",IF(ISNUMBER(SEARCH("##続き",AH9)),"（続きありの印）",IF(AH9="調査ID","（見出し行）",IF(AND(AH9<>"R1",AH9<>"R2"),"×表以外の行（集計されない）",IF(COUNTIF($AI$5:AI9,AI9)>1,"△重複（集計されない）",IF(D9="","△タスク名なし",IF(ISNA(MATCH(AK9,'M1_類型マスタ'!$A$5:$A$19,0)),"△類型が不正",IF(OR(AM9="",AN9=""),"△回数・分が読めない",IF(SUMPRODUCT(--ISNUMBER(--O9:U9))<7,"△採点が足りない",IF(SUMPRODUCT((--O9:U9>2)+(--O9:U9<0))>0,"△採点が範囲外","OK"))))))))))) | X9: =IF(W9<>"OK","",TRIM(IF(AND(AO9<>"",N(AO9)<=1),"根拠1件 ","")&IF(AP9<>"","同名あり ","")&IF(AND(NOT(ISNUMBER(I9)),I9<>""),"回数を換算 ",""))) | AC9: =IF(W9<>"OK","",IF(AB9<>"",AB9,AE9)) | AD9: =IF(W9<>"OK","",IFERROR(IF(Z9<>"",Z9,AM9)*IF(AA9<>"",AA9,AN9)/60,"")) | AE9: =IF(W9<>"OK","",IF(OR(VALUE(O9)=2,VALUE(P9)=2,VALUE(Q9)=2),"社内残置",IF(AND(VALUE(O9)=0,VALUE(R9)=0,VALUE(T9)=0),"自動化候補",IF(AND(VALUE(P9)=0,VALUE(R9)<=1,VALUE(S9)<=1,VALUE(T9)<=1,VALUE(U9)<=1),"オフショア候補",IF(AND(VALUE(T9)<=1,VALUE(U9)<=1),"ニアショア候補","社内で手順化→再評価"))))) | AF9: =IF(W9<>"OK","",14-SUMPRODUCT(--O9:U9)) | AG9: =IF(W9<>"OK","",AM9*AN9/60) | AH9: =IF(A9="","",UPPER(TRIM(ASC(A9&"")))) | AI9: =IF(AH9="","",AH9&"-"&B9) | AJ9: =IF(C9="","",IFERROR(VALUE(ASC(SUBSTITUTE(C9&"","観点",""))),"")) | AK9: =IF(E9="","",UPPER(LEFT(TRIM(ASC(E9&"")),3))) | AL9: =IF(I9="","",IFERROR(VALUE(SUBSTITUTE(SUBSTITUTE(SUBSTITUTE(SUBSTITUTE(SUBSTITUTE(SUBSTITUTE(SUBSTITUTE(SUBSTITUTE(SUBSTITUTE(SUBSTITUTE(SUBSTITUTE(SUBSTITUTE(ASC(I9&""),"約",""),"程度",""),"ほど",""),"回",""),"毎",""),"週",""),"月",""),"年",""),"日",""),"に",""),"/","")," ","")),"")) | AM9: =IF(I9="","",IF(ISNUMBER(I9),I9,IFERROR(VALUE(ASC(I9&"")),IF(AL9<>"",AL9*IF(ISNUMBER(SEARCH("週",I9)),4.3,IF(ISNUMBER(SEARCH("年",I9)),1/12,IF(ISNUMBER(SEARCH("日",I9)),20,1))),IF(ISNUMBER(SEARCH("日",I9)),20,IF(ISNUMBER(SEARCH("週",I9)),4.3,IF(ISNUMBER(SEARCH("月",I9)),1,""))))))) | AN9: =IF(J9="","",IF(ISNUMBER(J9),J9,IFERROR(VALUE(ASC(J9&"")),IF(ISNUMBER(SEARCH("時間",J9)),IFERROR(VALUE(SUBSTITUTE(SUBSTITUTE(SUBSTITUTE(SUBSTITUTE(SUBSTITUTE(ASC(J9&""),"約",""),"程度",""),"ほど",""),"時間","")," ",""))*60,""),IFERROR(VALUE(SUBSTITUTE(SUBSTITUTE(SUBSTITUTE(SUBSTITUTE(SUBSTITUTE(ASC(J9&""),"約",""),"程度",""),"ほど",""),"分","")," ","")),""))))) | AO9: =IF(K9="","",IF(ISNUMBER(K9),K9,IFERROR(VALUE(SUBSTITUTE(SUBSTITUTE(SUBSTITUTE(ASC(K9&""),"約",""),"件","")," ","")),""))) | AP9: =IF(W9<>"OK","",IF(COUNTIFS($D$5:$D$404,D9,$W$5:$W$404,"OK")>1,"同名あり","")) | AQ9: =IF(L9="","",IF(ISNUMBER(L9),L9,IFERROR(DATEVALUE(SUBSTITUTE(SUBSTITUTE(ASC(L9&""),"-","/"),".","/")&"/01"),""))) | AR9: =IF(M9="","",IF(ISNUMBER(M9),M9,IFERROR(DATEVALUE(SUBSTITUTE(SUBSTITUTE(ASC(M9&""),"-","/"),".","/")&"/01"),""))) | AS9: =IF(OR(W9<>"OK",AQ9=""),"",IF(AQ9>='01_設定'!$C$26,1,0)) | AT9: =IF(AND(W9="OK",Y9<>"除外"),COUNTIFS($W$5:W9,"OK",$Y$5:Y9,"<>除外"),"") | AU9: =IF(OR(AT9="",AD9=""),"",AD9+ROW()/1000000000)
W10: =IF(AND(A10="",D10=""),"",IF(ISNUMBER(SEARCH("##END",AH10)),"（終わりの印）",IF(ISNUMBER(SEARCH("##続き",AH10)),"（続きありの印）",IF(AH10="調査ID","（見出し行）",IF(AND(AH10<>"R1",AH10<>"R2"),"×表以外の行（集計されない）",IF(COUNTIF($AI$5:AI10,AI10)>1,"△重複（集計されない）",IF(D10="","△タスク名なし",IF(ISNA(MATCH(AK10,'M1_類型マスタ'!$A$5:$A$19,0)),"△類型が不正",IF(OR(AM10="",AN10=""),"△回数・分が読めない",IF(SUMPRODUCT(--ISNUMBER(--O10:U10))<7,"△採点が足りない",IF(SUMPRODUCT((--O10:U10>2)+(--O10:U10<0))>0,"△採点が範囲外","OK"))))))))))) | X10: =IF(W10<>"OK","",TRIM(IF(AND(AO10<>"",N(AO10)<=1),"根拠1件 ","")&IF(AP10<>"","同名あり ","")&IF(AND(NOT(ISNUMBER(I10)),I10<>""),"回数を換算 ",""))) | AC10: =IF(W10<>"OK","",IF(AB10<>"",AB10,AE10)) | AD10: =IF(W10<>"OK","",IFERROR(IF(Z10<>"",Z10,AM10)*IF(AA10<>"",AA10,AN10)/60,"")) | AE10: =IF(W10<>"OK","",IF(OR(VALUE(O10)=2,VALUE(P10)=2,VALUE(Q10)=2),"社内残置",IF(AND(VALUE(O10)=0,VALUE(R10)=0,VALUE(T10)=0),"自動化候補",IF(AND(VALUE(P10)=0,VALUE(R10)<=1,VALUE(S10)<=1,VALUE(T10)<=1,VALUE(U10)<=1),"オフショア候補",IF(AND(VALUE(T10)<=1,VALUE(U10)<=1),"ニアショア候補","社内で手順化→再評価"))))) | AF10: =IF(W10<>"OK","",14-SUMPRODUCT(--O10:U10)) | AG10: =IF(W10<>"OK","",AM10*AN10/60) | AH10: =IF(A10="","",UPPER(TRIM(ASC(A10&"")))) | AI10: =IF(AH10="","",AH10&"-"&B10) | AJ10: =IF(C10="","",IFERROR(VALUE(ASC(SUBSTITUTE(C10&"","観点",""))),"")) | AK10: =IF(E10="","",UPPER(LEFT(TRIM(ASC(E10&"")),3))) | AL10: =IF(I10="","",IFERROR(VALUE(SUBSTITUTE(SUBSTITUTE(SUBSTITUTE(SUBSTITUTE(SUBSTITUTE(SUBSTITUTE(SUBSTITUTE(SUBSTITUTE(SUBSTITUTE(SUBSTITUTE(SUBSTITUTE(SUBSTITUTE(ASC(I10&""),"約",""),"程度",""),"ほど",""),"回",""),"毎",""),"週",""),"月",""),"年",""),"日",""),"に",""),"/","")," ","")),"")) | AM10: =IF(I10="","",IF(ISNUMBER(I10),I10,IFERROR(VALUE(ASC(I10&"")),IF(AL10<>"",AL10*IF(ISNUMBER(SEARCH("週",I10)),4.3,IF(ISNUMBER(SEARCH("年",I10)),1/12,IF(ISNUMBER(SEARCH("日",I10)),20,1))),IF(ISNUMBER(SEARCH("日",I10)),20,IF(ISNUMBER(SEARCH("週",I10)),4.3,IF(ISNUMBER(SEARCH("月",I10)),1,""))))))) | AN10: =IF(J10="","",IF(ISNUMBER(J10),J10,IFERROR(VALUE(ASC(J10&"")),IF(ISNUMBER(SEARCH("時間",J10)),IFERROR(VALUE(SUBSTITUTE(SUBSTITUTE(SUBSTITUTE(SUBSTITUTE(SUBSTITUTE(ASC(J10&""),"約",""),"程度",""),"ほど",""),"時間","")," ",""))*60,""),IFERROR(VALUE(SUBSTITUTE(SUBSTITUTE(SUBSTITUTE(SUBSTITUTE(SUBSTITUTE(ASC(J10&""),"約",""),"程度",""),"ほど",""),"分","")," ","")),""))))) | AO10: =IF(K10="","",IF(ISNUMBER(K10),K10,IFERROR(VALUE(SUBSTITUTE(SUBSTITUTE(SUBSTITUTE(ASC(K10&""),"約",""),"件","")," ","")),""))) | AP10: =IF(W10<>"OK","",IF(COUNTIFS($D$5:$D$404,D10,$W$5:$W$404,"OK")>1,"同名あり","")) | AQ10: =IF(L10="","",IF(ISNUMBER(L10),L10,IFERROR(DATEVALUE(SUBSTITUTE(SUBSTITUTE(ASC(L10&""),"-","/"),".","/")&"/01"),""))) | AR10: =IF(M10="","",IF(ISNUMBER(M10),M10,IFERROR(DATEVALUE(SUBSTITUTE(SUBSTITUTE(ASC(M10&""),"-","/"),".","/")&"/01"),""))) | AS10: =IF(OR(W10<>"OK",AQ10=""),"",IF(AQ10>='01_設定'!$C$26,1,0)) | AT10: =IF(AND(W10="OK",Y10<>"除外"),COUNTIFS($W$5:W10,"OK",$Y$5:Y10,"<>除外"),"") | AU10: =IF(OR(AT10="",AD10=""),"",AD10+ROW()/1000000000)
W11: =IF(AND(A11="",D11=""),"",IF(ISNUMBER(SEARCH("##END",AH11)),"（終わりの印）",IF(ISNUMBER(SEARCH("##続き",AH11)),"（続きありの印）",IF(AH11="調査ID","（見出し行）",IF(AND(AH11<>"R1",AH11<>"R2"),"×表以外の行（集計されない）",IF(COUNTIF($AI$5:AI11,AI11)>1,"△重複（集計されない）",IF(D11="","△タスク名なし",IF(ISNA(MATCH(AK11,'M1_類型マスタ'!$A$5:$A$19,0)),"△類型が不正",IF(OR(AM11="",AN11=""),"△回数・分が読めない",IF(SUMPRODUCT(--ISNUMBER(--O11:U11))<7,"△採点が足りない",IF(SUMPRODUCT((--O11:U11>2)+(--O11:U11<0))>0,"△採点が範囲外","OK"))))))))))) | X11: =IF(W11<>"OK","",TRIM(IF(AND(AO11<>"",N(AO11)<=1),"根拠1件 ","")&IF(AP11<>"","同名あり ","")&IF(AND(NOT(ISNUMBER(I11)),I11<>""),"回数を換算 ",""))) | AC11: =IF(W11<>"OK","",IF(AB11<>"",AB11,AE11)) | AD11: =IF(W11<>"OK","",IFERROR(IF(Z11<>"",Z11,AM11)*IF(AA11<>"",AA11,AN11)/60,"")) | AE11: =IF(W11<>"OK","",IF(OR(VALUE(O11)=2,VALUE(P11)=2,VALUE(Q11)=2),"社内残置",IF(AND(VALUE(O11)=0,VALUE(R11)=0,VALUE(T11)=0),"自動化候補",IF(AND(VALUE(P11)=0,VALUE(R11)<=1,VALUE(S11)<=1,VALUE(T11)<=1,VALUE(U11)<=1),"オフショア候補",IF(AND(VALUE(T11)<=1,VALUE(U11)<=1),"ニアショア候補","社内で手順化→再評価"))))) | AF11: =IF(W11<>"OK","",14-SUMPRODUCT(--O11:U11)) | AG11: =IF(W11<>"OK","",AM11*AN11/60) | AH11: =IF(A11="","",UPPER(TRIM(ASC(A11&"")))) | AI11: =IF(AH11="","",AH11&"-"&B11) | AJ11: =IF(C11="","",IFERROR(VALUE(ASC(SUBSTITUTE(C11&"","観点",""))),"")) | AK11: =IF(E11="","",UPPER(LEFT(TRIM(ASC(E11&"")),3))) | AL11: =IF(I11="","",IFERROR(VALUE(SUBSTITUTE(SUBSTITUTE(SUBSTITUTE(SUBSTITUTE(SUBSTITUTE(SUBSTITUTE(SUBSTITUTE(SUBSTITUTE(SUBSTITUTE(SUBSTITUTE(SUBSTITUTE(SUBSTITUTE(ASC(I11&""),"約",""),"程度",""),"ほど",""),"回",""),"毎",""),"週",""),"月",""),"年",""),"日",""),"に",""),"/","")," ","")),"")) | AM11: =IF(I11="","",IF(ISNUMBER(I11),I11,IFERROR(VALUE(ASC(I11&"")),IF(AL11<>"",AL11*IF(ISNUMBER(SEARCH("週",I11)),4.3,IF(ISNUMBER(SEARCH("年",I11)),1/12,IF(ISNUMBER(SEARCH("日",I11)),20,1))),IF(ISNUMBER(SEARCH("日",I11)),20,IF(ISNUMBER(SEARCH("週",I11)),4.3,IF(ISNUMBER(SEARCH("月",I11)),1,""))))))) | AN11: =IF(J11="","",IF(ISNUMBER(J11),J11,IFERROR(VALUE(ASC(J11&"")),IF(ISNUMBER(SEARCH("時間",J11)),IFERROR(VALUE(SUBSTITUTE(SUBSTITUTE(SUBSTITUTE(SUBSTITUTE(SUBSTITUTE(ASC(J11&""),"約",""),"程度",""),"ほど",""),"時間","")," ",""))*60,""),IFERROR(VALUE(SUBSTITUTE(SUBSTITUTE(SUBSTITUTE(SUBSTITUTE(SUBSTITUTE(ASC(J11&""),"約",""),"程度",""),"ほど",""),"分","")," ","")),""))))) | AO11: =IF(K11="","",IF(ISNUMBER(K11),K11,IFERROR(VALUE(SUBSTITUTE(SUBSTITUTE(SUBSTITUTE(ASC(K11&""),"約",""),"件","")," ","")),""))) | AP11: =IF(W11<>"OK","",IF(COUNTIFS($D$5:$D$404,D11,$W$5:$W$404,"OK")>1,"同名あり","")) | AQ11: =IF(L11="","",IF(ISNUMBER(L11),L11,IFERROR(DATEVALUE(SUBSTITUTE(SUBSTITUTE(ASC(L11&""),"-","/"),".","/")&"/01"),""))) | AR11: =IF(M11="","",IF(ISNUMBER(M11),M11,IFERROR(DATEVALUE(SUBSTITUTE(SUBSTITUTE(ASC(M11&""),"-","/"),".","/")&"/01"),""))) | AS11: =IF(OR(W11<>"OK",AQ11=""),"",IF(AQ11>='01_設定'!$C$26,1,0)) | AT11: =IF(AND(W11="OK",Y11<>"除外"),COUNTIFS($W$5:W11,"OK",$Y$5:Y11,"<>除外"),"") | AU11: =IF(OR(AT11="",AD11=""),"",AD11+ROW()/1000000000)
W12: =IF(AND(A12="",D12=""),"",IF(ISNUMBER(SEARCH("##END",AH12)),"（終わりの印）",IF(ISNUMBER(SEARCH("##続き",AH12)),"（続きありの印）",IF(AH12="調査ID","（見出し行）",IF(AND(AH12<>"R1",AH12<>"R2"),"×表以外の行（集計されない）",IF(COUNTIF($AI$5:AI12,AI12)>1,"△重複（集計されない）",IF(D12="","△タスク名なし",IF(ISNA(MATCH(AK12,'M1_類型マスタ'!$A$5:$A$19,0)),"△類型が不正",IF(OR(AM12="",AN12=""),"△回数・分が読めない",IF(SUMPRODUCT(--ISNUMBER(--O12:U12))<7,"△採点が足りない",IF(SUMPRODUCT((--O12:U12>2)+(--O12:U12<0))>0,"△採点が範囲外","OK"))))))))))) | X12: =IF(W12<>"OK","",TRIM(IF(AND(AO12<>"",N(AO12)<=1),"根拠1件 ","")&IF(AP12<>"","同名あり ","")&IF(AND(NOT(ISNUMBER(I12)),I12<>""),"回数を換算 ",""))) | AC12: =IF(W12<>"OK","",IF(AB12<>"",AB12,AE12)) | AD12: =IF(W12<>"OK","",IFERROR(IF(Z12<>"",Z12,AM12)*IF(AA12<>"",AA12,AN12)/60,"")) | AE12: =IF(W12<>"OK","",IF(OR(VALUE(O12)=2,VALUE(P12)=2,VALUE(Q12)=2),"社内残置",IF(AND(VALUE(O12)=0,VALUE(R12)=0,VALUE(T12)=0),"自動化候補",IF(AND(VALUE(P12)=0,VALUE(R12)<=1,VALUE(S12)<=1,VALUE(T12)<=1,VALUE(U12)<=1),"オフショア候補",IF(AND(VALUE(T12)<=1,VALUE(U12)<=1),"ニアショア候補","社内で手順化→再評価"))))) | AF12: =IF(W12<>"OK","",14-SUMPRODUCT(--O12:U12)) | AG12: =IF(W12<>"OK","",AM12*AN12/60) | AH12: =IF(A12="","",UPPER(TRIM(ASC(A12&"")))) | AI12: =IF(AH12="","",AH12&"-"&B12) | AJ12: =IF(C12="","",IFERROR(VALUE(ASC(SUBSTITUTE(C12&"","観点",""))),"")) | AK12: =IF(E12="","",UPPER(LEFT(TRIM(ASC(E12&"")),3))) | AL12: =IF(I12="","",IFERROR(VALUE(SUBSTITUTE(SUBSTITUTE(SUBSTITUTE(SUBSTITUTE(SUBSTITUTE(SUBSTITUTE(SUBSTITUTE(SUBSTITUTE(SUBSTITUTE(SUBSTITUTE(SUBSTITUTE(SUBSTITUTE(ASC(I12&""),"約",""),"程度",""),"ほど",""),"回",""),"毎",""),"週",""),"月",""),"年",""),"日",""),"に",""),"/","")," ","")),"")) | AM12: =IF(I12="","",IF(ISNUMBER(I12),I12,IFERROR(VALUE(ASC(I12&"")),IF(AL12<>"",AL12*IF(ISNUMBER(SEARCH("週",I12)),4.3,IF(ISNUMBER(SEARCH("年",I12)),1/12,IF(ISNUMBER(SEARCH("日",I12)),20,1))),IF(ISNUMBER(SEARCH("日",I12)),20,IF(ISNUMBER(SEARCH("週",I12)),4.3,IF(ISNUMBER(SEARCH("月",I12)),1,""))))))) | AN12: =IF(J12="","",IF(ISNUMBER(J12),J12,IFERROR(VALUE(ASC(J12&"")),IF(ISNUMBER(SEARCH("時間",J12)),IFERROR(VALUE(SUBSTITUTE(SUBSTITUTE(SUBSTITUTE(SUBSTITUTE(SUBSTITUTE(ASC(J12&""),"約",""),"程度",""),"ほど",""),"時間","")," ",""))*60,""),IFERROR(VALUE(SUBSTITUTE(SUBSTITUTE(SUBSTITUTE(SUBSTITUTE(SUBSTITUTE(ASC(J12&""),"約",""),"程度",""),"ほど",""),"分","")," ","")),""))))) | AO12: =IF(K12="","",IF(ISNUMBER(K12),K12,IFERROR(VALUE(SUBSTITUTE(SUBSTITUTE(SUBSTITUTE(ASC(K12&""),"約",""),"件","")," ","")),""))) | AP12: =IF(W12<>"OK","",IF(COUNTIFS($D$5:$D$404,D12,$W$5:$W$404,"OK")>1,"同名あり","")) | AQ12: =IF(L12="","",IF(ISNUMBER(L12),L12,IFERROR(DATEVALUE(SUBSTITUTE(SUBSTITUTE(ASC(L12&""),"-","/"),".","/")&"/01"),""))) | AR12: =IF(M12="","",IF(ISNUMBER(M12),M12,IFERROR(DATEVALUE(SUBSTITUTE(SUBSTITUTE(ASC(M12&""),"-","/"),".","/")&"/01"),""))) | AS12: =IF(OR(W12<>"OK",AQ12=""),"",IF(AQ12>='01_設定'!$C$26,1,0)) | AT12: =IF(AND(W12="OK",Y12<>"除外"),COUNTIFS($W$5:W12,"OK",$Y$5:Y12,"<>除外"),"") | AU12: =IF(OR(AT12="",AD12=""),"",AD12+ROW()/1000000000)
W13: =IF(AND(A13="",D13=""),"",IF(ISNUMBER(SEARCH("##END",AH13)),"（終わりの印）",IF(ISNUMBER(SEARCH("##続き",AH13)),"（続きありの印）",IF(AH13="調査ID","（見出し行）",IF(AND(AH13<>"R1",AH13<>"R2"),"×表以外の行（集計されない）",IF(COUNTIF($AI$5:AI13,AI13)>1,"△重複（集計されない）",IF(D13="","△タスク名なし",IF(ISNA(MATCH(AK13,'M1_類型マスタ'!$A$5:$A$19,0)),"△類型が不正",IF(OR(AM13="",AN13=""),"△回数・分が読めない",IF(SUMPRODUCT(--ISNUMBER(--O13:U13))<7,"△採点が足りない",IF(SUMPRODUCT((--O13:U13>2)+(--O13:U13<0))>0,"△採点が範囲外","OK"))))))))))) | X13: =IF(W13<>"OK","",TRIM(IF(AND(AO13<>"",N(AO13)<=1),"根拠1件 ","")&IF(AP13<>"","同名あり ","")&IF(AND(NOT(ISNUMBER(I13)),I13<>""),"回数を換算 ",""))) | AC13: =IF(W13<>"OK","",IF(AB13<>"",AB13,AE13)) | AD13: =IF(W13<>"OK","",IFERROR(IF(Z13<>"",Z13,AM13)*IF(AA13<>"",AA13,AN13)/60,"")) | AE13: =IF(W13<>"OK","",IF(OR(VALUE(O13)=2,VALUE(P13)=2,VALUE(Q13)=2),"社内残置",IF(AND(VALUE(O13)=0,VALUE(R13)=0,VALUE(T13)=0),"自動化候補",IF(AND(VALUE(P13)=0,VALUE(R13)<=1,VALUE(S13)<=1,VALUE(T13)<=1,VALUE(U13)<=1),"オフショア候補",IF(AND(VALUE(T13)<=1,VALUE(U13)<=1),"ニアショア候補","社内で手順化→再評価"))))) | AF13: =IF(W13<>"OK","",14-SUMPRODUCT(--O13:U13)) | AG13: =IF(W13<>"OK","",AM13*AN13/60) | AH13: =IF(A13="","",UPPER(TRIM(ASC(A13&"")))) | AI13: =IF(AH13="","",AH13&"-"&B13) | AJ13: =IF(C13="","",IFERROR(VALUE(ASC(SUBSTITUTE(C13&"","観点",""))),"")) | AK13: =IF(E13="","",UPPER(LEFT(TRIM(ASC(E13&"")),3))) | AL13: =IF(I13="","",IFERROR(VALUE(SUBSTITUTE(SUBSTITUTE(SUBSTITUTE(SUBSTITUTE(SUBSTITUTE(SUBSTITUTE(SUBSTITUTE(SUBSTITUTE(SUBSTITUTE(SUBSTITUTE(SUBSTITUTE(SUBSTITUTE(ASC(I13&""),"約",""),"程度",""),"ほど",""),"回",""),"毎",""),"週",""),"月",""),"年",""),"日",""),"に",""),"/","")," ","")),"")) | AM13: =IF(I13="","",IF(ISNUMBER(I13),I13,IFERROR(VALUE(ASC(I13&"")),IF(AL13<>"",AL13*IF(ISNUMBER(SEARCH("週",I13)),4.3,IF(ISNUMBER(SEARCH("年",I13)),1/12,IF(ISNUMBER(SEARCH("日",I13)),20,1))),IF(ISNUMBER(SEARCH("日",I13)),20,IF(ISNUMBER(SEARCH("週",I13)),4.3,IF(ISNUMBER(SEARCH("月",I13)),1,""))))))) | AN13: =IF(J13="","",IF(ISNUMBER(J13),J13,IFERROR(VALUE(ASC(J13&"")),IF(ISNUMBER(SEARCH("時間",J13)),IFERROR(VALUE(SUBSTITUTE(SUBSTITUTE(SUBSTITUTE(SUBSTITUTE(SUBSTITUTE(ASC(J13&""),"約",""),"程度",""),"ほど",""),"時間","")," ",""))*60,""),IFERROR(VALUE(SUBSTITUTE(SUBSTITUTE(SUBSTITUTE(SUBSTITUTE(SUBSTITUTE(ASC(J13&""),"約",""),"程度",""),"ほど",""),"分","")," ","")),""))))) | AO13: =IF(K13="","",IF(ISNUMBER(K13),K13,IFERROR(VALUE(SUBSTITUTE(SUBSTITUTE(SUBSTITUTE(ASC(K13&""),"約",""),"件","")," ","")),""))) | AP13: =IF(W13<>"OK","",IF(COUNTIFS($D$5:$D$404,D13,$W$5:$W$404,"OK")>1,"同名あり","")) | AQ13: =IF(L13="","",IF(ISNUMBER(L13),L13,IFERROR(DATEVALUE(SUBSTITUTE(SUBSTITUTE(ASC(L13&""),"-","/"),".","/")&"/01"),""))) | AR13: =IF(M13="","",IF(ISNUMBER(M13),M13,IFERROR(DATEVALUE(SUBSTITUTE(SUBSTITUTE(ASC(M13&""),"-","/"),".","/")&"/01"),""))) | AS13: =IF(OR(W13<>"OK",AQ13=""),"",IF(AQ13>='01_設定'!$C$26,1,0)) | AT13: =IF(AND(W13="OK",Y13<>"除外"),COUNTIFS($W$5:W13,"OK",$Y$5:Y13,"<>除外"),"") | AU13: =IF(OR(AT13="",AD13=""),"",AD13+ROW()/1000000000)
W14: =IF(AND(A14="",D14=""),"",IF(ISNUMBER(SEARCH("##END",AH14)),"（終わりの印）",IF(ISNUMBER(SEARCH("##続き",AH14)),"（続きありの印）",IF(AH14="調査ID","（見出し行）",IF(AND(AH14<>"R1",AH14<>"R2"),"×表以外の行（集計されない）",IF(COUNTIF($AI$5:AI14,AI14)>1,"△重複（集計されない）",IF(D14="","△タスク名なし",IF(ISNA(MATCH(AK14,'M1_類型マスタ'!$A$5:$A$19,0)),"△類型が不正",IF(OR(AM14="",AN14=""),"△回数・分が読めない",IF(SUMPRODUCT(--ISNUMBER(--O14:U14))<7,"△採点が足りない",IF(SUMPRODUCT((--O14:U14>2)+(--O14:U14<0))>0,"△採点が範囲外","OK"))))))))))) | X14: =IF(W14<>"OK","",TRIM(IF(AND(AO14<>"",N(AO14)<=1),"根拠1件 ","")&IF(AP14<>"","同名あり ","")&IF(AND(NOT(ISNUMBER(I14)),I14<>""),"回数を換算 ",""))) | AC14: =IF(W14<>"OK","",IF(AB14<>"",AB14,AE14)) | AD14: =IF(W14<>"OK","",IFERROR(IF(Z14<>"",Z14,AM14)*IF(AA14<>"",AA14,AN14)/60,"")) | AE14: =IF(W14<>"OK","",IF(OR(VALUE(O14)=2,VALUE(P14)=2,VALUE(Q14)=2),"社内残置",IF(AND(VALUE(O14)=0,VALUE(R14)=0,VALUE(T14)=0),"自動化候補",IF(AND(VALUE(P14)=0,VALUE(R14)<=1,VALUE(S14)<=1,VALUE(T14)<=1,VALUE(U14)<=1),"オフショア候補",IF(AND(VALUE(T14)<=1,VALUE(U14)<=1),"ニアショア候補","社内で手順化→再評価"))))) | AF14: =IF(W14<>"OK","",14-SUMPRODUCT(--O14:U14)) | AG14: =IF(W14<>"OK","",AM14*AN14/60) | AH14: =IF(A14="","",UPPER(TRIM(ASC(A14&"")))) | AI14: =IF(AH14="","",AH14&"-"&B14) | AJ14: =IF(C14="","",IFERROR(VALUE(ASC(SUBSTITUTE(C14&"","観点",""))),"")) | AK14: =IF(E14="","",UPPER(LEFT(TRIM(ASC(E14&"")),3))) | AL14: =IF(I14="","",IFERROR(VALUE(SUBSTITUTE(SUBSTITUTE(SUBSTITUTE(SUBSTITUTE(SUBSTITUTE(SUBSTITUTE(SUBSTITUTE(SUBSTITUTE(SUBSTITUTE(SUBSTITUTE(SUBSTITUTE(SUBSTITUTE(ASC(I14&""),"約",""),"程度",""),"ほど",""),"回",""),"毎",""),"週",""),"月",""),"年",""),"日",""),"に",""),"/","")," ","")),"")) | AM14: =IF(I14="","",IF(ISNUMBER(I14),I14,IFERROR(VALUE(ASC(I14&"")),IF(AL14<>"",AL14*IF(ISNUMBER(SEARCH("週",I14)),4.3,IF(ISNUMBER(SEARCH("年",I14)),1/12,IF(ISNUMBER(SEARCH("日",I14)),20,1))),IF(ISNUMBER(SEARCH("日",I14)),20,IF(ISNUMBER(SEARCH("週",I14)),4.3,IF(ISNUMBER(SEARCH("月",I14)),1,""))))))) | AN14: =IF(J14="","",IF(ISNUMBER(J14),J14,IFERROR(VALUE(ASC(J14&"")),IF(ISNUMBER(SEARCH("時間",J14)),IFERROR(VALUE(SUBSTITUTE(SUBSTITUTE(SUBSTITUTE(SUBSTITUTE(SUBSTITUTE(ASC(J14&""),"約",""),"程度",""),"ほど",""),"時間","")," ",""))*60,""),IFERROR(VALUE(SUBSTITUTE(SUBSTITUTE(SUBSTITUTE(SUBSTITUTE(SUBSTITUTE(ASC(J14&""),"約",""),"程度",""),"ほど",""),"分","")," ","")),""))))) | AO14: =IF(K14="","",IF(ISNUMBER(K14),K14,IFERROR(VALUE(SUBSTITUTE(SUBSTITUTE(SUBSTITUTE(ASC(K14&""),"約",""),"件","")," ","")),""))) | AP14: =IF(W14<>"OK","",IF(COUNTIFS($D$5:$D$404,D14,$W$5:$W$404,"OK")>1,"同名あり","")) | AQ14: =IF(L14="","",IF(ISNUMBER(L14),L14,IFERROR(DATEVALUE(SUBSTITUTE(SUBSTITUTE(ASC(L14&""),"-","/"),".","/")&"/01"),""))) | AR14: =IF(M14="","",IF(ISNUMBER(M14),M14,IFERROR(DATEVALUE(SUBSTITUTE(SUBSTITUTE(ASC(M14&""),"-","/"),".","/")&"/01"),""))) | AS14: =IF(OR(W14<>"OK",AQ14=""),"",IF(AQ14>='01_設定'!$C$26,1,0)) | AT14: =IF(AND(W14="OK",Y14<>"除外"),COUNTIFS($W$5:W14,"OK",$Y$5:Y14,"<>除外"),"") | AU14: =IF(OR(AT14="",AD14=""),"",AD14+ROW()/1000000000)
W15: =IF(AND(A15="",D15=""),"",IF(ISNUMBER(SEARCH("##END",AH15)),"（終わりの印）",IF(ISNUMBER(SEARCH("##続き",AH15)),"（続きありの印）",IF(AH15="調査ID","（見出し行）",IF(AND(AH15<>"R1",AH15<>"R2"),"×表以外の行（集計されない）",IF(COUNTIF($AI$5:AI15,AI15)>1,"△重複（集計されない）",IF(D15="","△タスク名なし",IF(ISNA(MATCH(AK15,'M1_類型マスタ'!$A$5:$A$19,0)),"△類型が不正",IF(OR(AM15="",AN15=""),"△回数・分が読めない",IF(SUMPRODUCT(--ISNUMBER(--O15:U15))<7,"△採点が足りない",IF(SUMPRODUCT((--O15:U15>2)+(--O15:U15<0))>0,"△採点が範囲外","OK"))))))))))) | X15: =IF(W15<>"OK","",TRIM(IF(AND(AO15<>"",N(AO15)<=1),"根拠1件 ","")&IF(AP15<>"","同名あり ","")&IF(AND(NOT(ISNUMBER(I15)),I15<>""),"回数を換算 ",""))) | AC15: =IF(W15<>"OK","",IF(AB15<>"",AB15,AE15)) | AD15: =IF(W15<>"OK","",IFERROR(IF(Z15<>"",Z15,AM15)*IF(AA15<>"",AA15,AN15)/60,"")) | AE15: =IF(W15<>"OK","",IF(OR(VALUE(O15)=2,VALUE(P15)=2,VALUE(Q15)=2),"社内残置",IF(AND(VALUE(O15)=0,VALUE(R15)=0,VALUE(T15)=0),"自動化候補",IF(AND(VALUE(P15)=0,VALUE(R15)<=1,VALUE(S15)<=1,VALUE(T15)<=1,VALUE(U15)<=1),"オフショア候補",IF(AND(VALUE(T15)<=1,VALUE(U15)<=1),"ニアショア候補","社内で手順化→再評価"))))) | AF15: =IF(W15<>"OK","",14-SUMPRODUCT(--O15:U15)) | AG15: =IF(W15<>"OK","",AM15*AN15/60) | AH15: =IF(A15="","",UPPER(TRIM(ASC(A15&"")))) | AI15: =IF(AH15="","",AH15&"-"&B15) | AJ15: =IF(C15="","",IFERROR(VALUE(ASC(SUBSTITUTE(C15&"","観点",""))),"")) | AK15: =IF(E15="","",UPPER(LEFT(TRIM(ASC(E15&"")),3))) | AL15: =IF(I15="","",IFERROR(VALUE(SUBSTITUTE(SUBSTITUTE(SUBSTITUTE(SUBSTITUTE(SUBSTITUTE(SUBSTITUTE(SUBSTITUTE(SUBSTITUTE(SUBSTITUTE(SUBSTITUTE(SUBSTITUTE(SUBSTITUTE(ASC(I15&""),"約",""),"程度",""),"ほど",""),"回",""),"毎",""),"週",""),"月",""),"年",""),"日",""),"に",""),"/","")," ","")),"")) | AM15: =IF(I15="","",IF(ISNUMBER(I15),I15,IFERROR(VALUE(ASC(I15&"")),IF(AL15<>"",AL15*IF(ISNUMBER(SEARCH("週",I15)),4.3,IF(ISNUMBER(SEARCH("年",I15)),1/12,IF(ISNUMBER(SEARCH("日",I15)),20,1))),IF(ISNUMBER(SEARCH("日",I15)),20,IF(ISNUMBER(SEARCH("週",I15)),4.3,IF(ISNUMBER(SEARCH("月",I15)),1,""))))))) | AN15: =IF(J15="","",IF(ISNUMBER(J15),J15,IFERROR(VALUE(ASC(J15&"")),IF(ISNUMBER(SEARCH("時間",J15)),IFERROR(VALUE(SUBSTITUTE(SUBSTITUTE(SUBSTITUTE(SUBSTITUTE(SUBSTITUTE(ASC(J15&""),"約",""),"程度",""),"ほど",""),"時間","")," ",""))*60,""),IFERROR(VALUE(SUBSTITUTE(SUBSTITUTE(SUBSTITUTE(SUBSTITUTE(SUBSTITUTE(ASC(J15&""),"約",""),"程度",""),"ほど",""),"分","")," ","")),""))))) | AO15: =IF(K15="","",IF(ISNUMBER(K15),K15,IFERROR(VALUE(SUBSTITUTE(SUBSTITUTE(SUBSTITUTE(ASC(K15&""),"約",""),"件","")," ","")),""))) | AP15: =IF(W15<>"OK","",IF(COUNTIFS($D$5:$D$404,D15,$W$5:$W$404,"OK")>1,"同名あり","")) | AQ15: =IF(L15="","",IF(ISNUMBER(L15),L15,IFERROR(DATEVALUE(SUBSTITUTE(SUBSTITUTE(ASC(L15&""),"-","/"),".","/")&"/01"),""))) | AR15: =IF(M15="","",IF(ISNUMBER(M15),M15,IFERROR(DATEVALUE(SUBSTITUTE(SUBSTITUTE(ASC(M15&""),"-","/"),".","/")&"/01"),""))) | AS15: =IF(OR(W15<>"OK",AQ15=""),"",IF(AQ15>='01_設定'!$C$26,1,0)) | AT15: =IF(AND(W15="OK",Y15<>"除外"),COUNTIFS($W$5:W15,"OK",$Y$5:Y15,"<>除外"),"") | AU15: =IF(OR(AT15="",AD15=""),"",AD15+ROW()/1000000000)
W16: =IF(AND(A16="",D16=""),"",IF(ISNUMBER(SEARCH("##END",AH16)),"（終わりの印）",IF(ISNUMBER(SEARCH("##続き",AH16)),"（続きありの印）",IF(AH16="調査ID","（見出し行）",IF(AND(AH16<>"R1",AH16<>"R2"),"×表以外の行（集計されない）",IF(COUNTIF($AI$5:AI16,AI16)>1,"△重複（集計されない）",IF(D16="","△タスク名なし",IF(ISNA(MATCH(AK16,'M1_類型マスタ'!$A$5:$A$19,0)),"△類型が不正",IF(OR(AM16="",AN16=""),"△回数・分が読めない",IF(SUMPRODUCT(--ISNUMBER(--O16:U16))<7,"△採点が足りない",IF(SUMPRODUCT((--O16:U16>2)+(--O16:U16<0))>0,"△採点が範囲外","OK"))))))))))) | X16: =IF(W16<>"OK","",TRIM(IF(AND(AO16<>"",N(AO16)<=1),"根拠1件 ","")&IF(AP16<>"","同名あり ","")&IF(AND(NOT(ISNUMBER(I16)),I16<>""),"回数を換算 ",""))) | AC16: =IF(W16<>"OK","",IF(AB16<>"",AB16,AE16)) | AD16: =IF(W16<>"OK","",IFERROR(IF(Z16<>"",Z16,AM16)*IF(AA16<>"",AA16,AN16)/60,"")) | AE16: =IF(W16<>"OK","",IF(OR(VALUE(O16)=2,VALUE(P16)=2,VALUE(Q16)=2),"社内残置",IF(AND(VALUE(O16)=0,VALUE(R16)=0,VALUE(T16)=0),"自動化候補",IF(AND(VALUE(P16)=0,VALUE(R16)<=1,VALUE(S16)<=1,VALUE(T16)<=1,VALUE(U16)<=1),"オフショア候補",IF(AND(VALUE(T16)<=1,VALUE(U16)<=1),"ニアショア候補","社内で手順化→再評価"))))) | AF16: =IF(W16<>"OK","",14-SUMPRODUCT(--O16:U16)) | AG16: =IF(W16<>"OK","",AM16*AN16/60) | AH16: =IF(A16="","",UPPER(TRIM(ASC(A16&"")))) | AI16: =IF(AH16="","",AH16&"-"&B16) | AJ16: =IF(C16="","",IFERROR(VALUE(ASC(SUBSTITUTE(C16&"","観点",""))),"")) | AK16: =IF(E16="","",UPPER(LEFT(TRIM(ASC(E16&"")),3))) | AL16: =IF(I16="","",IFERROR(VALUE(SUBSTITUTE(SUBSTITUTE(SUBSTITUTE(SUBSTITUTE(SUBSTITUTE(SUBSTITUTE(SUBSTITUTE(SUBSTITUTE(SUBSTITUTE(SUBSTITUTE(SUBSTITUTE(SUBSTITUTE(ASC(I16&""),"約",""),"程度",""),"ほど",""),"回",""),"毎",""),"週",""),"月",""),"年",""),"日",""),"に",""),"/","")," ","")),"")) | AM16: =IF(I16="","",IF(ISNUMBER(I16),I16,IFERROR(VALUE(ASC(I16&"")),IF(AL16<>"",AL16*IF(ISNUMBER(SEARCH("週",I16)),4.3,IF(ISNUMBER(SEARCH("年",I16)),1/12,IF(ISNUMBER(SEARCH("日",I16)),20,1))),IF(ISNUMBER(SEARCH("日",I16)),20,IF(ISNUMBER(SEARCH("週",I16)),4.3,IF(ISNUMBER(SEARCH("月",I16)),1,""))))))) | AN16: =IF(J16="","",IF(ISNUMBER(J16),J16,IFERROR(VALUE(ASC(J16&"")),IF(ISNUMBER(SEARCH("時間",J16)),IFERROR(VALUE(SUBSTITUTE(SUBSTITUTE(SUBSTITUTE(SUBSTITUTE(SUBSTITUTE(ASC(J16&""),"約",""),"程度",""),"ほど",""),"時間","")," ",""))*60,""),IFERROR(VALUE(SUBSTITUTE(SUBSTITUTE(SUBSTITUTE(SUBSTITUTE(SUBSTITUTE(ASC(J16&""),"約",""),"程度",""),"ほど",""),"分","")," ","")),""))))) | AO16: =IF(K16="","",IF(ISNUMBER(K16),K16,IFERROR(VALUE(SUBSTITUTE(SUBSTITUTE(SUBSTITUTE(ASC(K16&""),"約",""),"件","")," ","")),""))) | AP16: =IF(W16<>"OK","",IF(COUNTIFS($D$5:$D$404,D16,$W$5:$W$404,"OK")>1,"同名あり","")) | AQ16: =IF(L16="","",IF(ISNUMBER(L16),L16,IFERROR(DATEVALUE(SUBSTITUTE(SUBSTITUTE(ASC(L16&""),"-","/"),".","/")&"/01"),""))) | AR16: =IF(M16="","",IF(ISNUMBER(M16),M16,IFERROR(DATEVALUE(SUBSTITUTE(SUBSTITUTE(ASC(M16&""),"-","/"),".","/")&"/01"),""))) | AS16: =IF(OR(W16<>"OK",AQ16=""),"",IF(AQ16>='01_設定'!$C$26,1,0)) | AT16: =IF(AND(W16="OK",Y16<>"除外"),COUNTIFS($W$5:W16,"OK",$Y$5:Y16,"<>除外"),"") | AU16: =IF(OR(AT16="",AD16=""),"",AD16+ROW()/1000000000)
... W404: =IF(AND(A404="",D404=""),"",IF(ISNUMBER(SEARCH("##END",AH404)),"（終わりの印）",IF(ISNUMBER(SEARCH("##続き",AH404)),"（続きありの印）",IF(AH404="調査ID","（見出し行）",IF(AND(AH404<>"R1",AH404<>"R2"),"×表以外の行（集計されない）",IF(COUNTIF($AI$5:AI404,AI404)>1,"△重複（集計されない）",IF(D404="","△タスク名なし",IF(ISNA(MATCH(AK404,'M1_類型マスタ'!$A$5:$A$19,0)),"△類型が不正",IF(OR(AM404="",AN404=""),"△回数・分が読めない",IF(SUMPRODUCT(--ISNUMBER(--O404:U404))<7,"△採点が足りない",IF(SUMPRODUCT((--O404:U404>2)+(--O404:U404<0))>0,"△採点が範囲外","OK"))))))))))) | X404: =IF(W404<>"OK","",TRIM(IF(AND(AO404<>"",N(AO404)<=1),"根拠1件 ","")&IF(AP404<>"","同名あり ","")&IF(AND(NOT(ISNUMBER(I404)),I404<>""),"回数を換算 ",""))) | AC404: =IF(W404<>"OK","",IF(AB404<>"",AB404,AE404)) | AD404: =IF(W404<>"OK","",IFERROR(IF(Z404<>"",Z404,AM404)*IF(AA404<>"",AA404,AN404)/60,"")) | AE404: =IF(W404<>"OK","",IF(OR(VALUE(O404)=2,VALUE(P404)=2,VALUE(Q404)=2),"社内残置",IF(AND(VALUE(O404)=0,VALUE(R404)=0,VALUE(T404)=0),"自動化候補",IF(AND(VALUE(P404)=0,VALUE(R404)<=1,VALUE(S404)<=1,VALUE(T404)<=1,VALUE(U404)<=1),"オフショア候補",IF(AND(VALUE(T404)<=1,VALUE(U404)<=1),"ニアショア候補","社内で手順化→再評価"))))) | AF404: =IF(W404<>"OK","",14-SUMPRODUCT(--O404:U404)) | AG404: =IF(W404<>"OK","",AM404*AN404/60) | AH404: =IF(A404="","",UPPER(TRIM(ASC(A404&"")))) | AI404: =IF(AH404="","",AH404&"-"&B404) | AJ404: =IF(C404="","",IFERROR(VALUE(ASC(SUBSTITUTE(C404&"","観点",""))),"")) | AK404: =IF(E404="","",UPPER(LEFT(TRIM(ASC(E404&"")),3))) | AL404: =IF(I404="","",IFERROR(VALUE(SUBSTITUTE(SUBSTITUTE(SUBSTITUTE(SUBSTITUTE(SUBSTITUTE(SUBSTITUTE(SUBSTITUTE(SUBSTITUTE(SUBSTITUTE(SUBSTITUTE(SUBSTITUTE(SUBSTITUTE(ASC(I404&""),"約",""),"程度",""),"ほど",""),"回",""),"毎",""),"週",""),"月",""),"年",""),"日",""),"に",""),"/","")," ","")),"")) | AM404: =IF(I404="","",IF(ISNUMBER(I404),I404,IFERROR(VALUE(ASC(I404&"")),IF(AL404<>"",AL404*IF(ISNUMBER(SEARCH("週",I404)),4.3,IF(ISNUMBER(SEARCH("年",I404)),1/12,IF(ISNUMBER(SEARCH("日",I404)),20,1))),IF(ISNUMBER(SEARCH("日",I404)),20,IF(ISNUMBER(SEARCH("週",I404)),4.3,IF(ISNUMBER(SEARCH("月",I404)),1,""))))))) | AN404: =IF(J404="","",IF(ISNUMBER(J404),J404,IFERROR(VALUE(ASC(J404&"")),IF(ISNUMBER(SEARCH("時間",J404)),IFERROR(VALUE(SUBSTITUTE(SUBSTITUTE(SUBSTITUTE(SUBSTITUTE(SUBSTITUTE(ASC(J404&""),"約",""),"程度",""),"ほど",""),"時間","")," ",""))*60,""),IFERROR(VALUE(SUBSTITUTE(SUBSTITUTE(SUBSTITUTE(SUBSTITUTE(SUBSTITUTE(ASC(J404&""),"約",""),"程度",""),"ほど",""),"分","")," ","")),""))))) | AO404: =IF(K404="","",IF(ISNUMBER(K404),K404,IFERROR(VALUE(SUBSTITUTE(SUBSTITUTE(SUBSTITUTE(ASC(K404&""),"約",""),"件","")," ","")),""))) | AP404: =IF(W404<>"OK","",IF(COUNTIFS($D$5:$D$404,D404,$W$5:$W$404,"OK")>1,"同名あり","")) | AQ404: =IF(L404="","",IF(ISNUMBER(L404),L404,IFERROR(DATEVALUE(SUBSTITUTE(SUBSTITUTE(ASC(L404&""),"-","/"),".","/")&"/01"),""))) | AR404: =IF(M404="","",IF(ISNUMBER(M404),M404,IFERROR(DATEVALUE(SUBSTITUTE(SUBSTITUTE(ASC(M404&""),"-","/"),".","/")&"/01"),""))) | AS404: =IF(OR(W404<>"OK",AQ404=""),"",IF(AQ404>='01_設定'!$C$26,1,0)) | AT404: =IF(AND(W404="OK",Y404<>"除外"),COUNTIFS($W$5:W404,"OK",$Y$5:Y404,"<>除外"),"") | AU404: =IF(OR(AT404="",AD404=""),"",AD404+ROW()/1000000000)

Sheet 05_タスク一覧（提出用）
A1: 05_タスク一覧（提出用・最終成果物）
A2: 04_調査結果のうち、判定が OK で「除外」していないタスクが自動で並ぶ。直接は編集しない（直すときは 04 で）。
A3: 実行者ID | B3: 部署区分 | C3: 役職区分 | D3: 実行日 | E3: 対象開始日 | F3: 台帳の版 | G3: No | H3: 観点 | I3: タスク名 | J3: 類型 | K3: 類型名 | L3: 説明 | M3: 主な相手 | N3: 明示暗黙 | O3: 月あたり回数 | P3: 1回あたり分 | Q3: 月あたり時間h | R3: 根拠の件数 | S3: 根拠の最初 | T3: 根拠の最後 | U3: 暗黙の理由 | V3: A1 | W3: A2 | X3: A3 | Y3: A4 | Z3: A5 | AA3: A6 | AB3: A7 | AC3: 任せやすさ | AD3: 採用区分 | AE3: 任せるための前提条件 | AF3: 要確認 | AG3: 行
A5: =IF($AG5="","",'01_設定'!$C$4) | B5: =IF($AG5="","",'01_設定'!$C$5) | C5: =IF($AG5="","",'01_設定'!$C$6) | D5: =IF($AG5="","",'01_設定'!$C$22) | E5: =IF($AG5="","",'01_設定'!$C$23) | F5: =IF($AG5="","",'01_設定'!$C$32) | G5: =IF($AG5="","",ROW()-4) | H5: =IF($AG5="","",INDEX('04_調査結果'!$AJ$5:$AJ$404,$AG5)) | I5: =IF($AG5="","",INDEX('04_調査結果'!$D$5:$D$404,$AG5)&"") | J5: =IF($AG5="","",INDEX('04_調査結果'!$AK$5:$AK$404,$AG5)&"") | K5: =IF($AG5="","",IFERROR(INDEX('M1_類型マスタ'!$B$5:$B$19,MATCH(J5,'M1_類型マスタ'!$A$5:$A$19,0)),"")) | L5: =IF($AG5="","",INDEX('04_調査結果'!$F$5:$F$404,$AG5)&"") | M5: =IF($AG5="","",INDEX('04_調査結果'!$G$5:$G$404,$AG5)&"") | N5: =IF($AG5="","",INDEX('04_調査結果'!$H$5:$H$404,$AG5)&"") | O5: =IF($AG5="","",IF(INDEX('04_調査結果'!$Z$5:$Z$404,$AG5)<>"",INDEX('04_調査結果'!$Z$5:$Z$404,$AG5),INDEX('04_調査結果'!$AM$5:$AM$404,$AG5))) | P5: =IF($AG5="","",IF(INDEX('04_調査結果'!$AA$5:$AA$404,$AG5)<>"",INDEX('04_調査結果'!$AA$5:$AA$404,$AG5),INDEX('04_調査結果'!$AN$5:$AN$404,$AG5))) | Q5: =IF($AG5="","",INDEX('04_調査結果'!$AD$5:$AD$404,$AG5)) | R5: =IF($AG5="","",INDEX('04_調査結果'!$AO$5:$AO$404,$AG5)) | S5: =IF($AG5="","",INDEX('04_調査結果'!$AQ$5:$AQ$404,$AG5)) | T5: =IF($AG5="","",INDEX('04_調査結果'!$AR$5:$AR$404,$AG5)) | U5: =IF($AG5="","",INDEX('04_調査結果'!$N$5:$N$404,$AG5)&"") | V5: =IF($AG5="","",INDEX('04_調査結果'!$O$5:$O$404,$AG5)) | W5: =IF($AG5="","",INDEX('04_調査結果'!$P$5:$P$404,$AG5)) | X5: =IF($AG5="","",INDEX('04_調査結果'!$Q$5:$Q$404,$AG5)) | Y5: =IF($AG5="","",INDEX('04_調査結果'!$R$5:$R$404,$AG5)) | Z5: =IF($AG5="","",INDEX('04_調査結果'!$S$5:$S$404,$AG5)) | AA5: =IF($AG5="","",INDEX('04_調査結果'!$T$5:$T$404,$AG5)) | AB5: =IF($AG5="","",INDEX('04_調査結果'!$U$5:$U$404,$AG5)) | AC5: =IF($AG5="","",INDEX('04_調査結果'!$AF$5:$AF$404,$AG5)) | AD5: =IF($AG5="","",INDEX('04_調査結果'!$AC$5:$AC$404,$AG5)&"") | AE5: =IF($AG5="","",INDEX('04_調査結果'!$V$5:$V$404,$AG5)&"") | AF5: =IF($AG5="","",INDEX('04_調査結果'!$X$5:$X$404,$AG5)&"") | AG5: =IFERROR(MATCH(ROW()-4,'04_調査結果'!$AT$5:$AT$404,0),"")
A6: =IF($AG6="","",'01_設定'!$C$4) | B6: =IF($AG6="","",'01_設定'!$C$5) | C6: =IF($AG6="","",'01_設定'!$C$6) | D6: =IF($AG6="","",'01_設定'!$C$22) | E6: =IF($AG6="","",'01_設定'!$C$23) | F6: =IF($AG6="","",'01_設定'!$C$32) | G6: =IF($AG6="","",ROW()-4) | H6: =IF($AG6="","",INDEX('04_調査結果'!$AJ$5:$AJ$404,$AG6)) | I6: =IF($AG6="","",INDEX('04_調査結果'!$D$5:$D$404,$AG6)&"") | J6: =IF($AG6="","",INDEX('04_調査結果'!$AK$5:$AK$404,$AG6)&"") | K6: =IF($AG6="","",IFERROR(INDEX('M1_類型マスタ'!$B$5:$B$19,MATCH(J6,'M1_類型マスタ'!$A$5:$A$19,0)),"")) | L6: =IF($AG6="","",INDEX('04_調査結果'!$F$5:$F$404,$AG6)&"") | M6: =IF($AG6="","",INDEX('04_調査結果'!$G$5:$G$404,$AG6)&"") | N6: =IF($AG6="","",INDEX('04_調査結果'!$H$5:$H$404,$AG6)&"") | O6: =IF($AG6="","",IF(INDEX('04_調査結果'!$Z$5:$Z$404,$AG6)<>"",INDEX('04_調査結果'!$Z$5:$Z$404,$AG6),INDEX('04_調査結果'!$AM$5:$AM$404,$AG6))) | P6: =IF($AG6="","",IF(INDEX('04_調査結果'!$AA$5:$AA$404,$AG6)<>"",INDEX('04_調査結果'!$AA$5:$AA$404,$AG6),INDEX('04_調査結果'!$AN$5:$AN$404,$AG6))) | Q6: =IF($AG6="","",INDEX('04_調査結果'!$AD$5:$AD$404,$AG6)) | R6: =IF($AG6="","",INDEX('04_調査結果'!$AO$5:$AO$404,$AG6)) | S6: =IF($AG6="","",INDEX('04_調査結果'!$AQ$5:$AQ$404,$AG6)) | T6: =IF($AG6="","",INDEX('04_調査結果'!$AR$5:$AR$404,$AG6)) | U6: =IF($AG6="","",INDEX('04_調査結果'!$N$5:$N$404,$AG6)&"") | V6: =IF($AG6="","",INDEX('04_調査結果'!$O$5:$O$404,$AG6)) | W6: =IF($AG6="","",INDEX('04_調査結果'!$P$5:$P$404,$AG6)) | X6: =IF($AG6="","",INDEX('04_調査結果'!$Q$5:$Q$404,$AG6)) | Y6: =IF($AG6="","",INDEX('04_調査結果'!$R$5:$R$404,$AG6)) | Z6: =IF($AG6="","",INDEX('04_調査結果'!$S$5:$S$404,$AG6)) | AA6: =IF($AG6="","",INDEX('04_調査結果'!$T$5:$T$404,$AG6)) | AB6: =IF($AG6="","",INDEX('04_調査結果'!$U$5:$U$404,$AG6)) | AC6: =IF($AG6="","",INDEX('04_調査結果'!$AF$5:$AF$404,$AG6)) | AD6: =IF($AG6="","",INDEX('04_調査結果'!$AC$5:$AC$404,$AG6)&"") | AE6: =IF($AG6="","",INDEX('04_調査結果'!$V$5:$V$404,$AG6)&"") | AF6: =IF($AG6="","",INDEX('04_調査結果'!$X$5:$X$404,$AG6)&"") | AG6: =IFERROR(MATCH(ROW()-4,'04_調査結果'!$AT$5:$AT$404,0),"")
A7: =IF($AG7="","",'01_設定'!$C$4) | B7: =IF($AG7="","",'01_設定'!$C$5) | C7: =IF($AG7="","",'01_設定'!$C$6) | D7: =IF($AG7="","",'01_設定'!$C$22) | E7: =IF($AG7="","",'01_設定'!$C$23) | F7: =IF($AG7="","",'01_設定'!$C$32) | G7: =IF($AG7="","",ROW()-4) | H7: =IF($AG7="","",INDEX('04_調査結果'!$AJ$5:$AJ$404,$AG7)) | I7: =IF($AG7="","",INDEX('04_調査結果'!$D$5:$D$404,$AG7)&"") | J7: =IF($AG7="","",INDEX('04_調査結果'!$AK$5:$AK$404,$AG7)&"") | K7: =IF($AG7="","",IFERROR(INDEX('M1_類型マスタ'!$B$5:$B$19,MATCH(J7,'M1_類型マスタ'!$A$5:$A$19,0)),"")) | L7: =IF($AG7="","",INDEX('04_調査結果'!$F$5:$F$404,$AG7)&"") | M7: =IF($AG7="","",INDEX('04_調査結果'!$G$5:$G$404,$AG7)&"") | N7: =IF($AG7="","",INDEX('04_調査結果'!$H$5:$H$404,$AG7)&"") | O7: =IF($AG7="","",IF(INDEX('04_調査結果'!$Z$5:$Z$404,$AG7)<>"",INDEX('04_調査結果'!$Z$5:$Z$404,$AG7),INDEX('04_調査結果'!$AM$5:$AM$404,$AG7))) | P7: =IF($AG7="","",IF(INDEX('04_調査結果'!$AA$5:$AA$404,$AG7)<>"",INDEX('04_調査結果'!$AA$5:$AA$404,$AG7),INDEX('04_調査結果'!$AN$5:$AN$404,$AG7))) | Q7: =IF($AG7="","",INDEX('04_調査結果'!$AD$5:$AD$404,$AG7)) | R7: =IF($AG7="","",INDEX('04_調査結果'!$AO$5:$AO$404,$AG7)) | S7: =IF($AG7="","",INDEX('04_調査結果'!$AQ$5:$AQ$404,$AG7)) | T7: =IF($AG7="","",INDEX('04_調査結果'!$AR$5:$AR$404,$AG7)) | U7: =IF($AG7="","",INDEX('04_調査結果'!$N$5:$N$404,$AG7)&"") | V7: =IF($AG7="","",INDEX('04_調査結果'!$O$5:$O$404,$AG7)) | W7: =IF($AG7="","",INDEX('04_調査結果'!$P$5:$P$404,$AG7)) | X7: =IF($AG7="","",INDEX('04_調査結果'!$Q$5:$Q$404,$AG7)) | Y7: =IF($AG7="","",INDEX('04_調査結果'!$R$5:$R$404,$AG7)) | Z7: =IF($AG7="","",INDEX('04_調査結果'!$S$5:$S$404,$AG7)) | AA7: =IF($AG7="","",INDEX('04_調査結果'!$T$5:$T$404,$AG7)) | AB7: =IF($AG7="","",INDEX('04_調査結果'!$U$5:$U$404,$AG7)) | AC7: =IF($AG7="","",INDEX('04_調査結果'!$AF$5:$AF$404,$AG7)) | AD7: =IF($AG7="","",INDEX('04_調査結果'!$AC$5:$AC$404,$AG7)&"") | AE7: =IF($AG7="","",INDEX('04_調査結果'!$V$5:$V$404,$AG7)&"") | AF7: =IF($AG7="","",INDEX('04_調査結果'!$X$5:$X$404,$AG7)&"") | AG7: =IFERROR(MATCH(ROW()-4,'04_調査結果'!$AT$5:$AT$404,0),"")
A8: =IF($AG8="","",'01_設定'!$C$4) | B8: =IF($AG8="","",'01_設定'!$C$5) | C8: =IF($AG8="","",'01_設定'!$C$6) | D8: =IF($AG8="","",'01_設定'!$C$22) | E8: =IF($AG8="","",'01_設定'!$C$23) | F8: =IF($AG8="","",'01_設定'!$C$32) | G8: =IF($AG8="","",ROW()-4) | H8: =IF($AG8="","",INDEX('04_調査結果'!$AJ$5:$AJ$404,$AG8)) | I8: =IF($AG8="","",INDEX('04_調査結果'!$D$5:$D$404,$AG8)&"") | J8: =IF($AG8="","",INDEX('04_調査結果'!$AK$5:$AK$404,$AG8)&"") | K8: =IF($AG8="","",IFERROR(INDEX('M1_類型マスタ'!$B$5:$B$19,MATCH(J8,'M1_類型マスタ'!$A$5:$A$19,0)),"")) | L8: =IF($AG8="","",INDEX('04_調査結果'!$F$5:$F$404,$AG8)&"") | M8: =IF($AG8="","",INDEX('04_調査結果'!$G$5:$G$404,$AG8)&"") | N8: =IF($AG8="","",INDEX('04_調査結果'!$H$5:$H$404,$AG8)&"") | O8: =IF($AG8="","",IF(INDEX('04_調査結果'!$Z$5:$Z$404,$AG8)<>"",INDEX('04_調査結果'!$Z$5:$Z$404,$AG8),INDEX('04_調査結果'!$AM$5:$AM$404,$AG8))) | P8: =IF($AG8="","",IF(INDEX('04_調査結果'!$AA$5:$AA$404,$AG8)<>"",INDEX('04_調査結果'!$AA$5:$AA$404,$AG8),INDEX('04_調査結果'!$AN$5:$AN$404,$AG8))) | Q8: =IF($AG8="","",INDEX('04_調査結果'!$AD$5:$AD$404,$AG8)) | R8: =IF($AG8="","",INDEX('04_調査結果'!$AO$5:$AO$404,$AG8)) | S8: =IF($AG8="","",INDEX('04_調査結果'!$AQ$5:$AQ$404,$AG8)) | T8: =IF($AG8="","",INDEX('04_調査結果'!$AR$5:$AR$404,$AG8)) | U8: =IF($AG8="","",INDEX('04_調査結果'!$N$5:$N$404,$AG8)&"") | V8: =IF($AG8="","",INDEX('04_調査結果'!$O$5:$O$404,$AG8)) | W8: =IF($AG8="","",INDEX('04_調査結果'!$P$5:$P$404,$AG8)) | X8: =IF($AG8="","",INDEX('04_調査結果'!$Q$5:$Q$404,$AG8)) | Y8: =IF($AG8="","",INDEX('04_調査結果'!$R$5:$R$404,$AG8)) | Z8: =IF($AG8="","",INDEX('04_調査結果'!$S$5:$S$404,$AG8)) | AA8: =IF($AG8="","",INDEX('04_調査結果'!$T$5:$T$404,$AG8)) | AB8: =IF($AG8="","",INDEX('04_調査結果'!$U$5:$U$404,$AG8)) | AC8: =IF($AG8="","",INDEX('04_調査結果'!$AF$5:$AF$404,$AG8)) | AD8: =IF($AG8="","",INDEX('04_調査結果'!$AC$5:$AC$404,$AG8)&"") | AE8: =IF($AG8="","",INDEX('04_調査結果'!$V$5:$V$404,$AG8)&"") | AF8: =IF($AG8="","",INDEX('04_調査結果'!$X$5:$X$404,$AG8)&"") | AG8: =IFERROR(MATCH(ROW()-4,'04_調査結果'!$AT$5:$AT$404,0),"")
